{
  "version": 8,
  "blockIdVersion": 11,
  "anchorX": 0,
  "anchorY": 0,
  "anchorZ": 0,
  "blocks": [
    {
      "x": 13,
      "y": -11,
      "z": -5,
      "name": "Prototype_Rock_Concrete_Brick_Stairs",
      "rotation": 3
    },
    {
      "x": 13,
      "y": -11,
      "z": 7,
      "name": "Prototype_Rock_Concrete_Brick_Stairs",
      "rotation": 3
    },
    {
      "x": 14,
      "y": -11,
      "z": -6,
      "name": "Prototype_Rock_Concrete_Brick_Half"
    },
    {
      "x": 14,
      "y": -11,
      "z": -5,
      "name": "Prototype_Rock_Concrete_Brick"
    },
    {
      "x": 14,
      "y": -10,
      "z": -5,
      "name": "Prototype_Rock_Concrete_Brick_Half"
    },
    {
      "x": 14,
      "y": -11,
      "z": -4,
      "name": "Prototype_Rock_Concrete_Brick_Half"
    },
    {
      "x": 14,
      "y": -11,
      "z": -3,
      "name": "Prototype_Rock_Concrete_Brick_Stairs",
      "rotation": 3
    },
    {
      "x": 14,
      "y": -11,
      "z": -2,
      "name": "Prototype_Rock_Concrete_Brick_Half"
    },
    {
      "x": 14,
      "y": -11,
      "z": -1,
      "name": "Rock_Shale_Brick_Half"
    },
    {
      "x": 14,
      "y": -11,
      "z": 0,
      "name": "Rock_Shale_Cobble_Half"
    },
    {
      "x": 14,
      "y": -11,
      "z": 1,
      "name": "Prototype_Rock_Concrete_Brick_Half"
    },
    {
      "x": 14,
      "y": -11,
      "z": 2,
      "name": "Rock_Shale_Cobble_Half"
    },
    {
      "x": 14,
      "y": -11,
      "z": 3,
      "name": "Rock_Shale_Brick_Half"
    },
    {
      "x": 14,
      "y": -11,
      "z": 4,
      "name": "Prototype_Rock_Concrete_Brick_Half"
    },
    {
      "x": 14,
      "y": -11,
      "z": 5,
      "name": "Prototype_Rock_Concrete_Brick_Stairs",
      "rotation": 3
    },
    {
      "x": 14,
      "y": -11,
      "z": 6,
      "name": "Prototype_Rock_Concrete_Brick_Half"
    },
    {
      "x": 14,
      "y": -11,
      "z": 7,
      "name": "Prototype_Rock_Concrete_Brick"
    },
    {
      "x": 14,
      "y": -10,
      "z": 7,
      "name": "Prototype_Rock_Concrete_Brick_Half"
    },
    {
      "x": 14,
      "y": -11,
      "z": 8,
      "name": "Prototype_Rock_Concrete_Brick_Half"
    },
    {
      "x": 15,
      "y": -11,
      "z": -6,
      "name": "Prototype_Rock_Concrete_Brick_Half",
      "rotation": 8
    },
    {
      "x": 15,
      "y": -11,
      "z": -5,
      "name": "Prototype_Rock_Concrete_Brick"
    },
    {
      "x": 15,
      "y": -10,
      "z": -5,
      "name": "Prototype_Rock_Concrete_Brick_Stairs",
      "rotation": 3
    },
    {
      "x": 15,
      "y": -11,
      "z": -4,
      "name": "Prototype_Rock_Concrete_Brick_Half",
      "rotation": 8
    },
    {
      "x": 15,
      "y": -11,
      "z": -3,
      "name": "Rock_Crystal_Cyan_Block"
    },
    {
      "x": 15,
      "y": -10,
      "z": -3,
      "name": "Plant_Moss_Rug_Green_Dark"
    },
    {
      "x": 15,
      "y": -11,
      "z": -2,
      "name": "Rock_Shale_Brick_Half",
      "rotation": 8
    },
    {
      "x": 15,
      "y": -11,
      "z": -1,
      "name": "Rock_Shale_Cobble_Half",
      "rotation": 8
    },
    {
      "x": 15,
      "y": -11,
      "z": 0,
      "name": "Prototype_Rock_Concrete_Brick_Half",
      "rotation": 8
    },
    {
      "x": 15,
      "y": -11,
      "z": 1,
      "name": "Rock_Shale_Brick_Half",
      "rotation": 8
    },
    {
      "x": 15,
      "y": -11,
      "z": 2,
      "name": "Prototype_Rock_Concrete_Brick_Half",
      "rotation": 8
    },
    {
      "x": 15,
      "y": -11,
      "z": 3,
      "name": "Rock_Shale_Cobble_Half",
      "rotation": 8
    },
    {
      "x": 15,
      "y": -11,
      "z": 4,
      "name": "Rock_Shale_Brick_Half",
      "rotation": 8
    },
    {
      "x": 15,
      "y": -11,
      "z": 5,
      "name": "Rock_Crystal_Cyan_Block"
    },
    {
      "x": 15,
      "y": -10,
      "z": 5,
      "name": "Plant_Moss_Rug_Green_Dark"
    },
    {
      "x": 15,
      "y": -11,
      "z": 6,
      "name": "Prototype_Rock_Concrete_Brick_Half",
      "rotation": 8
    },
    {
      "x": 15,
      "y": -11,
      "z": 7,
      "name": "Prototype_Rock_Concrete_Brick"
    },
    {
      "x": 15,
      "y": -10,
      "z": 7,
      "name": "Prototype_Rock_Concrete_Brick_Stairs",
      "rotation": 3
    },
    {
      "x": 15,
      "y": -11,
      "z": 8,
      "name": "Prototype_Rock_Concrete_Brick_Half",
      "rotation": 8
    },
    {
      "x": 16,
      "y": -11,
      "z": -6,
      "name": "Wood_Hardwood_Fence",
      "rotation": 1
    },
    {
      "x": 16,
      "y": -10,
      "z": -6,
      "name": "Prototype_Rock_Concrete_Brick_Half"
    },
    {
      "x": 16,
      "y": -11,
      "z": -5,
      "name": "Rock_Stone_Brick"
    },
    {
      "x": 16,
      "y": -10,
      "z": -5,
      "name": "Prototype_Rock_Concrete_Brick"
    },
    {
      "x": 16,
      "y": -9,
      "z": -5,
      "name": "Prototype_Rock_Concrete_Brick_Half"
    },
    {
      "x": 16,
      "y": -10,
      "z": -4,
      "name": "Prototype_Rock_Concrete_Brick_Half"
    },
    {
      "x": 16,
      "y": -10,
      "z": -3,
      "name": "Prototype_Rock_Concrete_Brick_Half"
    },
    {
      "x": 16,
      "y": -10,
      "z": -2,
      "name": "Rock_Shale_Brick_Half"
    },
    {
      "x": 16,
      "y": -10,
      "z": -1,
      "name": "Rock_Shale_Cobble_Half"
    },
    {
      "x": 16,
      "y": -10,
      "z": 0,
      "name": "Prototype_Rock_Concrete_Brick_Half"
    },
    {
      "x": 16,
      "y": -10,
      "z": 1,
      "name": "Rock_Shale_Brick_Stairs",
      "rotation": 3
    },
    {
      "x": 16,
      "y": -10,
      "z": 2,
      "name": "Prototype_Rock_Concrete_Brick_Half"
    },
    {
      "x": 16,
      "y": -10,
      "z": 3,
      "name": "Rock_Shale_Cobble_Half"
    },
    {
      "x": 16,
      "y": -10,
      "z": 4,
      "name": "Rock_Shale_Brick_Half"
    },
    {
      "x": 16,
      "y": -10,
      "z": 5,
      "name": "Prototype_Rock_Concrete_Brick_Half"
    },
    {
      "x": 16,
      "y": -10,
      "z": 6,
      "name": "Prototype_Rock_Concrete_Brick_Half"
    },
    {
      "x": 16,
      "y": -11,
      "z": 7,
      "name": "Rock_Shale_Brick"
    },
    {
      "x": 16,
      "y": -10,
      "z": 7,
      "name": "Prototype_Rock_Concrete_Brick"
    },
    {
      "x": 16,
      "y": -9,
      "z": 7,
      "name": "Prototype_Rock_Concrete_Brick_Half"
    },
    {
      "x": 16,
      "y": -11,
      "z": 8,
      "name": "Wood_Hardwood_Fence",
      "rotation": 1
    },
    {
      "x": 16,
      "y": -10,
      "z": 8,
      "name": "Prototype_Rock_Concrete_Brick_Half"
    },
    {
      "x": 17,
      "y": -10,
      "z": -6,
      "name": "Prototype_Rock_Concrete_Brick_Half",
      "rotation": 8
    },
    {
      "x": 17,
      "y": -11,
      "z": -5,
      "name": "Rock_Stone_Brick"
    },
    {
      "x": 17,
      "y": -10,
      "z": -5,
      "name": "Prototype_Rock_Concrete_Brick"
    },
    {
      "x": 17,
      "y": -9,
      "z": -5,
      "name": "Prototype_Rock_Concrete_Brick_Stairs",
      "rotation": 3
    },
    {
      "x": 17,
      "y": -11,
      "z": -4,
      "name": "Rock_Crystal_Cyan_Block"
    },
    {
      "x": 17,
      "y": -10,
      "z": -4,
      "name": "Prototype_Rock_Concrete_Brick_Half",
      "rotation": 8
    },
    {
      "x": 17,
      "y": -10,
      "z": -3,
      "name": "Rock_Shale_Brick_Half",
      "rotation": 8
    },
    {
      "x": 17,
      "y": -10,
      "z": -2,
      "name": "Rock_Shale_Cobble_Half",
      "rotation": 8
    },
    {
      "x": 17,
      "y": -10,
      "z": -1,
      "name": "Prototype_Rock_Concrete_Brick_Half",
      "rotation": 8
    },
    {
      "x": 17,
      "y": -10,
      "z": 0,
      "name": "Rock_Shale_Brick_Half",
      "rotation": 8
    },
    {
      "x": 17,
      "y": -10,
      "z": 1,
      "name": "Rock_Crystal_Cyan_Block"
    },
    {
      "x": 17,
      "y": -9,
      "z": 1,
      "name": "Plant_Moss_Rug_Green_Dark"
    },
    {
      "x": 17,
      "y": -10,
      "z": 2,
      "name": "Rock_Shale_Brick_Half",
      "rotation": 8
    },
    {
      "x": 17,
      "y": -10,
      "z": 3,
      "name": "Prototype_Rock_Concrete_Brick_Half",
      "rotation": 8
    },
    {
      "x": 17,
      "y": -10,
      "z": 4,
      "name": "Rock_Shale_Cobble_Half",
      "rotation": 8
    },
    {
      "x": 17,
      "y": -10,
      "z": 5,
      "name": "Rock_Shale_Brick_Half",
      "rotation": 8
    },
    {
      "x": 17,
      "y": -11,
      "z": 6,
      "name": "Rock_Crystal_Cyan_Block"
    },
    {
      "x": 17,
      "y": -10,
      "z": 6,
      "name": "Prototype_Rock_Concrete_Brick_Half",
      "rotation": 8
    },
    {
      "x": 17,
      "y": -11,
      "z": 7,
      "name": "Rock_Stone_Brick"
    },
    {
      "x": 17,
      "y": -10,
      "z": 7,
      "name": "Prototype_Rock_Concrete_Brick"
    },
    {
      "x": 17,
      "y": -9,
      "z": 7,
      "name": "Prototype_Rock_Concrete_Brick_Stairs",
      "rotation": 3
    },
    {
      "x": 17,
      "y": -10,
      "z": 8,
      "name": "Prototype_Rock_Concrete_Brick_Half",
      "rotation": 8
    },
    {
      "x": 18,
      "y": -11,
      "z": -6,
      "name": "Wood_Hardwood_Fence",
      "rotation": 1
    },
    {
      "x": 18,
      "y": -10,
      "z": -6,
      "name": "Wood_Hardwood_Fence",
      "rotation": 1
    },
    {
      "x": 18,
      "y": -9,
      "z": -6,
      "name": "Prototype_Rock_Concrete_Brick_Half"
    },
    {
      "x": 18,
      "y": -11,
      "z": -5,
      "name": "Rock_Shale_Brick"
    },
    {
      "x": 18,
      "y": -10,
      "z": -5,
      "name": "Rock_Shale_Brick"
    },
    {
      "x": 18,
      "y": -9,
      "z": -5,
      "name": "Prototype_Rock_Concrete_Brick"
    },
    {
      "x": 18,
      "y": -8,
      "z": -5,
      "name": "Prototype_Rock_Concrete_Brick_Half"
    },
    {
      "x": 18,
      "y": -9,
      "z": -4,
      "name": "Prototype_Rock_Concrete_Brick_Half"
    },
    {
      "x": 18,
      "y": -9,
      "z": -3,
      "name": "Rock_Shale_Brick_Stairs",
      "rotation": 3
    },
    {
      "x": 18,
      "y": -9,
      "z": -2,
      "name": "Rock_Shale_Cobble_Half"
    },
    {
      "x": 18,
      "y": -9,
      "z": -1,
      "name": "Prototype_Rock_Concrete_Brick_Half"
    },
    {
      "x": 18,
      "y": -9,
      "z": 0,
      "name": "Rock_Shale_Brick_Half"
    },
    {
      "x": 18,
      "y": -9,
      "z": 1,
      "name": "Rock_Shale_Cobble_Half"
    },
    {
      "x": 18,
      "y": -9,
      "z": 2,
      "name": "Rock_Shale_Brick_Half"
    },
    {
      "x": 18,
      "y": -9,
      "z": 3,
      "name": "Prototype_Rock_Concrete_Brick_Half"
    },
    {
      "x": 18,
      "y": -9,
      "z": 4,
      "name": "Rock_Shale_Cobble_Half"
    },
    {
      "x": 18,
      "y": -9,
      "z": 5,
      "name": "Rock_Shale_Brick_Stairs",
      "rotation": 3
    },
    {
      "x": 18,
      "y": -9,
      "z": 6,
      "name": "Prototype_Rock_Concrete_Brick_Half"
    },
    {
      "x": 18,
      "y": -11,
      "z": 7,
      "name": "Rock_Shale_Brick"
    },
    {
      "x": 18,
      "y": -10,
      "z": 7,
      "name": "Rock_Stone_Brick"
    },
    {
      "x": 18,
      "y": -9,
      "z": 7,
      "name": "Prototype_Rock_Concrete_Brick"
    },
    {
      "x": 18,
      "y": -8,
      "z": 7,
      "name": "Prototype_Rock_Concrete_Brick_Half"
    },
    {
      "x": 18,
      "y": -11,
      "z": 8,
      "name": "Wood_Hardwood_Fence",
      "rotation": 1
    },
    {
      "x": 18,
      "y": -10,
      "z": 8,
      "name": "Wood_Hardwood_Fence",
      "rotation": 1
    },
    {
      "x": 18,
      "y": -9,
      "z": 8,
      "name": "Prototype_Rock_Concrete_Brick_Half"
    },
    {
      "x": 19,
      "y": -11,
      "z": -6,
      "name": "*Furniture_Crude_Trapdoor_State_Definitions_OpenDoorOut",
      "rotation": 2
    },
    {
      "x": 19,
      "y": -9,
      "z": -6,
      "name": "Prototype_Rock_Concrete_Brick_Half",
      "rotation": 8
    },
    {
      "x": 19,
      "y": -11,
      "z": -5,
      "name": "Rock_Stone_Cobble"
    },
    {
      "x": 19,
      "y": -10,
      "z": -5,
      "name": "Rock_Stone_Brick"
    },
    {
      "x": 19,
      "y": -9,
      "z": -5,
      "name": "Prototype_Rock_Concrete_Brick"
    },
    {
      "x": 19,
      "y": -8,
      "z": -5,
      "name": "Prototype_Rock_Concrete_Brick_Stairs",
      "rotation": 3
    },
    {
      "x": 19,
      "y": -11,
      "z": -4,
      "name": "Rock_Crystal_Cyan_Block"
    },
    {
      "x": 19,
      "y": -10,
      "z": -4,
      "name": "Rock_Crystal_Cyan_Block"
    },
    {
      "x": 19,
      "y": -9,
      "z": -4,
      "name": "Prototype_Rock_Concrete_Brick_Half",
      "rotation": 8
    },
    {
      "x": 19,
      "y": -9,
      "z": -3,
      "name": "Rock_Crystal_Cyan_Block"
    },
    {
      "x": 19,
      "y": -8,
      "z": -3,
      "name": "Plant_Moss_Rug_Green_Dark"
    },
    {
      "x": 19,
      "y": -9,
      "z": -2,
      "name": "Rock_Shale_Cobble_Half",
      "rotation": 8
    },
    {
      "x": 19,
      "y": -9,
      "z": -1,
      "name": "Prototype_Rock_Concrete_Brick_Half",
      "rotation": 8
    },
    {
      "x": 19,
      "y": -9,
      "z": 0,
      "name": "Rock_Shale_Brick_Half",
      "rotation": 8
    },
    {
      "x": 19,
      "y": -9,
      "z": 1,
      "name": "Rock_Shale_Cobble_Half",
      "rotation": 8
    },
    {
      "x": 19,
      "y": -9,
      "z": 2,
      "name": "Rock_Shale_Brick_Half",
      "rotation": 8
    },
    {
      "x": 19,
      "y": -9,
      "z": 3,
      "name": "Prototype_Rock_Concrete_Brick_Half",
      "rotation": 8
    },
    {
      "x": 19,
      "y": -9,
      "z": 4,
      "name": "Rock_Shale_Cobble_Half",
      "rotation": 8
    },
    {
      "x": 19,
      "y": -9,
      "z": 5,
      "name": "Rock_Crystal_Cyan_Block"
    },
    {
      "x": 19,
      "y": -8,
      "z": 5,
      "name": "Plant_Moss_Rug_Green_Dark"
    },
    {
      "x": 19,
      "y": -11,
      "z": 6,
      "name": "Rock_Crystal_Cyan_Block"
    },
    {
      "x": 19,
      "y": -10,
      "z": 6,
      "name": "Rock_Crystal_Cyan_Block"
    },
    {
      "x": 19,
      "y": -9,
      "z": 6,
      "name": "Prototype_Rock_Concrete_Brick_Half",
      "rotation": 8
    },
    {
      "x": 19,
      "y": -11,
      "z": 7,
      "name": "Rock_Stone_Cobble"
    },
    {
      "x": 19,
      "y": -10,
      "z": 7,
      "name": "Rock_Stone_Brick"
    },
    {
      "x": 19,
      "y": -9,
      "z": 7,
      "name": "Prototype_Rock_Concrete_Brick"
    },
    {
      "x": 19,
      "y": -8,
      "z": 7,
      "name": "Prototype_Rock_Concrete_Brick_Stairs",
      "rotation": 3
    },
    {
      "x": 19,
      "y": -11,
      "z": 8,
      "name": "*Furniture_Crude_Trapdoor_State_Definitions_OpenDoorOut"
    },
    {
      "x": 19,
      "y": -9,
      "z": 8,
      "name": "Prototype_Rock_Concrete_Brick_Half",
      "rotation": 8
    },
    {
      "x": 20,
      "y": -11,
      "z": -6,
      "name": "Wood_Hardwood_Fence",
      "rotation": 1
    },
    {
      "x": 20,
      "y": -10,
      "z": -6,
      "name": "Wood_Hardwood_Fence",
      "rotation": 1
    },
    {
      "x": 20,
      "y": -9,
      "z": -6,
      "name": "Wood_Hardwood_Fence",
      "rotation": 1
    },
    {
      "x": 20,
      "y": -8,
      "z": -6,
      "name": "Prototype_Rock_Concrete_Brick_Half"
    },
    {
      "x": 20,
      "y": -11,
      "z": -5,
      "name": "Rock_Stone_Brick"
    },
    {
      "x": 20,
      "y": -10,
      "z": -5,
      "name": "Rock_Stone_Brick"
    },
    {
      "x": 20,
      "y": -9,
      "z": -5,
      "name": "Rock_Stone_Brick_Mossy"
    },
    {
      "x": 20,
      "y": -8,
      "z": -5,
      "name": "Prototype_Rock_Concrete_Brick"
    },
    {
      "x": 20,
      "y": -7,
      "z": -5,
      "name": "Prototype_Rock_Concrete_Brick_Half"
    },
    {
      "x": 20,
      "y": -8,
      "z": -4,
      "name": "Prototype_Rock_Concrete_Brick_Half"
    },
    {
      "x": 20,
      "y": -8,
      "z": -3,
      "name": "Rock_Shale_Brick_Half"
    },
    {
      "x": 20,
      "y": -8,
      "z": -2,
      "name": "Rock_Shale_Cobble_Half"
    },
    {
      "x": 20,
      "y": -8,
      "z": -1,
      "name": "Prototype_Rock_Concrete_Brick_Half"
    },
    {
      "x": 20,
      "y": -8,
      "z": 0,
      "name": "Rock_Shale_Brick_Half"
    },
    {
      "x": 20,
      "y": -8,
      "z": 1,
      "name": "Rock_Shale_Cobble_Stairs",
      "rotation": 3
    },
    {
      "x": 20,
      "y": -8,
      "z": 2,
      "name": "Rock_Shale_Brick_Half"
    },
    {
      "x": 20,
      "y": -8,
      "z": 3,
      "name": "Prototype_Rock_Concrete_Brick_Half"
    },
    {
      "x": 20,
      "y": -8,
      "z": 4,
      "name": "Rock_Shale_Cobble_Half"
    },
    {
      "x": 20,
      "y": -8,
      "z": 5,
      "name": "Rock_Shale_Brick_Half"
    },
    {
      "x": 20,
      "y": -8,
      "z": 6,
      "name": "Prototype_Rock_Concrete_Brick_Half"
    },
    {
      "x": 20,
      "y": -11,
      "z": 7,
      "name": "Rock_Stone_Brick_Mossy"
    },
    {
      "x": 20,
      "y": -10,
      "z": 7,
      "name": "Rock_Stone_Brick"
    },
    {
      "x": 20,
      "y": -9,
      "z": 7,
      "name": "Rock_Shale_Brick"
    },
    {
      "x": 20,
      "y": -8,
      "z": 7,
      "name": "Prototype_Rock_Concrete_Brick"
    },
    {
      "x": 20,
      "y": -7,
      "z": 7,
      "name": "Prototype_Rock_Concrete_Brick_Half"
    },
    {
      "x": 20,
      "y": -11,
      "z": 8,
      "name": "Wood_Hardwood_Fence",
      "rotation": 1
    },
    {
      "x": 20,
      "y": -10,
      "z": 8,
      "name": "Wood_Hardwood_Fence",
      "rotation": 1
    },
    {
      "x": 20,
      "y": -9,
      "z": 8,
      "name": "Wood_Hardwood_Fence",
      "rotation": 1
    },
    {
      "x": 20,
      "y": -8,
      "z": 8,
      "name": "Prototype_Rock_Concrete_Brick_Half"
    },
    {
      "x": 21,
      "y": -10,
      "z": -6,
      "name": "*Furniture_Crude_Trapdoor_State_Definitions_OpenDoorOut",
      "rotation": 2
    },
    {
      "x": 21,
      "y": -8,
      "z": -6,
      "name": "Prototype_Rock_Concrete_Brick_Half",
      "rotation": 8
    },
    {
      "x": 21,
      "y": -11,
      "z": -5,
      "name": "Rock_Chalk_Brick_Wall"
    },
    {
      "x": 21,
      "y": -10,
      "z": -5,
      "name": "Rock_Stone_Cobble"
    },
    {
      "x": 21,
      "y": -9,
      "z": -5,
      "name": "Rock_Shale_Brick"
    },
    {
      "x": 21,
      "y": -8,
      "z": -5,
      "name": "Prototype_Rock_Concrete_Brick"
    },
    {
      "x": 21,
      "y": -7,
      "z": -5,
      "name": "Prototype_Rock_Concrete_Brick_Stairs",
      "rotation": 3
    },
    {
      "x": 21,
      "y": -11,
      "z": -4,
      "name": "Rock_Crystal_Cyan_Block"
    },
    {
      "x": 21,
      "y": -10,
      "z": -4,
      "name": "Rock_Crystal_Cyan_Block"
    },
    {
      "x": 21,
      "y": -9,
      "z": -4,
      "name": "Rock_Crystal_Cyan_Block"
    },
    {
      "x": 21,
      "y": -8,
      "z": -4,
      "name": "Rock_Shale_Brick_Half",
      "rotation": 8
    },
    {
      "x": 21,
      "y": -8,
      "z": -3,
      "name": "Rock_Shale_Cobble_Half",
      "rotation": 8
    },
    {
      "x": 21,
      "y": -8,
      "z": -2,
      "name": "Prototype_Rock_Concrete_Brick_Half",
      "rotation": 8
    },
    {
      "x": 21,
      "y": -8,
      "z": -1,
      "name": "Rock_Shale_Brick_Half",
      "rotation": 8
    },
    {
      "x": 21,
      "y": -8,
      "z": 0,
      "name": "Rock_Shale_Cobble_Half",
      "rotation": 8
    },
    {
      "x": 21,
      "y": -8,
      "z": 1,
      "name": "Rock_Crystal_Cyan_Block"
    },
    {
      "x": 21,
      "y": -7,
      "z": 1,
      "name": "Plant_Moss_Rug_Green_Dark"
    },
    {
      "x": 21,
      "y": -8,
      "z": 2,
      "name": "Rock_Shale_Cobble_Half",
      "rotation": 8
    },
    {
      "x": 21,
      "y": -8,
      "z": 3,
      "name": "Rock_Shale_Brick_Half",
      "rotation": 8
    },
    {
      "x": 21,
      "y": -8,
      "z": 4,
      "name": "Prototype_Rock_Concrete_Brick_Half",
      "rotation": 8
    },
    {
      "x": 21,
      "y": -8,
      "z": 5,
      "name": "Rock_Shale_Cobble_Half",
      "rotation": 8
    },
    {
      "x": 21,
      "y": -11,
      "z": 6,
      "name": "Rock_Crystal_Cyan_Block"
    },
    {
      "x": 21,
      "y": -10,
      "z": 6,
      "name": "Rock_Crystal_Cyan_Block"
    },
    {
      "x": 21,
      "y": -9,
      "z": 6,
      "name": "Rock_Crystal_Cyan_Block"
    },
    {
      "x": 21,
      "y": -8,
      "z": 6,
      "name": "Rock_Shale_Brick_Half",
      "rotation": 8
    },
    {
      "x": 21,
      "y": -11,
      "z": 7,
      "name": "Rock_Chalk_Brick_Wall"
    },
    {
      "x": 21,
      "y": -10,
      "z": 7,
      "name": "Rock_Stone_Cobble"
    },
    {
      "x": 21,
      "y": -9,
      "z": 7,
      "name": "Rock_Stone_Brick"
    },
    {
      "x": 21,
      "y": -8,
      "z": 7,
      "name": "Prototype_Rock_Concrete_Brick"
    },
    {
      "x": 21,
      "y": -7,
      "z": 7,
      "name": "Prototype_Rock_Concrete_Brick_Stairs",
      "rotation": 3
    },
    {
      "x": 21,
      "y": -10,
      "z": 8,
      "name": "*Furniture_Crude_Trapdoor_State_Definitions_OpenDoorOut"
    },
    {
      "x": 21,
      "y": -8,
      "z": 8,
      "name": "Prototype_Rock_Concrete_Brick_Half",
      "rotation": 8
    },
    {
      "x": 22,
      "y": -11,
      "z": -6,
      "name": "Wood_Hardwood_Fence",
      "rotation": 1
    },
    {
      "x": 22,
      "y": -10,
      "z": -6,
      "name": "Wood_Hardwood_Fence",
      "rotation": 1
    },
    {
      "x": 22,
      "y": -9,
      "z": -6,
      "name": "Wood_Hardwood_Fence",
      "rotation": 1
    },
    {
      "x": 22,
      "y": -8,
      "z": -6,
      "name": "Wood_Hardwood_Fence",
      "rotation": 1
    },
    {
      "x": 22,
      "y": -7,
      "z": -6,
      "name": "Prototype_Rock_Concrete_Brick_Half"
    },
    {
      "x": 22,
      "y": -11,
      "z": -5,
      "name": "Rock_Stone_Brick"
    },
    {
      "x": 22,
      "y": -10,
      "z": -5,
      "name": "Rock_Stone_Brick_Mossy"
    },
    {
      "x": 22,
      "y": -9,
      "z": -5,
      "name": "Rock_Stone_Brick_Mossy"
    },
    {
      "x": 22,
      "y": -8,
      "z": -5,
      "name": "Rock_Shale_Brick"
    },
    {
      "x": 22,
      "y": -7,
      "z": -5,
      "name": "Prototype_Rock_Concrete_Brick"
    },
    {
      "x": 22,
      "y": -6,
      "z": -5,
      "name": "Prototype_Rock_Concrete_Brick_Half"
    },
    {
      "x": 22,
      "y": -7,
      "z": -4,
      "name": "Rock_Shale_Brick_Half"
    },
    {
      "x": 22,
      "y": -7,
      "z": -3,
      "name": "Rock_Shale_Cobble_Half"
    },
    {
      "x": 22,
      "y": -7,
      "z": -2,
      "name": "Prototype_Rock_Concrete_Brick_Half"
    },
    {
      "x": 22,
      "y": -7,
      "z": -1,
      "name": "Rock_Shale_Brick_Half"
    },
    {
      "x": 22,
      "y": -7,
      "z": 0,
      "name": "Rock_Shale_Cobble_Half"
    },
    {
      "x": 22,
      "y": -7,
      "z": 1,
      "name": "Rock_Shale_Brick_Stairs",
      "rotation": 3
    },
    {
      "x": 22,
      "y": -7,
      "z": 2,
      "name": "Rock_Shale_Cobble_Half"
    },
    {
      "x": 22,
      "y": -7,
      "z": 3,
      "name": "Rock_Shale_Brick_Half"
    },
    {
      "x": 22,
      "y": -7,
      "z": 4,
      "name": "Prototype_Rock_Concrete_Brick_Half"
    },
    {
      "x": 22,
      "y": -7,
      "z": 5,
      "name": "Rock_Shale_Cobble_Half"
    },
    {
      "x": 22,
      "y": -7,
      "z": 6,
      "name": "Rock_Shale_Brick_Half"
    },
    {
      "x": 22,
      "y": -11,
      "z": 7,
      "name": "Rock_Stone_Brick_Mossy"
    },
    {
      "x": 22,
      "y": -10,
      "z": 7,
      "name": "Rock_Shale_Brick"
    },
    {
      "x": 22,
      "y": -9,
      "z": 7,
      "name": "Rock_Stone_Brick"
    },
    {
      "x": 22,
      "y": -8,
      "z": 7,
      "name": "Rock_Stone_Brick"
    },
    {
      "x": 22,
      "y": -7,
      "z": 7,
      "name": "Prototype_Rock_Concrete_Brick"
    },
    {
      "x": 22,
      "y": -6,
      "z": 7,
      "name": "Prototype_Rock_Concrete_Brick_Half"
    },
    {
      "x": 22,
      "y": -11,
      "z": 8,
      "name": "Wood_Hardwood_Fence",
      "rotation": 1
    },
    {
      "x": 22,
      "y": -10,
      "z": 8,
      "name": "Wood_Hardwood_Fence",
      "rotation": 1
    },
    {
      "x": 22,
      "y": -9,
      "z": 8,
      "name": "Wood_Hardwood_Fence",
      "rotation": 1
    },
    {
      "x": 22,
      "y": -8,
      "z": 8,
      "name": "Wood_Hardwood_Fence",
      "rotation": 1
    },
    {
      "x": 22,
      "y": -7,
      "z": 8,
      "name": "Prototype_Rock_Concrete_Brick_Half"
    },
    {
      "x": 23,
      "y": -9,
      "z": -6,
      "name": "*Furniture_Crude_Trapdoor_State_Definitions_OpenDoorOut",
      "rotation": 2
    },
    {
      "x": 23,
      "y": -7,
      "z": -6,
      "name": "Prototype_Rock_Concrete_Brick_Half",
      "rotation": 8
    },
    {
      "x": 23,
      "y": -11,
      "z": -5,
      "name": "Rock_Chalk_Brick_Wall"
    },
    {
      "x": 23,
      "y": -10,
      "z": -5,
      "name": "Rock_Chalk_Brick_Wall"
    },
    {
      "x": 23,
      "y": -9,
      "z": -5,
      "name": "Rock_Stone_Cobble"
    },
    {
      "x": 23,
      "y": -8,
      "z": -5,
      "name": "Rock_Stone_Brick_Mossy"
    },
    {
      "x": 23,
      "y": -7,
      "z": -5,
      "name": "Prototype_Rock_Concrete_Brick"
    },
    {
      "x": 23,
      "y": -6,
      "z": -5,
      "name": "Prototype_Rock_Concrete_Brick_Stairs",
      "rotation": 3
    },
    {
      "x": 23,
      "y": -11,
      "z": -4,
      "name": "Rock_Crystal_Cyan_Block"
    },
    {
      "x": 23,
      "y": -10,
      "z": -4,
      "name": "Rock_Crystal_Cyan_Block"
    },
    {
      "x": 23,
      "y": -9,
      "z": -4,
      "name": "Rock_Crystal_Cyan_Block"
    },
    {
      "x": 23,
      "y": -8,
      "z": -4,
      "name": "Rock_Crystal_Cyan_Block"
    },
    {
      "x": 23,
      "y": -7,
      "z": -4,
      "name": "Rock_Shale_Brick_Half",
      "rotation": 8
    },
    {
      "x": 23,
      "y": -7,
      "z": -3,
      "name": "Rock_Shale_Cobble_Half",
      "rotation": 8
    },
    {
      "x": 23,
      "y": -7,
      "z": -2,
      "name": "Prototype_Rock_Concrete_Brick_Half",
      "rotation": 8
    },
    {
      "x": 23,
      "y": -7,
      "z": -1,
      "name": "Rock_Shale_Brick_Half",
      "rotation": 8
    },
    {
      "x": 23,
      "y": -7,
      "z": 0,
      "name": "Rock_Shale_Cobble_Half",
      "rotation": 8
    },
    {
      "x": 23,
      "y": -7,
      "z": 1,
      "name": "Rock_Crystal_Cyan_Block"
    },
    {
      "x": 23,
      "y": -6,
      "z": 1,
      "name": "Plant_Moss_Rug_Green_Dark"
    },
    {
      "x": 23,
      "y": -7,
      "z": 2,
      "name": "Rock_Shale_Cobble_Half",
      "rotation": 8
    },
    {
      "x": 23,
      "y": -7,
      "z": 3,
      "name": "Rock_Shale_Brick_Half",
      "rotation": 8
    },
    {
      "x": 23,
      "y": -7,
      "z": 4,
      "name": "Prototype_Rock_Concrete_Brick_Half",
      "rotation": 8
    },
    {
      "x": 23,
      "y": -7,
      "z": 5,
      "name": "Rock_Shale_Cobble_Half",
      "rotation": 8
    },
    {
      "x": 23,
      "y": -11,
      "z": 6,
      "name": "Rock_Crystal_Cyan_Block"
    },
    {
      "x": 23,
      "y": -10,
      "z": 6,
      "name": "Rock_Crystal_Cyan_Block"
    },
    {
      "x": 23,
      "y": -9,
      "z": 6,
      "name": "Rock_Crystal_Cyan_Block"
    },
    {
      "x": 23,
      "y": -8,
      "z": 6,
      "name": "Rock_Crystal_Cyan_Block"
    },
    {
      "x": 23,
      "y": -7,
      "z": 6,
      "name": "Rock_Shale_Brick_Half",
      "rotation": 8
    },
    {
      "x": 23,
      "y": -11,
      "z": 7,
      "name": "Rock_Chalk_Brick_Wall"
    },
    {
      "x": 23,
      "y": -10,
      "z": 7,
      "name": "Rock_Chalk_Brick_Wall"
    },
    {
      "x": 23,
      "y": -9,
      "z": 7,
      "name": "Rock_Stone_Cobble"
    },
    {
      "x": 23,
      "y": -8,
      "z": 7,
      "name": "Rock_Shale_Brick"
    },
    {
      "x": 23,
      "y": -7,
      "z": 7,
      "name": "Prototype_Rock_Concrete_Brick"
    },
    {
      "x": 23,
      "y": -6,
      "z": 7,
      "name": "Prototype_Rock_Concrete_Brick_Stairs",
      "rotation": 3
    },
    {
      "x": 23,
      "y": -9,
      "z": 8,
      "name": "*Furniture_Crude_Trapdoor_State_Definitions_OpenDoorOut"
    },
    {
      "x": 23,
      "y": -7,
      "z": 8,
      "name": "Prototype_Rock_Concrete_Brick_Half",
      "rotation": 8
    },
    {
      "x": 24,
      "y": -11,
      "z": -6,
      "name": "Wood_Hardwood_Fence",
      "rotation": 1
    },
    {
      "x": 24,
      "y": -10,
      "z": -6,
      "name": "Wood_Hardwood_Fence",
      "rotation": 1
    },
    {
      "x": 24,
      "y": -9,
      "z": -6,
      "name": "Wood_Hardwood_Fence",
      "rotation": 1
    },
    {
      "x": 24,
      "y": -8,
      "z": -6,
      "name": "Wood_Hardwood_Fence",
      "rotation": 1
    },
    {
      "x": 24,
      "y": -7,
      "z": -6,
      "name": "Wood_Hardwood_Fence",
      "rotation": 1
    },
    {
      "x": 24,
      "y": -6,
      "z": -6,
      "name": "Prototype_Rock_Concrete_Brick_Half"
    },
    {
      "x": 24,
      "y": -11,
      "z": -5,
      "name": "Rock_Shale_Brick"
    },
    {
      "x": 24,
      "y": -10,
      "z": -5,
      "name": "Rock_Stone_Brick_Mossy"
    },
    {
      "x": 24,
      "y": -9,
      "z": -5,
      "name": "Rock_Shale_Brick"
    },
    {
      "x": 24,
      "y": -8,
      "z": -5,
      "name": "Rock_Stone_Brick"
    },
    {
      "x": 24,
      "y": -7,
      "z": -5,
      "name": "Rock_Stone_Brick"
    },
    {
      "x": 24,
      "y": -6,
      "z": -5,
      "name": "Prototype_Rock_Concrete_Brick"
    },
    {
      "x": 24,
      "y": -5,
      "z": -5,
      "name": "Prototype_Rock_Concrete_Brick_Half"
    },
    {
      "x": 24,
      "y": -6,
      "z": -4,
      "name": "Rock_Shale_Brick_Half"
    },
    {
      "x": 24,
      "y": -6,
      "z": -3,
      "name": "Rock_Shale_Cobble_Half"
    },
    {
      "x": 24,
      "y": -6,
      "z": -2,
      "name": "Prototype_Rock_Concrete_Brick_Half"
    },
    {
      "x": 24,
      "y": -6,
      "z": -1,
      "name": "Rock_Shale_Brick_Half"
    },
    {
      "x": 24,
      "y": -6,
      "z": 0,
      "name": "Rock_Shale_Cobble_Half"
    },
    {
      "x": 24,
      "y": -6,
      "z": 1,
      "name": "Rock_Shale_Brick_Stairs",
      "rotation": 3
    },
    {
      "x": 24,
      "y": -6,
      "z": 2,
      "name": "Rock_Shale_Cobble_Half"
    },
    {
      "x": 24,
      "y": -6,
      "z": 3,
      "name": "Rock_Shale_Brick_Half"
    },
    {
      "x": 24,
      "y": -6,
      "z": 4,
      "name": "Prototype_Rock_Concrete_Brick_Half"
    },
    {
      "x": 24,
      "y": -6,
      "z": 5,
      "name": "Rock_Shale_Cobble_Half"
    },
    {
      "x": 24,
      "y": -6,
      "z": 6,
      "name": "Rock_Shale_Brick_Half"
    },
    {
      "x": 24,
      "y": -11,
      "z": 7,
      "name": "Rock_Shale_Brick"
    },
    {
      "x": 24,
      "y": -10,
      "z": 7,
      "name": "Rock_Stone_Brick_Mossy"
    },
    {
      "x": 24,
      "y": -9,
      "z": 7,
      "name": "Rock_Shale_Brick"
    },
    {
      "x": 24,
      "y": -8,
      "z": 7,
      "name": "Rock_Stone_Brick_Mossy"
    },
    {
      "x": 24,
      "y": -7,
      "z": 7,
      "name": "Rock_Stone_Brick"
    },
    {
      "x": 24,
      "y": -6,
      "z": 7,
      "name": "Prototype_Rock_Concrete_Brick"
    },
    {
      "x": 24,
      "y": -5,
      "z": 7,
      "name": "Prototype_Rock_Concrete_Brick_Half"
    },
    {
      "x": 24,
      "y": -11,
      "z": 8,
      "name": "Wood_Hardwood_Fence",
      "rotation": 1
    },
    {
      "x": 24,
      "y": -10,
      "z": 8,
      "name": "Wood_Hardwood_Fence",
      "rotation": 1
    },
    {
      "x": 24,
      "y": -9,
      "z": 8,
      "name": "Wood_Hardwood_Fence",
      "rotation": 1
    },
    {
      "x": 24,
      "y": -8,
      "z": 8,
      "name": "Wood_Hardwood_Fence",
      "rotation": 1
    },
    {
      "x": 24,
      "y": -7,
      "z": 8,
      "name": "Wood_Hardwood_Fence",
      "rotation": 1
    },
    {
      "x": 24,
      "y": -6,
      "z": 8,
      "name": "Prototype_Rock_Concrete_Brick_Half"
    },
    {
      "x": 25,
      "y": -8,
      "z": -6,
      "name": "*Furniture_Crude_Trapdoor_State_Definitions_OpenDoorOut",
      "rotation": 2
    },
    {
      "x": 25,
      "y": -6,
      "z": -6,
      "name": "Prototype_Rock_Concrete_Brick_Half",
      "rotation": 8
    },
    {
      "x": 25,
      "y": -11,
      "z": -5,
      "name": "Rock_Chalk_Brick_Wall"
    },
    {
      "x": 25,
      "y": -10,
      "z": -5,
      "name": "Rock_Chalk_Brick_Wall"
    },
    {
      "x": 25,
      "y": -9,
      "z": -5,
      "name": "Rock_Chalk_Brick_Wall"
    },
    {
      "x": 25,
      "y": -8,
      "z": -5,
      "name": "Rock_Stone_Cobble"
    },
    {
      "x": 25,
      "y": -7,
      "z": -5,
      "name": "Rock_Shale_Brick"
    },
    {
      "x": 25,
      "y": -6,
      "z": -5,
      "name": "Prototype_Rock_Concrete_Brick"
    },
    {
      "x": 25,
      "y": -5,
      "z": -5,
      "name": "Prototype_Rock_Concrete_Brick_Stairs",
      "rotation": 3
    },
    {
      "x": 25,
      "y": -11,
      "z": -4,
      "name": "Rock_Crystal_Cyan_Block"
    },
    {
      "x": 25,
      "y": -10,
      "z": -4,
      "name": "Rock_Crystal_Cyan_Block"
    },
    {
      "x": 25,
      "y": -9,
      "z": -4,
      "name": "Rock_Crystal_Cyan_Block"
    },
    {
      "x": 25,
      "y": -8,
      "z": -4,
      "name": "Rock_Crystal_Cyan_Block"
    },
    {
      "x": 25,
      "y": -7,
      "z": -4,
      "name": "Rock_Crystal_Cyan_Block"
    },
    {
      "x": 25,
      "y": -6,
      "z": -4,
      "name": "Prototype_Rock_Concrete_Brick_Half",
      "rotation": 8
    },
    {
      "x": 25,
      "y": -6,
      "z": -3,
      "name": "Rock_Shale_Brick_Half",
      "rotation": 8
    },
    {
      "x": 25,
      "y": -6,
      "z": -2,
      "name": "Rock_Shale_Cobble_Half",
      "rotation": 8
    },
    {
      "x": 25,
      "y": -6,
      "z": -1,
      "name": "Prototype_Rock_Concrete_Brick_Half",
      "rotation": 8
    },
    {
      "x": 25,
      "y": -6,
      "z": 0,
      "name": "Rock_Shale_Brick_Half",
      "rotation": 8
    },
    {
      "x": 25,
      "y": -6,
      "z": 1,
      "name": "Rock_Crystal_Cyan_Block"
    },
    {
      "x": 25,
      "y": -5,
      "z": 1,
      "name": "Plant_Moss_Rug_Green_Dark"
    },
    {
      "x": 25,
      "y": -6,
      "z": 2,
      "name": "Rock_Shale_Brick_Half",
      "rotation": 8
    },
    {
      "x": 25,
      "y": -6,
      "z": 3,
      "name": "Prototype_Rock_Concrete_Brick_Half",
      "rotation": 8
    },
    {
      "x": 25,
      "y": -6,
      "z": 4,
      "name": "Rock_Shale_Cobble_Half",
      "rotation": 8
    },
    {
      "x": 25,
      "y": -6,
      "z": 5,
      "name": "Rock_Shale_Brick_Half",
      "rotation": 8
    },
    {
      "x": 25,
      "y": -11,
      "z": 6,
      "name": "Rock_Crystal_Cyan_Block"
    },
    {
      "x": 25,
      "y": -10,
      "z": 6,
      "name": "Rock_Crystal_Cyan_Block"
    },
    {
      "x": 25,
      "y": -9,
      "z": 6,
      "name": "Rock_Crystal_Cyan_Block"
    },
    {
      "x": 25,
      "y": -8,
      "z": 6,
      "name": "Rock_Crystal_Cyan_Block"
    },
    {
      "x": 25,
      "y": -7,
      "z": 6,
      "name": "Rock_Crystal_Cyan_Block"
    },
    {
      "x": 25,
      "y": -6,
      "z": 6,
      "name": "Prototype_Rock_Concrete_Brick_Half",
      "rotation": 8
    },
    {
      "x": 25,
      "y": -11,
      "z": 7,
      "name": "Rock_Chalk_Brick_Wall"
    },
    {
      "x": 25,
      "y": -10,
      "z": 7,
      "name": "Rock_Chalk_Brick_Wall"
    },
    {
      "x": 25,
      "y": -9,
      "z": 7,
      "name": "Rock_Chalk_Brick_Wall"
    },
    {
      "x": 25,
      "y": -8,
      "z": 7,
      "name": "Rock_Stone_Cobble"
    },
    {
      "x": 25,
      "y": -7,
      "z": 7,
      "name": "Rock_Shale_Brick"
    },
    {
      "x": 25,
      "y": -6,
      "z": 7,
      "name": "Prototype_Rock_Concrete_Brick"
    },
    {
      "x": 25,
      "y": -5,
      "z": 7,
      "name": "Prototype_Rock_Concrete_Brick_Stairs",
      "rotation": 3
    },
    {
      "x": 25,
      "y": -8,
      "z": 8,
      "name": "*Furniture_Crude_Trapdoor_State_Definitions_OpenDoorOut"
    },
    {
      "x": 25,
      "y": -6,
      "z": 8,
      "name": "Prototype_Rock_Concrete_Brick_Half",
      "rotation": 8
    },
    {
      "x": 26,
      "y": -11,
      "z": -6,
      "name": "Wood_Hardwood_Fence",
      "rotation": 1
    },
    {
      "x": 26,
      "y": -10,
      "z": -6,
      "name": "Wood_Hardwood_Fence",
      "rotation": 1
    },
    {
      "x": 26,
      "y": -9,
      "z": -6,
      "name": "Wood_Hardwood_Fence",
      "rotation": 1
    },
    {
      "x": 26,
      "y": -8,
      "z": -6,
      "name": "Wood_Hardwood_Fence",
      "rotation": 1
    },
    {
      "x": 26,
      "y": -7,
      "z": -6,
      "name": "Wood_Hardwood_Fence",
      "rotation": 1
    },
    {
      "x": 26,
      "y": -6,
      "z": -6,
      "name": "Wood_Hardwood_Fence",
      "rotation": 1
    },
    {
      "x": 26,
      "y": -5,
      "z": -6,
      "name": "Prototype_Rock_Concrete_Brick_Half"
    },
    {
      "x": 26,
      "y": -11,
      "z": -5,
      "name": "Rock_Stone_Brick_Mossy"
    },
    {
      "x": 26,
      "y": -10,
      "z": -5,
      "name": "Rock_Stone_Brick"
    },
    {
      "x": 26,
      "y": -9,
      "z": -5,
      "name": "Rock_Stone_Brick"
    },
    {
      "x": 26,
      "y": -8,
      "z": -5,
      "name": "Rock_Shale_Brick"
    },
    {
      "x": 26,
      "y": -7,
      "z": -5,
      "name": "Rock_Stone_Brick"
    },
    {
      "x": 26,
      "y": -6,
      "z": -5,
      "name": "Rock_Stone_Brick"
    },
    {
      "x": 26,
      "y": -5,
      "z": -5,
      "name": "Prototype_Rock_Concrete_Brick"
    },
    {
      "x": 26,
      "y": -4,
      "z": -5,
      "name": "Prototype_Rock_Concrete_Brick_Half"
    },
    {
      "x": 26,
      "y": -5,
      "z": -4,
      "name": "Prototype_Rock_Concrete_Brick_Stairs",
      "rotation": 3
    },
    {
      "x": 26,
      "y": -5,
      "z": -3,
      "name": "Rock_Shale_Brick_Half"
    },
    {
      "x": 26,
      "y": -5,
      "z": -2,
      "name": "Rock_Shale_Cobble_Half"
    },
    {
      "x": 26,
      "y": -5,
      "z": -1,
      "name": "Prototype_Rock_Concrete_Brick_Half"
    },
    {
      "x": 26,
      "y": -5,
      "z": 0,
      "name": "Rock_Shale_Brick_Half"
    },
    {
      "x": 26,
      "y": -5,
      "z": 1,
      "name": "Rock_Shale_Cobble_Half"
    },
    {
      "x": 26,
      "y": -5,
      "z": 2,
      "name": "Rock_Shale_Brick_Half"
    },
    {
      "x": 26,
      "y": -5,
      "z": 3,
      "name": "Prototype_Rock_Concrete_Brick_Half"
    },
    {
      "x": 26,
      "y": -5,
      "z": 4,
      "name": "Rock_Shale_Cobble_Half"
    },
    {
      "x": 26,
      "y": -5,
      "z": 5,
      "name": "Rock_Shale_Brick_Half"
    },
    {
      "x": 26,
      "y": -5,
      "z": 6,
      "name": "Prototype_Rock_Concrete_Brick_Stairs",
      "rotation": 3
    },
    {
      "x": 26,
      "y": -11,
      "z": 7,
      "name": "Rock_Stone_Brick"
    },
    {
      "x": 26,
      "y": -10,
      "z": 7,
      "name": "Rock_Stone_Brick"
    },
    {
      "x": 26,
      "y": -9,
      "z": 7,
      "name": "Rock_Stone_Brick"
    },
    {
      "x": 26,
      "y": -8,
      "z": 7,
      "name": "Rock_Stone_Brick_Mossy"
    },
    {
      "x": 26,
      "y": -7,
      "z": 7,
      "name": "Rock_Stone_Brick_Mossy"
    },
    {
      "x": 26,
      "y": -6,
      "z": 7,
      "name": "Rock_Stone_Brick_Mossy"
    },
    {
      "x": 26,
      "y": -5,
      "z": 7,
      "name": "Prototype_Rock_Concrete_Brick"
    },
    {
      "x": 26,
      "y": -4,
      "z": 7,
      "name": "Prototype_Rock_Concrete_Brick_Half"
    },
    {
      "x": 26,
      "y": -11,
      "z": 8,
      "name": "Wood_Hardwood_Fence",
      "rotation": 1
    },
    {
      "x": 26,
      "y": -10,
      "z": 8,
      "name": "Wood_Hardwood_Fence",
      "rotation": 1
    },
    {
      "x": 26,
      "y": -9,
      "z": 8,
      "name": "Wood_Hardwood_Fence",
      "rotation": 1
    },
    {
      "x": 26,
      "y": -8,
      "z": 8,
      "name": "Wood_Hardwood_Fence",
      "rotation": 1
    },
    {
      "x": 26,
      "y": -7,
      "z": 8,
      "name": "Wood_Hardwood_Fence",
      "rotation": 1
    },
    {
      "x": 26,
      "y": -6,
      "z": 8,
      "name": "Wood_Hardwood_Fence",
      "rotation": 1
    },
    {
      "x": 26,
      "y": -5,
      "z": 8,
      "name": "Prototype_Rock_Concrete_Brick_Half"
    },
    {
      "x": 27,
      "y": -7,
      "z": -6,
      "name": "*Furniture_Crude_Trapdoor_State_Definitions_OpenDoorOut",
      "rotation": 2
    },
    {
      "x": 27,
      "y": -5,
      "z": -6,
      "name": "Prototype_Rock_Concrete_Brick_Half",
      "rotation": 8
    },
    {
      "x": 27,
      "y": -11,
      "z": -5,
      "name": "Rock_Chalk_Brick_Wall"
    },
    {
      "x": 27,
      "y": -10,
      "z": -5,
      "name": "Rock_Chalk_Brick_Wall"
    },
    {
      "x": 27,
      "y": -9,
      "z": -5,
      "name": "Rock_Chalk_Brick_Wall"
    },
    {
      "x": 27,
      "y": -8,
      "z": -5,
      "name": "Rock_Chalk_Brick_Wall"
    },
    {
      "x": 27,
      "y": -7,
      "z": -5,
      "name": "Rock_Stone_Cobble"
    },
    {
      "x": 27,
      "y": -6,
      "z": -5,
      "name": "Rock_Stone_Brick"
    },
    {
      "x": 27,
      "y": -5,
      "z": -5,
      "name": "Prototype_Rock_Concrete_Brick"
    },
    {
      "x": 27,
      "y": -4,
      "z": -5,
      "name": "Prototype_Rock_Concrete_Brick_Stairs",
      "rotation": 3
    },
    {
      "x": 27,
      "y": -11,
      "z": -4,
      "name": "Rock_Crystal_Cyan_Block"
    },
    {
      "x": 27,
      "y": -10,
      "z": -4,
      "name": "Rock_Crystal_Cyan_Block"
    },
    {
      "x": 27,
      "y": -9,
      "z": -4,
      "name": "Rock_Crystal_Cyan_Block"
    },
    {
      "x": 27,
      "y": -8,
      "z": -4,
      "name": "Rock_Crystal_Cyan_Block"
    },
    {
      "x": 27,
      "y": -7,
      "z": -4,
      "name": "Rock_Crystal_Cyan_Block"
    },
    {
      "x": 27,
      "y": -6,
      "z": -4,
      "name": "Rock_Crystal_Cyan_Block"
    },
    {
      "x": 27,
      "y": -5,
      "z": -4,
      "name": "Rock_Crystal_Cyan_Block"
    },
    {
      "x": 27,
      "y": -4,
      "z": -4,
      "name": "Plant_Moss_Rug_Green_Dark"
    },
    {
      "x": 27,
      "y": -5,
      "z": -3,
      "name": "Rock_Shale_Brick_Half",
      "rotation": 8
    },
    {
      "x": 27,
      "y": -5,
      "z": -2,
      "name": "Rock_Shale_Cobble_Half",
      "rotation": 8
    },
    {
      "x": 27,
      "y": -5,
      "z": -1,
      "name": "Prototype_Rock_Concrete_Brick_Half",
      "rotation": 8
    },
    {
      "x": 27,
      "y": -5,
      "z": 0,
      "name": "Rock_Shale_Brick_Half",
      "rotation": 8
    },
    {
      "x": 27,
      "y": -5,
      "z": 1,
      "name": "Rock_Shale_Cobble_Half",
      "rotation": 8
    },
    {
      "x": 27,
      "y": -5,
      "z": 2,
      "name": "Rock_Shale_Brick_Half",
      "rotation": 8
    },
    {
      "x": 27,
      "y": -5,
      "z": 3,
      "name": "Prototype_Rock_Concrete_Brick_Half",
      "rotation": 8
    },
    {
      "x": 27,
      "y": -5,
      "z": 4,
      "name": "Rock_Shale_Cobble_Half",
      "rotation": 8
    },
    {
      "x": 27,
      "y": -5,
      "z": 5,
      "name": "Rock_Shale_Brick_Half",
      "rotation": 8
    },
    {
      "x": 27,
      "y": -11,
      "z": 6,
      "name": "Rock_Crystal_Cyan_Block"
    },
    {
      "x": 27,
      "y": -10,
      "z": 6,
      "name": "Rock_Crystal_Cyan_Block"
    },
    {
      "x": 27,
      "y": -9,
      "z": 6,
      "name": "Rock_Crystal_Cyan_Block"
    },
    {
      "x": 27,
      "y": -8,
      "z": 6,
      "name": "Rock_Crystal_Cyan_Block"
    },
    {
      "x": 27,
      "y": -7,
      "z": 6,
      "name": "Rock_Crystal_Cyan_Block"
    },
    {
      "x": 27,
      "y": -6,
      "z": 6,
      "name": "Rock_Crystal_Cyan_Block"
    },
    {
      "x": 27,
      "y": -5,
      "z": 6,
      "name": "Rock_Crystal_Cyan_Block"
    },
    {
      "x": 27,
      "y": -4,
      "z": 6,
      "name": "Plant_Moss_Rug_Green_Dark"
    },
    {
      "x": 27,
      "y": -11,
      "z": 7,
      "name": "Rock_Chalk_Brick_Wall"
    },
    {
      "x": 27,
      "y": -10,
      "z": 7,
      "name": "Rock_Chalk_Brick_Wall"
    },
    {
      "x": 27,
      "y": -9,
      "z": 7,
      "name": "Rock_Chalk_Brick_Wall"
    },
    {
      "x": 27,
      "y": -8,
      "z": 7,
      "name": "Rock_Chalk_Brick_Wall"
    },
    {
      "x": 27,
      "y": -7,
      "z": 7,
      "name": "Rock_Stone_Cobble"
    },
    {
      "x": 27,
      "y": -6,
      "z": 7,
      "name": "Rock_Stone_Brick"
    },
    {
      "x": 27,
      "y": -5,
      "z": 7,
      "name": "Prototype_Rock_Concrete_Brick"
    },
    {
      "x": 27,
      "y": -4,
      "z": 7,
      "name": "Prototype_Rock_Concrete_Brick_Stairs",
      "rotation": 3
    },
    {
      "x": 27,
      "y": -7,
      "z": 8,
      "name": "*Furniture_Crude_Trapdoor_State_Definitions_OpenDoorOut"
    },
    {
      "x": 27,
      "y": -5,
      "z": 8,
      "name": "Prototype_Rock_Concrete_Brick_Half",
      "rotation": 8
    },
    {
      "x": 28,
      "y": -11,
      "z": -6,
      "name": "Wood_Hardwood_Fence",
      "rotation": 1
    },
    {
      "x": 28,
      "y": -10,
      "z": -6,
      "name": "Wood_Hardwood_Fence",
      "rotation": 1
    },
    {
      "x": 28,
      "y": -9,
      "z": -6,
      "name": "Wood_Hardwood_Fence",
      "rotation": 1
    },
    {
      "x": 28,
      "y": -8,
      "z": -6,
      "name": "Wood_Hardwood_Fence",
      "rotation": 1
    },
    {
      "x": 28,
      "y": -7,
      "z": -6,
      "name": "Wood_Hardwood_Fence",
      "rotation": 1
    },
    {
      "x": 28,
      "y": -6,
      "z": -6,
      "name": "Wood_Hardwood_Fence",
      "rotation": 1
    },
    {
      "x": 28,
      "y": -5,
      "z": -6,
      "name": "Wood_Hardwood_Fence",
      "rotation": 1
    },
    {
      "x": 28,
      "y": -4,
      "z": -6,
      "name": "Prototype_Rock_Concrete_Brick_Half"
    },
    {
      "x": 28,
      "y": -11,
      "z": -5,
      "name": "Rock_Stone_Brick_Mossy"
    },
    {
      "x": 28,
      "y": -10,
      "z": -5,
      "name": "Rock_Stone_Brick"
    },
    {
      "x": 28,
      "y": -9,
      "z": -5,
      "name": "Rock_Shale_Brick"
    },
    {
      "x": 28,
      "y": -8,
      "z": -5,
      "name": "Rock_Stone_Brick"
    },
    {
      "x": 28,
      "y": -7,
      "z": -5,
      "name": "Rock_Stone_Brick"
    },
    {
      "x": 28,
      "y": -6,
      "z": -5,
      "name": "Rock_Stone_Brick_Mossy"
    },
    {
      "x": 28,
      "y": -5,
      "z": -5,
      "name": "Rock_Stone_Brick_Mossy"
    },
    {
      "x": 28,
      "y": -4,
      "z": -5,
      "name": "Prototype_Rock_Concrete_Brick"
    },
    {
      "x": 28,
      "y": -3,
      "z": -5,
      "name": "Prototype_Rock_Concrete_Brick_Half"
    },
    {
      "x": 28,
      "y": -4,
      "z": -4,
      "name": "Prototype_Rock_Concrete_Brick_Half"
    },
    {
      "x": 28,
      "y": -4,
      "z": -3,
      "name": "Rock_Shale_Brick_Half"
    },
    {
      "x": 28,
      "y": -4,
      "z": -2,
      "name": "Rock_Shale_Cobble_Half"
    },
    {
      "x": 28,
      "y": -4,
      "z": -1,
      "name": "Prototype_Rock_Concrete_Brick_Half"
    },
    {
      "x": 28,
      "y": -4,
      "z": 0,
      "name": "Rock_Shale_Brick_Half"
    },
    {
      "x": 28,
      "y": -4,
      "z": 1,
      "name": "Rock_Shale_Cobble_Stairs",
      "rotation": 3
    },
    {
      "x": 28,
      "y": -4,
      "z": 2,
      "name": "Rock_Shale_Brick_Half"
    },
    {
      "x": 28,
      "y": -4,
      "z": 3,
      "name": "Prototype_Rock_Concrete_Brick_Half"
    },
    {
      "x": 28,
      "y": -4,
      "z": 4,
      "name": "Rock_Shale_Cobble_Half"
    },
    {
      "x": 28,
      "y": -4,
      "z": 5,
      "name": "Rock_Shale_Brick_Half"
    },
    {
      "x": 28,
      "y": -4,
      "z": 6,
      "name": "Prototype_Rock_Concrete_Brick_Half"
    },
    {
      "x": 28,
      "y": -11,
      "z": 7,
      "name": "Rock_Shale_Brick"
    },
    {
      "x": 28,
      "y": -10,
      "z": 7,
      "name": "Rock_Shale_Brick"
    },
    {
      "x": 28,
      "y": -9,
      "z": 7,
      "name": "Rock_Stone_Brick"
    },
    {
      "x": 28,
      "y": -8,
      "z": 7,
      "name": "Rock_Stone_Brick"
    },
    {
      "x": 28,
      "y": -7,
      "z": 7,
      "name": "Rock_Stone_Brick_Mossy"
    },
    {
      "x": 28,
      "y": -6,
      "z": 7,
      "name": "Rock_Stone_Brick_Mossy"
    },
    {
      "x": 28,
      "y": -5,
      "z": 7,
      "name": "Rock_Stone_Brick"
    },
    {
      "x": 28,
      "y": -4,
      "z": 7,
      "name": "Prototype_Rock_Concrete_Brick"
    },
    {
      "x": 28,
      "y": -3,
      "z": 7,
      "name": "Prototype_Rock_Concrete_Brick_Half"
    },
    {
      "x": 28,
      "y": -11,
      "z": 8,
      "name": "Wood_Hardwood_Fence",
      "rotation": 1
    },
    {
      "x": 28,
      "y": -10,
      "z": 8,
      "name": "Wood_Hardwood_Fence",
      "rotation": 1
    },
    {
      "x": 28,
      "y": -9,
      "z": 8,
      "name": "Wood_Hardwood_Fence",
      "rotation": 1
    },
    {
      "x": 28,
      "y": -8,
      "z": 8,
      "name": "Wood_Hardwood_Fence",
      "rotation": 1
    },
    {
      "x": 28,
      "y": -7,
      "z": 8,
      "name": "Wood_Hardwood_Fence",
      "rotation": 1
    },
    {
      "x": 28,
      "y": -6,
      "z": 8,
      "name": "Wood_Hardwood_Fence",
      "rotation": 1
    },
    {
      "x": 28,
      "y": -5,
      "z": 8,
      "name": "Wood_Hardwood_Fence",
      "rotation": 1
    },
    {
      "x": 28,
      "y": -4,
      "z": 8,
      "name": "Prototype_Rock_Concrete_Brick_Half"
    },
    {
      "x": 29,
      "y": -6,
      "z": -6,
      "name": "*Furniture_Crude_Trapdoor_State_Definitions_OpenDoorOut",
      "rotation": 2
    },
    {
      "x": 29,
      "y": -4,
      "z": -6,
      "name": "Prototype_Rock_Concrete_Brick_Half",
      "rotation": 8
    },
    {
      "x": 29,
      "y": -11,
      "z": -5,
      "name": "Rock_Chalk_Brick_Wall"
    },
    {
      "x": 29,
      "y": -10,
      "z": -5,
      "name": "Rock_Chalk_Brick_Wall"
    },
    {
      "x": 29,
      "y": -9,
      "z": -5,
      "name": "Rock_Chalk_Brick_Wall"
    },
    {
      "x": 29,
      "y": -8,
      "z": -5,
      "name": "Rock_Chalk_Brick_Wall"
    },
    {
      "x": 29,
      "y": -7,
      "z": -5,
      "name": "Rock_Chalk_Brick_Wall"
    },
    {
      "x": 29,
      "y": -6,
      "z": -5,
      "name": "Rock_Stone_Cobble"
    },
    {
      "x": 29,
      "y": -5,
      "z": -5,
      "name": "Rock_Stone_Brick"
    },
    {
      "x": 29,
      "y": -4,
      "z": -5,
      "name": "Prototype_Rock_Concrete_Brick"
    },
    {
      "x": 29,
      "y": -3,
      "z": -5,
      "name": "Prototype_Rock_Concrete_Brick_Stairs",
      "rotation": 3
    },
    {
      "x": 29,
      "y": -11,
      "z": -4,
      "name": "Rock_Crystal_Cyan_Block"
    },
    {
      "x": 29,
      "y": -10,
      "z": -4,
      "name": "Rock_Crystal_Cyan_Block"
    },
    {
      "x": 29,
      "y": -9,
      "z": -4,
      "name": "Rock_Crystal_Cyan_Block"
    },
    {
      "x": 29,
      "y": -8,
      "z": -4,
      "name": "Rock_Crystal_Cyan_Block"
    },
    {
      "x": 29,
      "y": -7,
      "z": -4,
      "name": "Rock_Crystal_Cyan_Block"
    },
    {
      "x": 29,
      "y": -6,
      "z": -4,
      "name": "Rock_Crystal_Cyan_Block"
    },
    {
      "x": 29,
      "y": -5,
      "z": -4,
      "name": "Rock_Crystal_Cyan_Block"
    },
    {
      "x": 29,
      "y": -4,
      "z": -4,
      "name": "Prototype_Rock_Concrete_Brick_Half",
      "rotation": 8
    },
    {
      "x": 29,
      "y": -4,
      "z": -3,
      "name": "Rock_Shale_Brick_Half",
      "rotation": 8
    },
    {
      "x": 29,
      "y": -4,
      "z": -2,
      "name": "Rock_Shale_Cobble_Half",
      "rotation": 8
    },
    {
      "x": 29,
      "y": -4,
      "z": -1,
      "name": "Prototype_Rock_Concrete_Brick_Half",
      "rotation": 8
    },
    {
      "x": 29,
      "y": -4,
      "z": 0,
      "name": "Rock_Shale_Brick_Half",
      "rotation": 8
    },
    {
      "x": 29,
      "y": -4,
      "z": 1,
      "name": "Rock_Crystal_Cyan_Block"
    },
    {
      "x": 29,
      "y": -3,
      "z": 1,
      "name": "Plant_Moss_Rug_Green_Dark"
    },
    {
      "x": 29,
      "y": -4,
      "z": 2,
      "name": "Rock_Shale_Brick_Half",
      "rotation": 8
    },
    {
      "x": 29,
      "y": -4,
      "z": 3,
      "name": "Prototype_Rock_Concrete_Brick_Half",
      "rotation": 8
    },
    {
      "x": 29,
      "y": -4,
      "z": 4,
      "name": "Rock_Shale_Cobble_Half",
      "rotation": 8
    },
    {
      "x": 29,
      "y": -4,
      "z": 5,
      "name": "Rock_Shale_Brick_Half",
      "rotation": 8
    },
    {
      "x": 29,
      "y": -11,
      "z": 6,
      "name": "Rock_Crystal_Cyan_Block"
    },
    {
      "x": 29,
      "y": -10,
      "z": 6,
      "name": "Rock_Crystal_Cyan_Block"
    },
    {
      "x": 29,
      "y": -9,
      "z": 6,
      "name": "Rock_Crystal_Cyan_Block"
    },
    {
      "x": 29,
      "y": -8,
      "z": 6,
      "name": "Rock_Crystal_Cyan_Block"
    },
    {
      "x": 29,
      "y": -7,
      "z": 6,
      "name": "Rock_Crystal_Cyan_Block"
    },
    {
      "x": 29,
      "y": -6,
      "z": 6,
      "name": "Rock_Crystal_Cyan_Block"
    },
    {
      "x": 29,
      "y": -5,
      "z": 6,
      "name": "Rock_Crystal_Cyan_Block"
    },
    {
      "x": 29,
      "y": -4,
      "z": 6,
      "name": "Prototype_Rock_Concrete_Brick_Half",
      "rotation": 8
    },
    {
      "x": 29,
      "y": -11,
      "z": 7,
      "name": "Rock_Chalk_Brick_Wall"
    },
    {
      "x": 29,
      "y": -10,
      "z": 7,
      "name": "Rock_Chalk_Brick_Wall"
    },
    {
      "x": 29,
      "y": -9,
      "z": 7,
      "name": "Rock_Chalk_Brick_Wall"
    },
    {
      "x": 29,
      "y": -8,
      "z": 7,
      "name": "Rock_Chalk_Brick_Wall"
    },
    {
      "x": 29,
      "y": -7,
      "z": 7,
      "name": "Rock_Chalk_Brick_Wall"
    },
    {
      "x": 29,
      "y": -6,
      "z": 7,
      "name": "Rock_Stone_Cobble"
    },
    {
      "x": 29,
      "y": -5,
      "z": 7,
      "name": "Rock_Stone_Brick"
    },
    {
      "x": 29,
      "y": -4,
      "z": 7,
      "name": "Prototype_Rock_Concrete_Brick"
    },
    {
      "x": 29,
      "y": -3,
      "z": 7,
      "name": "Prototype_Rock_Concrete_Brick_Stairs",
      "rotation": 3
    },
    {
      "x": 29,
      "y": -6,
      "z": 8,
      "name": "*Furniture_Crude_Trapdoor_State_Definitions_OpenDoorOut"
    },
    {
      "x": 29,
      "y": -4,
      "z": 8,
      "name": "Prototype_Rock_Concrete_Brick_Half",
      "rotation": 8
    },
    {
      "x": 30,
      "y": -11,
      "z": -6,
      "name": "Wood_Hardwood_Fence",
      "rotation": 1
    },
    {
      "x": 30,
      "y": -10,
      "z": -6,
      "name": "Wood_Hardwood_Fence",
      "rotation": 1
    },
    {
      "x": 30,
      "y": -9,
      "z": -6,
      "name": "Wood_Hardwood_Fence",
      "rotation": 1
    },
    {
      "x": 30,
      "y": -8,
      "z": -6,
      "name": "Wood_Hardwood_Fence",
      "rotation": 1
    },
    {
      "x": 30,
      "y": -7,
      "z": -6,
      "name": "Wood_Hardwood_Fence",
      "rotation": 1
    },
    {
      "x": 30,
      "y": -6,
      "z": -6,
      "name": "Wood_Hardwood_Fence",
      "rotation": 1
    },
    {
      "x": 30,
      "y": -5,
      "z": -6,
      "name": "Wood_Hardwood_Fence",
      "rotation": 1
    },
    {
      "x": 30,
      "y": -4,
      "z": -6,
      "name": "Wood_Hardwood_Fence",
      "rotation": 1
    },
    {
      "x": 30,
      "y": -3,
      "z": -6,
      "name": "Prototype_Rock_Concrete_Brick_Half"
    },
    {
      "x": 30,
      "y": -11,
      "z": -5,
      "name": "Rock_Stone_Brick"
    },
    {
      "x": 30,
      "y": -10,
      "z": -5,
      "name": "Rock_Stone_Brick"
    },
    {
      "x": 30,
      "y": -9,
      "z": -5,
      "name": "Rock_Stone_Brick"
    },
    {
      "x": 30,
      "y": -8,
      "z": -5,
      "name": "Rock_Stone_Brick"
    },
    {
      "x": 30,
      "y": -7,
      "z": -5,
      "name": "Rock_Stone_Brick"
    },
    {
      "x": 30,
      "y": -6,
      "z": -5,
      "name": "Rock_Stone_Brick"
    },
    {
      "x": 30,
      "y": -5,
      "z": -5,
      "name": "Rock_Shale_Brick"
    },
    {
      "x": 30,
      "y": -4,
      "z": -5,
      "name": "Rock_Stone_Brick"
    },
    {
      "x": 30,
      "y": -3,
      "z": -5,
      "name": "Prototype_Rock_Concrete_Brick"
    },
    {
      "x": 30,
      "y": -2,
      "z": -5,
      "name": "Prototype_Rock_Concrete_Brick_Half"
    },
    {
      "x": 30,
      "y": -3,
      "z": -4,
      "name": "Prototype_Rock_Concrete_Brick_Half"
    },
    {
      "x": 30,
      "y": -3,
      "z": -3,
      "name": "Prototype_Rock_Concrete_Brick_Stairs",
      "rotation": 3
    },
    {
      "x": 30,
      "y": -3,
      "z": -2,
      "name": "Rock_Shale_Brick_Half"
    },
    {
      "x": 30,
      "y": -3,
      "z": -1,
      "name": "Rock_Shale_Cobble_Half"
    },
    {
      "x": 30,
      "y": -3,
      "z": 0,
      "name": "Prototype_Rock_Concrete_Brick_Half"
    },
    {
      "x": 30,
      "y": -3,
      "z": 1,
      "name": "Rock_Shale_Brick_Half"
    },
    {
      "x": 30,
      "y": -3,
      "z": 2,
      "name": "Prototype_Rock_Concrete_Brick_Half"
    },
    {
      "x": 30,
      "y": -3,
      "z": 3,
      "name": "Rock_Shale_Cobble_Half"
    },
    {
      "x": 30,
      "y": -3,
      "z": 4,
      "name": "Rock_Shale_Brick_Half"
    },
    {
      "x": 30,
      "y": -3,
      "z": 5,
      "name": "Prototype_Rock_Concrete_Brick_Stairs",
      "rotation": 3
    },
    {
      "x": 30,
      "y": -3,
      "z": 6,
      "name": "Prototype_Rock_Concrete_Brick_Half"
    },
    {
      "x": 30,
      "y": -11,
      "z": 7,
      "name": "Rock_Stone_Brick"
    },
    {
      "x": 30,
      "y": -10,
      "z": 7,
      "name": "Rock_Stone_Brick"
    },
    {
      "x": 30,
      "y": -9,
      "z": 7,
      "name": "Rock_Stone_Brick"
    },
    {
      "x": 30,
      "y": -8,
      "z": 7,
      "name": "Rock_Stone_Brick"
    },
    {
      "x": 30,
      "y": -7,
      "z": 7,
      "name": "Rock_Stone_Brick"
    },
    {
      "x": 30,
      "y": -6,
      "z": 7,
      "name": "Rock_Shale_Brick"
    },
    {
      "x": 30,
      "y": -5,
      "z": 7,
      "name": "Rock_Shale_Brick"
    },
    {
      "x": 30,
      "y": -4,
      "z": 7,
      "name": "Rock_Stone_Brick"
    },
    {
      "x": 30,
      "y": -3,
      "z": 7,
      "name": "Prototype_Rock_Concrete_Brick"
    },
    {
      "x": 30,
      "y": -2,
      "z": 7,
      "name": "Prototype_Rock_Concrete_Brick_Half"
    },
    {
      "x": 30,
      "y": -11,
      "z": 8,
      "name": "Wood_Hardwood_Fence",
      "rotation": 1
    },
    {
      "x": 30,
      "y": -10,
      "z": 8,
      "name": "Wood_Hardwood_Fence",
      "rotation": 1
    },
    {
      "x": 30,
      "y": -9,
      "z": 8,
      "name": "Wood_Hardwood_Fence",
      "rotation": 1
    },
    {
      "x": 30,
      "y": -8,
      "z": 8,
      "name": "Wood_Hardwood_Fence",
      "rotation": 1
    },
    {
      "x": 30,
      "y": -7,
      "z": 8,
      "name": "Wood_Hardwood_Fence",
      "rotation": 1
    },
    {
      "x": 30,
      "y": -6,
      "z": 8,
      "name": "Wood_Hardwood_Fence",
      "rotation": 1
    },
    {
      "x": 30,
      "y": -5,
      "z": 8,
      "name": "Wood_Hardwood_Fence",
      "rotation": 1
    },
    {
      "x": 30,
      "y": -4,
      "z": 8,
      "name": "Wood_Hardwood_Fence",
      "rotation": 1
    },
    {
      "x": 30,
      "y": -3,
      "z": 8,
      "name": "Prototype_Rock_Concrete_Brick_Half"
    },
    {
      "x": 30,
      "y": -11,
      "z": 14,
      "name": "Rock_Stone_Brick_Mossy"
    },
    {
      "x": 30,
      "y": -11,
      "z": 16,
      "name": "Rock_Stone_Brick"
    },
    {
      "x": 31,
      "y": -11,
      "z": -13,
      "name": "Rock_Stone_Brick"
    },
    {
      "x": 31,
      "y": -11,
      "z": -12,
      "name": "Plant_Moss_Rug_Green_Dark"
    },
    {
      "x": 31,
      "y": -11,
      "z": -9,
      "name": "Rock_Shale_Brick"
    },
    {
      "x": 31,
      "y": -9,
      "z": -8,
      "name": "Rock_Shale_Brick"
    },
    {
      "x": 31,
      "y": -11,
      "z": -7,
      "name": "Rock_Stone_Brick"
    },
    {
      "x": 31,
      "y": -5,
      "z": -6,
      "name": "*Furniture_Crude_Trapdoor_State_Definitions_OpenDoorOut",
      "rotation": 2
    },
    {
      "x": 31,
      "y": -3,
      "z": -6,
      "name": "Prototype_Rock_Concrete_Brick_Half",
      "rotation": 8
    },
    {
      "x": 31,
      "y": -11,
      "z": -5,
      "name": "Rock_Chalk_Brick_Wall"
    },
    {
      "x": 31,
      "y": -10,
      "z": -5,
      "name": "Rock_Chalk_Brick_Wall"
    },
    {
      "x": 31,
      "y": -9,
      "z": -5,
      "name": "Rock_Chalk_Brick_Wall"
    },
    {
      "x": 31,
      "y": -8,
      "z": -5,
      "name": "Rock_Chalk_Brick_Wall"
    },
    {
      "x": 31,
      "y": -7,
      "z": -5,
      "name": "Rock_Chalk_Brick_Wall"
    },
    {
      "x": 31,
      "y": -6,
      "z": -5,
      "name": "Rock_Chalk_Brick_Wall"
    },
    {
      "x": 31,
      "y": -5,
      "z": -5,
      "name": "Rock_Stone_Cobble"
    },
    {
      "x": 31,
      "y": -4,
      "z": -5,
      "name": "Rock_Shale_Brick"
    },
    {
      "x": 31,
      "y": -3,
      "z": -5,
      "name": "Prototype_Rock_Concrete_Brick"
    },
    {
      "x": 31,
      "y": -2,
      "z": -5,
      "name": "Prototype_Rock_Concrete_Brick_Stairs",
      "rotation": 3
    },
    {
      "x": 31,
      "y": -11,
      "z": -4,
      "name": "Rock_Crystal_Cyan_Block"
    },
    {
      "x": 31,
      "y": -10,
      "z": -4,
      "name": "Rock_Crystal_Cyan_Block"
    },
    {
      "x": 31,
      "y": -9,
      "z": -4,
      "name": "Rock_Crystal_Cyan_Block"
    },
    {
      "x": 31,
      "y": -8,
      "z": -4,
      "name": "Rock_Crystal_Cyan_Block"
    },
    {
      "x": 31,
      "y": -7,
      "z": -4,
      "name": "Rock_Crystal_Cyan_Block"
    },
    {
      "x": 31,
      "y": -6,
      "z": -4,
      "name": "Rock_Crystal_Cyan_Block"
    },
    {
      "x": 31,
      "y": -5,
      "z": -4,
      "name": "Rock_Crystal_Cyan_Block"
    },
    {
      "x": 31,
      "y": -4,
      "z": -4,
      "name": "Rock_Crystal_Cyan_Block"
    },
    {
      "x": 31,
      "y": -3,
      "z": -4,
      "name": "Prototype_Rock_Concrete_Brick_Half",
      "rotation": 8
    },
    {
      "x": 31,
      "y": -3,
      "z": -3,
      "name": "Rock_Crystal_Cyan_Block"
    },
    {
      "x": 31,
      "y": -2,
      "z": -3,
      "name": "Plant_Moss_Rug_Green_Dark"
    },
    {
      "x": 31,
      "y": -3,
      "z": -2,
      "name": "Rock_Shale_Brick_Half",
      "rotation": 8
    },
    {
      "x": 31,
      "y": -3,
      "z": -1,
      "name": "Rock_Shale_Cobble_Half",
      "rotation": 8
    },
    {
      "x": 31,
      "y": -3,
      "z": 0,
      "name": "Prototype_Rock_Concrete_Brick_Half",
      "rotation": 8
    },
    {
      "x": 31,
      "y": -3,
      "z": 1,
      "name": "Rock_Shale_Brick_Half",
      "rotation": 8
    },
    {
      "x": 31,
      "y": -3,
      "z": 2,
      "name": "Prototype_Rock_Concrete_Brick_Half",
      "rotation": 8
    },
    {
      "x": 31,
      "y": -3,
      "z": 3,
      "name": "Rock_Shale_Cobble_Half",
      "rotation": 8
    },
    {
      "x": 31,
      "y": -3,
      "z": 4,
      "name": "Rock_Shale_Brick_Half",
      "rotation": 8
    },
    {
      "x": 31,
      "y": -3,
      "z": 5,
      "name": "Rock_Crystal_Cyan_Block"
    },
    {
      "x": 31,
      "y": -2,
      "z": 5,
      "name": "Plant_Moss_Rug_Green_Dark"
    },
    {
      "x": 31,
      "y": -11,
      "z": 6,
      "name": "Rock_Crystal_Cyan_Block"
    },
    {
      "x": 31,
      "y": -10,
      "z": 6,
      "name": "Rock_Crystal_Cyan_Block"
    },
    {
      "x": 31,
      "y": -9,
      "z": 6,
      "name": "Rock_Crystal_Cyan_Block"
    },
    {
      "x": 31,
      "y": -8,
      "z": 6,
      "name": "Rock_Crystal_Cyan_Block"
    },
    {
      "x": 31,
      "y": -7,
      "z": 6,
      "name": "Rock_Crystal_Cyan_Block"
    },
    {
      "x": 31,
      "y": -6,
      "z": 6,
      "name": "Rock_Crystal_Cyan_Block"
    },
    {
      "x": 31,
      "y": -5,
      "z": 6,
      "name": "Rock_Crystal_Cyan_Block"
    },
    {
      "x": 31,
      "y": -4,
      "z": 6,
      "name": "Rock_Crystal_Cyan_Block"
    },
    {
      "x": 31,
      "y": -3,
      "z": 6,
      "name": "Prototype_Rock_Concrete_Brick_Half",
      "rotation": 8
    },
    {
      "x": 31,
      "y": -11,
      "z": 7,
      "name": "Rock_Chalk_Brick_Wall"
    },
    {
      "x": 31,
      "y": -10,
      "z": 7,
      "name": "Rock_Chalk_Brick_Wall"
    },
    {
      "x": 31,
      "y": -9,
      "z": 7,
      "name": "Rock_Chalk_Brick_Wall"
    },
    {
      "x": 31,
      "y": -8,
      "z": 7,
      "name": "Rock_Chalk_Brick_Wall"
    },
    {
      "x": 31,
      "y": -7,
      "z": 7,
      "name": "Rock_Chalk_Brick_Wall"
    },
    {
      "x": 31,
      "y": -6,
      "z": 7,
      "name": "Rock_Chalk_Brick_Wall"
    },
    {
      "x": 31,
      "y": -5,
      "z": 7,
      "name": "Rock_Stone_Cobble"
    },
    {
      "x": 31,
      "y": -4,
      "z": 7,
      "name": "Rock_Shale_Brick"
    },
    {
      "x": 31,
      "y": -3,
      "z": 7,
      "name": "Prototype_Rock_Concrete_Brick"
    },
    {
      "x": 31,
      "y": -2,
      "z": 7,
      "name": "Prototype_Rock_Concrete_Brick_Stairs",
      "rotation": 3
    },
    {
      "x": 31,
      "y": -5,
      "z": 8,
      "name": "*Furniture_Crude_Trapdoor_State_Definitions_OpenDoorOut"
    },
    {
      "x": 31,
      "y": -3,
      "z": 8,
      "name": "Prototype_Rock_Concrete_Brick_Half",
      "rotation": 8
    },
    {
      "x": 31,
      "y": -11,
      "z": 11,
      "name": "Rock_Stone_Brick"
    },
    {
      "x": 31,
      "y": -11,
      "z": 13,
      "name": "Rock_Shale_Brick"
    },
    {
      "x": 31,
      "y": -11,
      "z": 15,
      "name": "Rock_Shale_Brick"
    },
    {
      "x": 31,
      "y": -11,
      "z": 16,
      "name": "Plant_Moss_Rug_Green_Dark"
    },
    {
      "x": 32,
      "y": -11,
      "z": -14,
      "name": "Rock_Stone_Brick"
    },
    {
      "x": 32,
      "y": -11,
      "z": -13,
      "name": "Rock_Shale_Brick"
    },
    {
      "x": 32,
      "y": -10,
      "z": -13,
      "name": "Rock_Stone_Brick_Mossy"
    },
    {
      "x": 32,
      "y": -11,
      "z": -12,
      "name": "Rock_Stone_Brick_Mossy"
    },
    {
      "x": 32,
      "y": -10,
      "z": -12,
      "name": "Rock_Shale_Brick"
    },
    {
      "x": 32,
      "y": -11,
      "z": -11,
      "name": "Rock_Stone_Brick"
    },
    {
      "x": 32,
      "y": -10,
      "z": -11,
      "name": "Rock_Stone_Brick"
    },
    {
      "x": 32,
      "y": -11,
      "z": -10,
      "name": "Rock_Stone_Brick"
    },
    {
      "x": 32,
      "y": -11,
      "z": -9,
      "name": "Rock_Shale_Brick"
    },
    {
      "x": 32,
      "y": -10,
      "z": -9,
      "name": "Rock_Stone_Brick"
    },
    {
      "x": 32,
      "y": -11,
      "z": -8,
      "name": "Rock_Shale_Brick"
    },
    {
      "x": 32,
      "y": -10,
      "z": -8,
      "name": "Rock_Stone_Brick"
    },
    {
      "x": 32,
      "y": -9,
      "z": -8,
      "name": "Rock_Stone_Brick"
    },
    {
      "x": 32,
      "y": -11,
      "z": -7,
      "name": "Rock_Stone_Brick"
    },
    {
      "x": 32,
      "y": -10,
      "z": -7,
      "name": "Rock_Shale_Brick"
    },
    {
      "x": 32,
      "y": -9,
      "z": -7,
      "name": "Rock_Stone_Brick"
    },
    {
      "x": 32,
      "y": -11,
      "z": -6,
      "name": "Wood_Hardwood_Fence"
    },
    {
      "x": 32,
      "y": -10,
      "z": -6,
      "name": "Wood_Hardwood_Fence"
    },
    {
      "x": 32,
      "y": -9,
      "z": -6,
      "name": "Wood_Hardwood_Fence"
    },
    {
      "x": 32,
      "y": -8,
      "z": -6,
      "name": "*Wood_Hardwood_Fence_State_Definitions_Corner",
      "rotation": 1
    },
    {
      "x": 32,
      "y": -7,
      "z": -6,
      "name": "*Wood_Hardwood_Fence_State_Definitions_Corner",
      "rotation": 1
    },
    {
      "x": 32,
      "y": -6,
      "z": -6,
      "name": "*Wood_Hardwood_Fence_State_Definitions_Corner",
      "rotation": 1
    },
    {
      "x": 32,
      "y": -5,
      "z": -6,
      "name": "*Wood_Hardwood_Fence_State_Definitions_Corner",
      "rotation": 1
    },
    {
      "x": 32,
      "y": -4,
      "z": -6,
      "name": "*Wood_Hardwood_Fence_State_Definitions_Corner",
      "rotation": 1
    },
    {
      "x": 32,
      "y": -3,
      "z": -6,
      "name": "*Wood_Hardwood_Fence_State_Definitions_Corner",
      "rotation": 1
    },
    {
      "x": 32,
      "y": -2,
      "z": -6,
      "name": "Prototype_Rock_Concrete_Brick_Half"
    },
    {
      "x": 32,
      "y": -11,
      "z": -5,
      "name": "Rock_Stone_Brick"
    },
    {
      "x": 32,
      "y": -10,
      "z": -5,
      "name": "Rock_Stone_Brick"
    },
    {
      "x": 32,
      "y": -9,
      "z": -5,
      "name": "Rock_Shale_Brick"
    },
    {
      "x": 32,
      "y": -8,
      "z": -5,
      "name": "Rock_Stone_Brick"
    },
    {
      "x": 32,
      "y": -7,
      "z": -5,
      "name": "Rock_Stone_Brick_Mossy"
    },
    {
      "x": 32,
      "y": -6,
      "z": -5,
      "name": "Rock_Stone_Brick"
    },
    {
      "x": 32,
      "y": -5,
      "z": -5,
      "name": "Rock_Stone_Brick"
    },
    {
      "x": 32,
      "y": -4,
      "z": -5,
      "name": "Rock_Shale_Brick"
    },
    {
      "x": 32,
      "y": -3,
      "z": -5,
      "name": "Rock_Stone_Brick"
    },
    {
      "x": 32,
      "y": -2,
      "z": -5,
      "name": "Prototype_Rock_Concrete_Brick"
    },
    {
      "x": 32,
      "y": -2,
      "z": -4,
      "name": "Prototype_Rock_Concrete_Brick_Half"
    },
    {
      "x": 32,
      "y": -2,
      "z": -3,
      "name": "Prototype_Rock_Concrete_Brick_Half"
    },
    {
      "x": 32,
      "y": -2,
      "z": -2,
      "name": "Prototype_Rock_Concrete_Brick_Half"
    },
    {
      "x": 32,
      "y": -2,
      "z": -1,
      "name": "Rock_Shale_Brick_Half"
    },
    {
      "x": 32,
      "y": -2,
      "z": 0,
      "name": "Rock_Shale_Cobble_Half"
    },
    {
      "x": 32,
      "y": -2,
      "z": 1,
      "name": "Prototype_Rock_Concrete_Brick_Half"
    },
    {
      "x": 32,
      "y": -2,
      "z": 2,
      "name": "Rock_Shale_Cobble_Half"
    },
    {
      "x": 32,
      "y": -2,
      "z": 3,
      "name": "Rock_Shale_Brick_Half"
    },
    {
      "x": 32,
      "y": -2,
      "z": 4,
      "name": "Prototype_Rock_Concrete_Brick_Half"
    },
    {
      "x": 32,
      "y": -2,
      "z": 5,
      "name": "Prototype_Rock_Concrete_Brick_Half"
    },
    {
      "x": 32,
      "y": -2,
      "z": 6,
      "name": "Prototype_Rock_Concrete_Brick_Half"
    },
    {
      "x": 32,
      "y": -11,
      "z": 7,
      "name": "Rock_Stone_Brick_Mossy"
    },
    {
      "x": 32,
      "y": -10,
      "z": 7,
      "name": "Rock_Stone_Brick"
    },
    {
      "x": 32,
      "y": -9,
      "z": 7,
      "name": "Rock_Stone_Brick_Mossy"
    },
    {
      "x": 32,
      "y": -8,
      "z": 7,
      "name": "Rock_Stone_Brick_Mossy"
    },
    {
      "x": 32,
      "y": -7,
      "z": 7,
      "name": "Rock_Shale_Brick"
    },
    {
      "x": 32,
      "y": -6,
      "z": 7,
      "name": "Rock_Stone_Brick"
    },
    {
      "x": 32,
      "y": -5,
      "z": 7,
      "name": "Rock_Stone_Brick"
    },
    {
      "x": 32,
      "y": -4,
      "z": 7,
      "name": "Rock_Stone_Brick"
    },
    {
      "x": 32,
      "y": -3,
      "z": 7,
      "name": "Rock_Stone_Brick"
    },
    {
      "x": 32,
      "y": -2,
      "z": 7,
      "name": "Prototype_Rock_Concrete_Brick"
    },
    {
      "x": 32,
      "y": -11,
      "z": 8,
      "name": "Wood_Hardwood_Fence"
    },
    {
      "x": 32,
      "y": -10,
      "z": 8,
      "name": "*Wood_Hardwood_Fence_State_Definitions_Corner",
      "rotation": 2
    },
    {
      "x": 32,
      "y": -9,
      "z": 8,
      "name": "*Wood_Hardwood_Fence_State_Definitions_Corner",
      "rotation": 2
    },
    {
      "x": 32,
      "y": -8,
      "z": 8,
      "name": "*Wood_Hardwood_Fence_State_Definitions_Corner",
      "rotation": 2
    },
    {
      "x": 32,
      "y": -7,
      "z": 8,
      "name": "*Wood_Hardwood_Fence_State_Definitions_Corner",
      "rotation": 2
    },
    {
      "x": 32,
      "y": -6,
      "z": 8,
      "name": "*Wood_Hardwood_Fence_State_Definitions_Corner",
      "rotation": 2
    },
    {
      "x": 32,
      "y": -5,
      "z": 8,
      "name": "*Wood_Hardwood_Fence_State_Definitions_Corner",
      "rotation": 2
    },
    {
      "x": 32,
      "y": -4,
      "z": 8,
      "name": "*Wood_Hardwood_Fence_State_Definitions_Corner",
      "rotation": 2
    },
    {
      "x": 32,
      "y": -3,
      "z": 8,
      "name": "*Wood_Hardwood_Fence_State_Definitions_Corner",
      "rotation": 2
    },
    {
      "x": 32,
      "y": -2,
      "z": 8,
      "name": "Prototype_Rock_Concrete_Brick_Half"
    },
    {
      "x": 32,
      "y": -11,
      "z": 9,
      "name": "Rock_Shale_Brick"
    },
    {
      "x": 32,
      "y": -11,
      "z": 10,
      "name": "Rock_Stone_Brick"
    },
    {
      "x": 32,
      "y": -9,
      "z": 10,
      "name": "Rock_Stone_Brick"
    },
    {
      "x": 32,
      "y": -11,
      "z": 11,
      "name": "Rock_Stone_Brick"
    },
    {
      "x": 32,
      "y": -10,
      "z": 11,
      "name": "Rock_Stone_Brick"
    },
    {
      "x": 32,
      "y": -11,
      "z": 12,
      "name": "Rock_Stone_Brick"
    },
    {
      "x": 32,
      "y": -10,
      "z": 12,
      "name": "Rock_Stone_Brick"
    },
    {
      "x": 32,
      "y": -11,
      "z": 13,
      "name": "Rock_Stone_Brick"
    },
    {
      "x": 32,
      "y": -11,
      "z": 14,
      "name": "Rock_Stone_Brick_Mossy"
    },
    {
      "x": 32,
      "y": -10,
      "z": 15,
      "name": "Rock_Shale_Brick"
    },
    {
      "x": 32,
      "y": 44,
      "z": 15,
      "name": "Rock_Crystal_White_Block"
    },
    {
      "x": 32,
      "y": 45,
      "z": 15,
      "name": "Plant_Coral_Block_White"
    },
    {
      "x": 32,
      "y": -11,
      "z": 16,
      "name": "Rock_Stone_Brick"
    },
    {
      "x": 32,
      "y": -10,
      "z": 16,
      "name": "Rock_Stone_Brick"
    },
    {
      "x": 32,
      "y": -11,
      "z": 17,
      "name": "Rock_Stone_Brick"
    },
    {
      "x": 32,
      "y": -11,
      "z": 18,
      "name": "Rock_Stone_Brick"
    },
    {
      "x": 32,
      "y": -10,
      "z": 18,
      "name": "Rock_Stone_Brick_Mossy"
    },
    {
      "x": 32,
      "y": -11,
      "z": 20,
      "name": "Rock_Stone_Brick"
    },
    {
      "x": 33,
      "y": -11,
      "z": -14,
      "name": "Rock_Stone_Brick_Mossy"
    },
    {
      "x": 33,
      "y": -10,
      "z": -14,
      "name": "Rock_Shale_Brick"
    },
    {
      "x": 33,
      "y": -11,
      "z": -13,
      "name": "Rock_Stone_Brick"
    },
    {
      "x": 33,
      "y": -10,
      "z": -13,
      "name": "Rock_Stone_Brick"
    },
    {
      "x": 33,
      "y": -9,
      "z": -13,
      "name": "Rock_Stone_Brick_Mossy"
    },
    {
      "x": 33,
      "y": -8,
      "z": -13,
      "name": "Rock_Stone_Brick"
    },
    {
      "x": 33,
      "y": -11,
      "z": -12,
      "name": "Rock_Stone_Brick"
    },
    {
      "x": 33,
      "y": -10,
      "z": -12,
      "name": "Rock_Stone_Brick"
    },
    {
      "x": 33,
      "y": -9,
      "z": -12,
      "name": "Rock_Shale_Brick"
    },
    {
      "x": 33,
      "y": -11,
      "z": -11,
      "name": "Rock_Stone_Brick_Mossy"
    },
    {
      "x": 33,
      "y": -10,
      "z": -11,
      "name": "Rock_Stone_Brick_Mossy"
    },
    {
      "x": 33,
      "y": -9,
      "z": -11,
      "name": "Rock_Stone_Brick"
    },
    {
      "x": 33,
      "y": -7,
      "z": -11,
      "name": "Rock_Stone_Brick_Mossy"
    },
    {
      "x": 33,
      "y": -2,
      "z": -11,
      "name": "Prototype_Rock_Concrete_Brick_Half"
    },
    {
      "x": 33,
      "y": -11,
      "z": -10,
      "name": "Rock_Stone_Brick_Mossy"
    },
    {
      "x": 33,
      "y": -10,
      "z": -10,
      "name": "Rock_Stone_Brick"
    },
    {
      "x": 33,
      "y": -9,
      "z": -10,
      "name": "Rock_Shale_Brick"
    },
    {
      "x": 33,
      "y": -2,
      "z": -10,
      "name": "Prototype_Rock_Concrete_Brick_Half"
    },
    {
      "x": 33,
      "y": -11,
      "z": -9,
      "name": "Rock_Stone_Brick"
    },
    {
      "x": 33,
      "y": -10,
      "z": -9,
      "name": "Rock_Stone_Brick"
    },
    {
      "x": 33,
      "y": -9,
      "z": -9,
      "name": "Rock_Stone_Brick"
    },
    {
      "x": 33,
      "y": -8,
      "z": -9,
      "name": "Rock_Stone_Brick"
    },
    {
      "x": 33,
      "y": -2,
      "z": -9,
      "name": "Prototype_Rock_Concrete_Brick_Half"
    },
    {
      "x": 33,
      "y": -11,
      "z": -8,
      "name": "Rock_Stone_Brick_Mossy"
    },
    {
      "x": 33,
      "y": -9,
      "z": -8,
      "name": "Rock_Crystal_Cyan_Block"
    },
    {
      "x": 33,
      "y": -8,
      "z": -8,
      "name": "Plant_Moss_Rug_Green_Dark"
    },
    {
      "x": 33,
      "y": -2,
      "z": -8,
      "name": "Prototype_Rock_Concrete_Brick_Half"
    },
    {
      "x": 33,
      "y": -10,
      "z": -7,
      "name": "Rock_Stone_Brick"
    },
    {
      "x": 33,
      "y": -8,
      "z": -7,
      "name": "Rock_Stone_Brick"
    },
    {
      "x": 33,
      "y": -7,
      "z": -7,
      "name": "Rock_Shale_Brick"
    },
    {
      "x": 33,
      "y": -2,
      "z": -7,
      "name": "Prototype_Rock_Concrete_Brick_Half"
    },
    {
      "x": 33,
      "y": -11,
      "z": -6,
      "name": "Rock_Stone_Brick_Mossy"
    },
    {
      "x": 33,
      "y": -10,
      "z": -6,
      "name": "Rock_Stone_Brick_Mossy"
    },
    {
      "x": 33,
      "y": -9,
      "z": -6,
      "name": "Rock_Stone_Brick"
    },
    {
      "x": 33,
      "y": -8,
      "z": -6,
      "name": "Rock_Stone_Brick_Mossy"
    },
    {
      "x": 33,
      "y": -7,
      "z": -6,
      "name": "Rock_Stone_Brick_Mossy"
    },
    {
      "x": 33,
      "y": -6,
      "z": -6,
      "name": "Rock_Shale_Brick"
    },
    {
      "x": 33,
      "y": -5,
      "z": -6,
      "name": "Rock_Stone_Brick_Mossy"
    },
    {
      "x": 33,
      "y": -4,
      "z": -6,
      "name": "Rock_Stone_Brick"
    },
    {
      "x": 33,
      "y": -3,
      "z": -6,
      "name": "Rock_Stone_Brick"
    },
    {
      "x": 33,
      "y": -2,
      "z": -6,
      "name": "Prototype_Rock_Concrete_Brick"
    },
    {
      "x": 33,
      "y": -11,
      "z": -5,
      "name": "Rock_Stone_Brick_Mossy"
    },
    {
      "x": 33,
      "y": -10,
      "z": -5,
      "name": "Rock_Stone_Brick_Mossy"
    },
    {
      "x": 33,
      "y": -9,
      "z": -5,
      "name": "Rock_Shale_Brick"
    },
    {
      "x": 33,
      "y": -8,
      "z": -5,
      "name": "Rock_Stone_Brick"
    },
    {
      "x": 33,
      "y": -7,
      "z": -5,
      "name": "Rock_Stone_Brick_Mossy"
    },
    {
      "x": 33,
      "y": -6,
      "z": -5,
      "name": "Rock_Stone_Brick"
    },
    {
      "x": 33,
      "y": -5,
      "z": -5,
      "name": "Rock_Stone_Brick_Mossy"
    },
    {
      "x": 33,
      "y": -4,
      "z": -5,
      "name": "Rock_Stone_Brick"
    },
    {
      "x": 33,
      "y": -3,
      "z": -5,
      "name": "Rock_Stone_Brick_Mossy"
    },
    {
      "x": 33,
      "y": -2,
      "z": -5,
      "name": "Prototype_Rock_Concrete_Brick"
    },
    {
      "x": 33,
      "y": -11,
      "z": -4,
      "name": "Rock_Stone_Brick_Mossy"
    },
    {
      "x": 33,
      "y": -10,
      "z": -4,
      "name": "Rock_Shale_Brick"
    },
    {
      "x": 33,
      "y": -9,
      "z": -4,
      "name": "Rock_Stone_Brick_Mossy"
    },
    {
      "x": 33,
      "y": -8,
      "z": -4,
      "name": "Rock_Stone_Brick"
    },
    {
      "x": 33,
      "y": -7,
      "z": -4,
      "name": "Rock_Shale_Brick"
    },
    {
      "x": 33,
      "y": -6,
      "z": -4,
      "name": "Rock_Shale_Brick"
    },
    {
      "x": 33,
      "y": -5,
      "z": -4,
      "name": "Rock_Stone_Brick_Mossy"
    },
    {
      "x": 33,
      "y": -4,
      "z": -4,
      "name": "Rock_Stone_Brick"
    },
    {
      "x": 33,
      "y": -3,
      "z": -4,
      "name": "Rock_Stone_Brick"
    },
    {
      "x": 33,
      "y": -2,
      "z": -4,
      "name": "Prototype_Rock_Concrete_Brick"
    },
    {
      "x": 33,
      "y": -11,
      "z": -3,
      "name": "Rock_Stone_Brick"
    },
    {
      "x": 33,
      "y": -10,
      "z": -3,
      "name": "Rock_Stone_Brick_Mossy"
    },
    {
      "x": 33,
      "y": -9,
      "z": -3,
      "name": "Rock_Stone_Brick"
    },
    {
      "x": 33,
      "y": -8,
      "z": -3,
      "name": "Rock_Stone_Brick"
    },
    {
      "x": 33,
      "y": -7,
      "z": -3,
      "name": "Rock_Shale_Brick"
    },
    {
      "x": 33,
      "y": -6,
      "z": -3,
      "name": "Rock_Stone_Brick"
    },
    {
      "x": 33,
      "y": -5,
      "z": -3,
      "name": "Rock_Stone_Brick"
    },
    {
      "x": 33,
      "y": -4,
      "z": -3,
      "name": "Rock_Shale_Brick"
    },
    {
      "x": 33,
      "y": -3,
      "z": -3,
      "name": "Rock_Stone_Brick"
    },
    {
      "x": 33,
      "y": -2,
      "z": -3,
      "name": "Rock_Shale_Brick_Half"
    },
    {
      "x": 33,
      "y": -11,
      "z": -2,
      "name": "Rock_Stone_Brick_Mossy"
    },
    {
      "x": 33,
      "y": -10,
      "z": -2,
      "name": "Rock_Stone_Brick_Mossy"
    },
    {
      "x": 33,
      "y": -9,
      "z": -2,
      "name": "Rock_Stone_Brick"
    },
    {
      "x": 33,
      "y": -8,
      "z": -2,
      "name": "Rock_Shale_Brick"
    },
    {
      "x": 33,
      "y": -7,
      "z": -2,
      "name": "Rock_Shale_Brick"
    },
    {
      "x": 33,
      "y": -6,
      "z": -2,
      "name": "Rock_Stone_Brick"
    },
    {
      "x": 33,
      "y": -5,
      "z": -2,
      "name": "Rock_Stone_Brick_Mossy"
    },
    {
      "x": 33,
      "y": -4,
      "z": -2,
      "name": "Rock_Stone_Brick"
    },
    {
      "x": 33,
      "y": -3,
      "z": -2,
      "name": "Rock_Shale_Brick"
    },
    {
      "x": 33,
      "y": -2,
      "z": -2,
      "name": "Rock_Shale_Brick_Half"
    },
    {
      "x": 33,
      "y": -11,
      "z": -1,
      "name": "Rock_Stone_Brick_Mossy"
    },
    {
      "x": 33,
      "y": -10,
      "z": -1,
      "name": "Rock_Shale_Brick"
    },
    {
      "x": 33,
      "y": -9,
      "z": -1,
      "name": "Rock_Stone_Brick_Mossy"
    },
    {
      "x": 33,
      "y": -8,
      "z": -1,
      "name": "Rock_Stone_Brick"
    },
    {
      "x": 33,
      "y": -7,
      "z": -1,
      "name": "Rock_Stone_Brick_Mossy"
    },
    {
      "x": 33,
      "y": -6,
      "z": -1,
      "name": "Rock_Stone_Brick"
    },
    {
      "x": 33,
      "y": -5,
      "z": -1,
      "name": "Rock_Stone_Brick"
    },
    {
      "x": 33,
      "y": -4,
      "z": -1,
      "name": "Rock_Stone_Brick"
    },
    {
      "x": 33,
      "y": -3,
      "z": -1,
      "name": "Rock_Shale_Brick"
    },
    {
      "x": 33,
      "y": -2,
      "z": -1,
      "name": "Rock_Shale_Brick_Half"
    },
    {
      "x": 33,
      "y": -11,
      "z": 0,
      "name": "Rock_Stone_Brick"
    },
    {
      "x": 33,
      "y": -10,
      "z": 0,
      "name": "Rock_Shale_Brick"
    },
    {
      "x": 33,
      "y": -9,
      "z": 0,
      "name": "Rock_Stone_Brick"
    },
    {
      "x": 33,
      "y": -8,
      "z": 0,
      "name": "Rock_Stone_Brick"
    },
    {
      "x": 33,
      "y": -7,
      "z": 0,
      "name": "Rock_Shale_Brick"
    },
    {
      "x": 33,
      "y": -6,
      "z": 0,
      "name": "Rock_Stone_Brick"
    },
    {
      "x": 33,
      "y": -5,
      "z": 0,
      "name": "Rock_Stone_Brick_Mossy"
    },
    {
      "x": 33,
      "y": -4,
      "z": 0,
      "name": "Rock_Shale_Brick"
    },
    {
      "x": 33,
      "y": -3,
      "z": 0,
      "name": "Rock_Shale_Brick"
    },
    {
      "x": 33,
      "y": -2,
      "z": 0,
      "name": "Rock_Shale_Cobble"
    },
    {
      "x": 33,
      "y": -11,
      "z": 1,
      "name": "Rock_Stone_Brick"
    },
    {
      "x": 33,
      "y": -10,
      "z": 1,
      "name": "Rock_Stone_Brick"
    },
    {
      "x": 33,
      "y": -9,
      "z": 1,
      "name": "Rock_Stone_Brick_Mossy"
    },
    {
      "x": 33,
      "y": -8,
      "z": 1,
      "name": "Rock_Stone_Brick"
    },
    {
      "x": 33,
      "y": -7,
      "z": 1,
      "name": "Rock_Shale_Brick"
    },
    {
      "x": 33,
      "y": -6,
      "z": 1,
      "name": "Rock_Stone_Brick"
    },
    {
      "x": 33,
      "y": -5,
      "z": 1,
      "name": "Rock_Stone_Brick_Mossy"
    },
    {
      "x": 33,
      "y": -4,
      "z": 1,
      "name": "Rock_Stone_Brick"
    },
    {
      "x": 33,
      "y": -3,
      "z": 1,
      "name": "Rock_Stone_Brick_Mossy"
    },
    {
      "x": 33,
      "y": -2,
      "z": 1,
      "name": "Rock_Shale_Brick"
    },
    {
      "x": 33,
      "y": -11,
      "z": 2,
      "name": "Rock_Shale_Brick"
    },
    {
      "x": 33,
      "y": -10,
      "z": 2,
      "name": "Rock_Stone_Brick_Mossy"
    },
    {
      "x": 33,
      "y": -9,
      "z": 2,
      "name": "Rock_Shale_Brick"
    },
    {
      "x": 33,
      "y": -8,
      "z": 2,
      "name": "Rock_Stone_Brick_Mossy"
    },
    {
      "x": 33,
      "y": -7,
      "z": 2,
      "name": "Rock_Stone_Brick"
    },
    {
      "x": 33,
      "y": -6,
      "z": 2,
      "name": "Rock_Stone_Brick"
    },
    {
      "x": 33,
      "y": -5,
      "z": 2,
      "name": "Rock_Stone_Brick"
    },
    {
      "x": 33,
      "y": -4,
      "z": 2,
      "name": "Rock_Stone_Brick"
    },
    {
      "x": 33,
      "y": -3,
      "z": 2,
      "name": "Rock_Stone_Brick"
    },
    {
      "x": 33,
      "y": -2,
      "z": 2,
      "name": "Rock_Shale_Cobble"
    },
    {
      "x": 33,
      "y": -11,
      "z": 3,
      "name": "Rock_Shale_Brick"
    },
    {
      "x": 33,
      "y": -10,
      "z": 3,
      "name": "Rock_Stone_Brick"
    },
    {
      "x": 33,
      "y": -9,
      "z": 3,
      "name": "Rock_Stone_Brick"
    },
    {
      "x": 33,
      "y": -8,
      "z": 3,
      "name": "Rock_Stone_Brick"
    },
    {
      "x": 33,
      "y": -7,
      "z": 3,
      "name": "Rock_Stone_Brick"
    },
    {
      "x": 33,
      "y": -6,
      "z": 3,
      "name": "Rock_Stone_Brick"
    },
    {
      "x": 33,
      "y": -5,
      "z": 3,
      "name": "Rock_Stone_Brick"
    },
    {
      "x": 33,
      "y": -4,
      "z": 3,
      "name": "Rock_Shale_Brick"
    },
    {
      "x": 33,
      "y": -3,
      "z": 3,
      "name": "Rock_Stone_Brick"
    },
    {
      "x": 33,
      "y": -2,
      "z": 3,
      "name": "Rock_Shale_Brick_Half"
    },
    {
      "x": 33,
      "y": -11,
      "z": 4,
      "name": "Rock_Stone_Brick_Mossy"
    },
    {
      "x": 33,
      "y": -10,
      "z": 4,
      "name": "Rock_Stone_Brick"
    },
    {
      "x": 33,
      "y": -9,
      "z": 4,
      "name": "Rock_Stone_Brick_Mossy"
    },
    {
      "x": 33,
      "y": -8,
      "z": 4,
      "name": "Rock_Stone_Brick"
    },
    {
      "x": 33,
      "y": -7,
      "z": 4,
      "name": "Rock_Shale_Brick"
    },
    {
      "x": 33,
      "y": -6,
      "z": 4,
      "name": "Rock_Stone_Brick"
    },
    {
      "x": 33,
      "y": -5,
      "z": 4,
      "name": "Rock_Stone_Brick_Mossy"
    },
    {
      "x": 33,
      "y": -4,
      "z": 4,
      "name": "Rock_Stone_Brick"
    },
    {
      "x": 33,
      "y": -3,
      "z": 4,
      "name": "Rock_Stone_Brick"
    },
    {
      "x": 33,
      "y": -2,
      "z": 4,
      "name": "Rock_Shale_Brick_Half"
    },
    {
      "x": 33,
      "y": -11,
      "z": 5,
      "name": "Rock_Stone_Brick"
    },
    {
      "x": 33,
      "y": -10,
      "z": 5,
      "name": "Rock_Stone_Brick"
    },
    {
      "x": 33,
      "y": -9,
      "z": 5,
      "name": "Rock_Shale_Brick"
    },
    {
      "x": 33,
      "y": -8,
      "z": 5,
      "name": "Rock_Shale_Brick"
    },
    {
      "x": 33,
      "y": -7,
      "z": 5,
      "name": "Rock_Stone_Brick_Mossy"
    },
    {
      "x": 33,
      "y": -6,
      "z": 5,
      "name": "Rock_Stone_Brick"
    },
    {
      "x": 33,
      "y": -5,
      "z": 5,
      "name": "Rock_Stone_Brick"
    },
    {
      "x": 33,
      "y": -4,
      "z": 5,
      "name": "Rock_Stone_Brick"
    },
    {
      "x": 33,
      "y": -3,
      "z": 5,
      "name": "Rock_Stone_Brick"
    },
    {
      "x": 33,
      "y": -2,
      "z": 5,
      "name": "Rock_Shale_Brick_Half"
    },
    {
      "x": 33,
      "y": -11,
      "z": 6,
      "name": "Rock_Stone_Brick"
    },
    {
      "x": 33,
      "y": -10,
      "z": 6,
      "name": "Rock_Stone_Brick_Mossy"
    },
    {
      "x": 33,
      "y": -9,
      "z": 6,
      "name": "Rock_Stone_Brick"
    },
    {
      "x": 33,
      "y": -8,
      "z": 6,
      "name": "Rock_Stone_Brick"
    },
    {
      "x": 33,
      "y": -7,
      "z": 6,
      "name": "Rock_Stone_Brick"
    },
    {
      "x": 33,
      "y": -6,
      "z": 6,
      "name": "Rock_Shale_Brick"
    },
    {
      "x": 33,
      "y": -5,
      "z": 6,
      "name": "Rock_Stone_Brick_Mossy"
    },
    {
      "x": 33,
      "y": -4,
      "z": 6,
      "name": "Rock_Shale_Brick"
    },
    {
      "x": 33,
      "y": -3,
      "z": 6,
      "name": "Rock_Stone_Brick"
    },
    {
      "x": 33,
      "y": -2,
      "z": 6,
      "name": "Prototype_Rock_Concrete_Brick"
    },
    {
      "x": 33,
      "y": -11,
      "z": 7,
      "name": "Rock_Stone_Brick_Mossy"
    },
    {
      "x": 33,
      "y": -10,
      "z": 7,
      "name": "Rock_Stone_Brick"
    },
    {
      "x": 33,
      "y": -9,
      "z": 7,
      "name": "Rock_Stone_Brick"
    },
    {
      "x": 33,
      "y": -8,
      "z": 7,
      "name": "Rock_Shale_Brick"
    },
    {
      "x": 33,
      "y": -7,
      "z": 7,
      "name": "Rock_Stone_Brick"
    },
    {
      "x": 33,
      "y": -6,
      "z": 7,
      "name": "Rock_Stone_Brick_Mossy"
    },
    {
      "x": 33,
      "y": -5,
      "z": 7,
      "name": "Rock_Shale_Brick"
    },
    {
      "x": 33,
      "y": -4,
      "z": 7,
      "name": "Rock_Stone_Brick"
    },
    {
      "x": 33,
      "y": -3,
      "z": 7,
      "name": "Rock_Shale_Brick"
    },
    {
      "x": 33,
      "y": -2,
      "z": 7,
      "name": "Prototype_Rock_Concrete_Brick"
    },
    {
      "x": 33,
      "y": -11,
      "z": 8,
      "name": "Rock_Stone_Brick"
    },
    {
      "x": 33,
      "y": -10,
      "z": 8,
      "name": "Rock_Stone_Brick"
    },
    {
      "x": 33,
      "y": -9,
      "z": 8,
      "name": "Rock_Stone_Brick"
    },
    {
      "x": 33,
      "y": -8,
      "z": 8,
      "name": "Rock_Shale_Brick"
    },
    {
      "x": 33,
      "y": -7,
      "z": 8,
      "name": "Rock_Stone_Brick"
    },
    {
      "x": 33,
      "y": -6,
      "z": 8,
      "name": "Rock_Shale_Brick"
    },
    {
      "x": 33,
      "y": -5,
      "z": 8,
      "name": "Rock_Stone_Brick"
    },
    {
      "x": 33,
      "y": -4,
      "z": 8,
      "name": "Rock_Stone_Brick"
    },
    {
      "x": 33,
      "y": -3,
      "z": 8,
      "name": "Rock_Shale_Brick"
    },
    {
      "x": 33,
      "y": -2,
      "z": 8,
      "name": "Prototype_Rock_Concrete_Brick"
    },
    {
      "x": 33,
      "y": -11,
      "z": 9,
      "name": "Rock_Stone_Brick"
    },
    {
      "x": 33,
      "y": -10,
      "z": 9,
      "name": "Rock_Stone_Brick"
    },
    {
      "x": 33,
      "y": -9,
      "z": 9,
      "name": "Rock_Stone_Brick_Mossy"
    },
    {
      "x": 33,
      "y": -2,
      "z": 9,
      "name": "Prototype_Rock_Concrete_Brick_Half"
    },
    {
      "x": 33,
      "y": -11,
      "z": 10,
      "name": "Rock_Stone_Brick_Mossy"
    },
    {
      "x": 33,
      "y": -10,
      "z": 10,
      "name": "Rock_Stone_Brick"
    },
    {
      "x": 33,
      "y": -9,
      "z": 10,
      "name": "Rock_Stone_Brick_Mossy"
    },
    {
      "x": 33,
      "y": -8,
      "z": 10,
      "name": "Rock_Stone_Brick"
    },
    {
      "x": 33,
      "y": -2,
      "z": 10,
      "name": "Prototype_Rock_Concrete_Brick_Half"
    },
    {
      "x": 33,
      "y": -11,
      "z": 11,
      "name": "Rock_Stone_Brick_Mossy"
    },
    {
      "x": 33,
      "y": -10,
      "z": 11,
      "name": "Rock_Shale_Brick"
    },
    {
      "x": 33,
      "y": -9,
      "z": 11,
      "name": "Rock_Shale_Brick"
    },
    {
      "x": 33,
      "y": -8,
      "z": 11,
      "name": "Rock_Stone_Brick_Mossy"
    },
    {
      "x": 33,
      "y": -2,
      "z": 11,
      "name": "Prototype_Rock_Concrete_Brick_Half"
    },
    {
      "x": 33,
      "y": -11,
      "z": 12,
      "name": "Rock_Crystal_Cyan_Block"
    },
    {
      "x": 33,
      "y": -10,
      "z": 12,
      "name": "Plant_Moss_Rug_Green_Dark"
    },
    {
      "x": 33,
      "y": -2,
      "z": 12,
      "name": "Prototype_Rock_Concrete_Brick_Half"
    },
    {
      "x": 33,
      "y": 44,
      "z": 12,
      "name": "Build_Lightsource_White"
    },
    {
      "x": 33,
      "y": 45,
      "z": 12,
      "name": "Build_Lightsource_White"
    },
    {
      "x": 33,
      "y": 46,
      "z": 12,
      "name": "Build_Lightsource_White"
    },
    {
      "x": 33,
      "y": 47,
      "z": 12,
      "name": "Plant_Coral_Block_White"
    },
    {
      "x": 33,
      "y": -11,
      "z": 13,
      "name": "Rock_Shale_Brick"
    },
    {
      "x": 33,
      "y": -2,
      "z": 13,
      "name": "Prototype_Rock_Concrete_Brick_Half"
    },
    {
      "x": 33,
      "y": 42,
      "z": 13,
      "name": "Build_Lightsource_White"
    },
    {
      "x": 33,
      "y": 43,
      "z": 13,
      "name": "Plant_Coral_Block_White"
    },
    {
      "x": 33,
      "y": 44,
      "z": 13,
      "name": "Plant_Coral_Block_White"
    },
    {
      "x": 33,
      "y": -11,
      "z": 14,
      "name": "Rock_Stone_Brick"
    },
    {
      "x": 33,
      "y": -10,
      "z": 14,
      "name": "Rock_Stone_Brick"
    },
    {
      "x": 33,
      "y": 44,
      "z": 14,
      "name": "Plant_Coral_Block_White"
    },
    {
      "x": 33,
      "y": 45,
      "z": 14,
      "name": "Rock_Crystal_White_Block"
    },
    {
      "x": 33,
      "y": 46,
      "z": 14,
      "name": "Plant_Coral_Block_White"
    },
    {
      "x": 33,
      "y": -11,
      "z": 15,
      "name": "Rock_Stone_Brick"
    },
    {
      "x": 33,
      "y": 43,
      "z": 15,
      "name": "Plant_Coral_Block_White"
    },
    {
      "x": 33,
      "y": 44,
      "z": 15,
      "name": "Rock_Crystal_White_Block"
    },
    {
      "x": 33,
      "y": 46,
      "z": 15,
      "name": "Plant_Coral_Block_White"
    },
    {
      "x": 33,
      "y": 47,
      "z": 15,
      "name": "Rock_Crystal_White_Block"
    },
    {
      "x": 33,
      "y": 48,
      "z": 15,
      "name": "Plant_Coral_Block_White"
    },
    {
      "x": 33,
      "y": 49,
      "z": 15,
      "name": "Build_Lightsource_White"
    },
    {
      "x": 33,
      "y": -10,
      "z": 16,
      "name": "Rock_Stone_Brick_Mossy"
    },
    {
      "x": 33,
      "y": 43,
      "z": 16,
      "name": "Rock_Crystal_White_Block"
    },
    {
      "x": 33,
      "y": 44,
      "z": 16,
      "name": "Plant_Coral_Block_White"
    },
    {
      "x": 33,
      "y": 45,
      "z": 16,
      "name": "Build_Lightsource_White"
    },
    {
      "x": 33,
      "y": -11,
      "z": 17,
      "name": "Rock_Stone_Brick"
    },
    {
      "x": 33,
      "y": -10,
      "z": 17,
      "name": "Rock_Shale_Brick"
    },
    {
      "x": 33,
      "y": 44,
      "z": 17,
      "name": "Rock_Crystal_White_Block"
    },
    {
      "x": 33,
      "y": 45,
      "z": 17,
      "name": "Plant_Coral_Block_White"
    },
    {
      "x": 33,
      "y": 46,
      "z": 17,
      "name": "Rock_Crystal_White_Block"
    },
    {
      "x": 33,
      "y": 47,
      "z": 17,
      "name": "Plant_Coral_Block_White"
    },
    {
      "x": 33,
      "y": -11,
      "z": 18,
      "name": "Rock_Stone_Brick"
    },
    {
      "x": 33,
      "y": -11,
      "z": 19,
      "name": "Rock_Shale_Brick"
    },
    {
      "x": 33,
      "y": -11,
      "z": 20,
      "name": "Rock_Stone_Brick"
    },
    {
      "x": 33,
      "y": -10,
      "z": 20,
      "name": "Rock_Stone_Brick"
    },
    {
      "x": 33,
      "y": -11,
      "z": 21,
      "name": "Rock_Shale_Brick"
    },
    {
      "x": 34,
      "y": -11,
      "z": -20,
      "name": "Rock_Stone_Brick_Mossy"
    },
    {
      "x": 34,
      "y": -11,
      "z": -19,
      "name": "Rock_Stone_Brick_Mossy"
    },
    {
      "x": 34,
      "y": -10,
      "z": -19,
      "name": "Rock_Stone_Brick"
    },
    {
      "x": 34,
      "y": -11,
      "z": -17,
      "name": "Rock_Stone_Brick_Mossy"
    },
    {
      "x": 34,
      "y": -10,
      "z": -17,
      "name": "Rock_Shale_Brick"
    },
    {
      "x": 34,
      "y": -9,
      "z": -17,
      "name": "Rock_Shale_Brick"
    },
    {
      "x": 34,
      "y": -11,
      "z": -16,
      "name": "Rock_Stone_Brick"
    },
    {
      "x": 34,
      "y": 18,
      "z": -16,
      "name": "Build_Lightsource_White"
    },
    {
      "x": 34,
      "y": 19,
      "z": -16,
      "name": "Plant_Coral_Block_White"
    },
    {
      "x": 34,
      "y": 29,
      "z": -16,
      "name": "Rock_Crystal_White_Block"
    },
    {
      "x": 34,
      "y": 20,
      "z": -15,
      "name": "Build_Lightsource_White"
    },
    {
      "x": 34,
      "y": 30,
      "z": -15,
      "name": "Plant_Coral_Block_White"
    },
    {
      "x": 34,
      "y": 36,
      "z": -15,
      "name": "Rock_Crystal_White_Block"
    },
    {
      "x": 34,
      "y": -11,
      "z": -14,
      "name": "Rock_Stone_Brick_Mossy"
    },
    {
      "x": 34,
      "y": -10,
      "z": -14,
