{
  "version": 8,
  "blockIdVersion": 11,
  "anchorX": 0,
  "anchorY": 0,
  "anchorZ": 0,
  "blocks": [
    {
      "x": -65,
      "y": 2,
      "z": -5,
      "name": "Prototype_Rock_Concrete_Brick_Stairs",
      "rotation": 3
    },
    {
      "x": -65,
      "y": 2,
      "z": 7,
      "name": "Prototype_Rock_Concrete_Brick_Stairs",
      "rotation": 3
    },
    {
      "x": -64,
      "y": 2,
      "z": -6,
      "name": "Prototype_Rock_Concrete_Brick_Half"
    },
    {
      "x": -64,
      "y": 2,
      "z": -5,
      "name": "Prototype_Rock_Concrete_Brick"
    },
    {
      "x": -64,
      "y": 3,
      "z": -5,
      "name": "Prototype_Rock_Concrete_Brick_Half"
    },
    {
      "x": -64,
      "y": 2,
      "z": -4,
      "name": "Prototype_Rock_Concrete_Brick_Half"
    },
    {
      "x": -64,
      "y": 2,
      "z": -3,
      "name": "Prototype_Rock_Concrete_Brick_Stairs",
      "rotation": 3
    },
    {
      "x": -64,
      "y": 2,
      "z": -2,
      "name": "Prototype_Rock_Concrete_Brick_Half"
    },
    {
      "x": -64,
      "y": 2,
      "z": -1,
      "name": "Rock_Shale_Brick_Half"
    },
    {
      "x": -64,
      "y": 2,
      "z": 0,
      "name": "Rock_Shale_Cobble_Half"
    },
    {
      "x": -64,
      "y": 2,
      "z": 1,
      "name": "Prototype_Rock_Concrete_Brick_Half"
    },
    {
      "x": -64,
      "y": 2,
      "z": 2,
      "name": "Rock_Shale_Cobble_Half"
    },
    {
      "x": -64,
      "y": 2,
      "z": 3,
      "name": "Rock_Shale_Brick_Half"
    },
    {
      "x": -64,
      "y": 2,
      "z": 4,
      "name": "Prototype_Rock_Concrete_Brick_Half"
    },
    {
      "x": -64,
      "y": 2,
      "z": 5,
      "name": "Prototype_Rock_Concrete_Brick_Stairs",
      "rotation": 3
    },
    {
      "x": -64,
      "y": 2,
      "z": 6,
      "name": "Prototype_Rock_Concrete_Brick_Half"
    },
    {
      "x": -64,
      "y": 2,
      "z": 7,
      "name": "Prototype_Rock_Concrete_Brick"
    },
    {
      "x": -64,
      "y": 3,
      "z": 7,
      "name": "Prototype_Rock_Concrete_Brick_Half"
    },
    {
      "x": -64,
      "y": 2,
      "z": 8,
      "name": "Prototype_Rock_Concrete_Brick_Half"
    },
    {
      "x": -63,
      "y": 2,
      "z": -6,
      "name": "Prototype_Rock_Concrete_Brick_Half",
      "rotation": 8
    },
    {
      "x": -63,
      "y": 2,
      "z": -5,
      "name": "Prototype_Rock_Concrete_Brick"
    },
    {
      "x": -63,
      "y": 3,
      "z": -5,
      "name": "Prototype_Rock_Concrete_Brick_Stairs",
      "rotation": 3
    },
    {
      "x": -63,
      "y": 2,
      "z": -4,
      "name": "Prototype_Rock_Concrete_Brick_Half",
      "rotation": 8
    },
    {
      "x": -63,
      "y": 2,
      "z": -3,
      "name": "Rock_Crystal_Cyan_Block"
    },
    {
      "x": -63,
      "y": 3,
      "z": -3,
      "name": "Plant_Moss_Rug_Green_Dark"
    },
    {
      "x": -63,
      "y": 2,
      "z": -2,
      "name": "Rock_Shale_Brick_Half",
      "rotation": 8
    },
    {
      "x": -63,
      "y": 2,
      "z": -1,
      "name": "Rock_Shale_Cobble_Half",
      "rotation": 8
    },
    {
      "x": -63,
      "y": 2,
      "z": 0,
      "name": "Prototype_Rock_Concrete_Brick_Half",
      "rotation": 8
    },
    {
      "x": -63,
      "y": 2,
      "z": 1,
      "name": "Rock_Shale_Brick_Half",
      "rotation": 8
    },
    {
      "x": -63,
      "y": 2,
      "z": 2,
      "name": "Prototype_Rock_Concrete_Brick_Half",
      "rotation": 8
    },
    {
      "x": -63,
      "y": 2,
      "z": 3,
      "name": "Rock_Shale_Cobble_Half",
      "rotation": 8
    },
    {
      "x": -63,
      "y": 2,
      "z": 4,
      "name": "Rock_Shale_Brick_Half",
      "rotation": 8
    },
    {
      "x": -63,
      "y": 2,
      "z": 5,
      "name": "Rock_Crystal_Cyan_Block"
    },
    {
      "x": -63,
      "y": 3,
      "z": 5,
      "name": "Plant_Moss_Rug_Green_Dark"
    },
    {
      "x": -63,
      "y": 2,
      "z": 6,
      "name": "Prototype_Rock_Concrete_Brick_Half",
      "rotation": 8
    },
    {
      "x": -63,
      "y": 2,
      "z": 7,
      "name": "Prototype_Rock_Concrete_Brick"
    },
    {
      "x": -63,
      "y": 3,
      "z": 7,
      "name": "Prototype_Rock_Concrete_Brick_Stairs",
      "rotation": 3
    },
    {
      "x": -63,
      "y": 2,
      "z": 8,
      "name": "Prototype_Rock_Concrete_Brick_Half",
      "rotation": 8
    },
    {
      "x": -62,
      "y": 2,
      "z": -6,
      "name": "Wood_Hardwood_Fence",
      "rotation": 1
    },
    {
      "x": -62,
      "y": 3,
      "z": -6,
      "name": "Prototype_Rock_Concrete_Brick_Half"
    },
    {
      "x": -62,
      "y": 2,
      "z": -5,
      "name": "Rock_Stone_Brick"
    },
    {
      "x": -62,
      "y": 3,
      "z": -5,
      "name": "Prototype_Rock_Concrete_Brick"
    },
    {
      "x": -62,
      "y": 4,
      "z": -5,
      "name": "Prototype_Rock_Concrete_Brick_Half"
    },
    {
      "x": -62,
      "y": 3,
      "z": -4,
      "name": "Prototype_Rock_Concrete_Brick_Half"
    },
    {
      "x": -62,
      "y": 3,
      "z": -3,
      "name": "Prototype_Rock_Concrete_Brick_Half"
    },
    {
      "x": -62,
      "y": 3,
      "z": -2,
      "name": "Rock_Shale_Brick_Half"
    },
    {
      "x": -62,
      "y": 3,
      "z": -1,
      "name": "Rock_Shale_Cobble_Half"
    },
    {
      "x": -62,
      "y": 3,
      "z": 0,
      "name": "Prototype_Rock_Concrete_Brick_Half"
    },
    {
      "x": -62,
      "y": 3,
      "z": 1,
      "name": "Rock_Shale_Brick_Stairs",
      "rotation": 3
    },
    {
      "x": -62,
      "y": 3,
      "z": 2,
      "name": "Prototype_Rock_Concrete_Brick_Half"
    },
    {
      "x": -62,
      "y": 3,
      "z": 3,
      "name": "Rock_Shale_Cobble_Half"
    },
    {
      "x": -62,
      "y": 3,
      "z": 4,
      "name": "Rock_Shale_Brick_Half"
    },
    {
      "x": -62,
      "y": 3,
      "z": 5,
      "name": "Prototype_Rock_Concrete_Brick_Half"
    },
    {
      "x": -62,
      "y": 3,
      "z": 6,
      "name": "Prototype_Rock_Concrete_Brick_Half"
    },
    {
      "x": -62,
      "y": 2,
      "z": 7,
      "name": "Rock_Shale_Brick"
    },
    {
      "x": -62,
      "y": 3,
      "z": 7,
      "name": "Prototype_Rock_Concrete_Brick"
    },
    {
      "x": -62,
      "y": 4,
      "z": 7,
      "name": "Prototype_Rock_Concrete_Brick_Half"
    },
    {
      "x": -62,
      "y": 2,
      "z": 8,
      "name": "Wood_Hardwood_Fence",
      "rotation": 1
    },
    {
      "x": -62,
      "y": 3,
      "z": 8,
      "name": "Prototype_Rock_Concrete_Brick_Half"
    },
    {
      "x": -61,
      "y": 3,
      "z": -6,
      "name": "Prototype_Rock_Concrete_Brick_Half",
      "rotation": 8
    },
    {
      "x": -61,
      "y": 2,
      "z": -5,
      "name": "Rock_Stone_Brick"
    },
    {
      "x": -61,
      "y": 3,
      "z": -5,
      "name": "Prototype_Rock_Concrete_Brick"
    },
    {
      "x": -61,
      "y": 4,
      "z": -5,
      "name": "Prototype_Rock_Concrete_Brick_Stairs",
      "rotation": 3
    },
    {
      "x": -61,
      "y": 2,
      "z": -4,
      "name": "Rock_Crystal_Cyan_Block"
    },
    {
      "x": -61,
      "y": 3,
      "z": -4,
      "name": "Prototype_Rock_Concrete_Brick_Half",
      "rotation": 8
    },
    {
      "x": -61,
      "y": 3,
      "z": -3,
      "name": "Rock_Shale_Brick_Half",
      "rotation": 8
    },
    {
      "x": -61,
      "y": 3,
      "z": -2,
      "name": "Rock_Shale_Cobble_Half",
      "rotation": 8
    },
    {
      "x": -61,
      "y": 3,
      "z": -1,
      "name": "Prototype_Rock_Concrete_Brick_Half",
      "rotation": 8
    },
    {
      "x": -61,
      "y": 3,
      "z": 0,
      "name": "Rock_Shale_Brick_Half",
      "rotation": 8
    },
    {
      "x": -61,
      "y": 3,
      "z": 1,
      "name": "Rock_Crystal_Cyan_Block"
    },
    {
      "x": -61,
      "y": 4,
      "z": 1,
      "name": "Plant_Moss_Rug_Green_Dark"
    },
    {
      "x": -61,
      "y": 3,
      "z": 2,
      "name": "Rock_Shale_Brick_Half",
      "rotation": 8
    },
    {
      "x": -61,
      "y": 3,
      "z": 3,
      "name": "Prototype_Rock_Concrete_Brick_Half",
      "rotation": 8
    },
    {
      "x": -61,
      "y": 3,
      "z": 4,
      "name": "Rock_Shale_Cobble_Half",
      "rotation": 8
    },
    {
      "x": -61,
      "y": 3,
      "z": 5,
      "name": "Rock_Shale_Brick_Half",
      "rotation": 8
    },
    {
      "x": -61,
      "y": 2,
      "z": 6,
      "name": "Rock_Crystal_Cyan_Block"
    },
    {
      "x": -61,
      "y": 3,
      "z": 6,
      "name": "Prototype_Rock_Concrete_Brick_Half",
      "rotation": 8
    },
    {
      "x": -61,
      "y": 2,
      "z": 7,
      "name": "Rock_Stone_Brick"
    },
    {
      "x": -61,
      "y": 3,
      "z": 7,
      "name": "Prototype_Rock_Concrete_Brick"
    },
    {
      "x": -61,
      "y": 4,
      "z": 7,
      "name": "Prototype_Rock_Concrete_Brick_Stairs",
      "rotation": 3
    },
    {
      "x": -61,
      "y": 3,
      "z": 8,
      "name": "Prototype_Rock_Concrete_Brick_Half",
      "rotation": 8
    },
    {
      "x": -60,
      "y": 2,
      "z": -6,
      "name": "Wood_Hardwood_Fence",
      "rotation": 1
    },
    {
      "x": -60,
      "y": 3,
      "z": -6,
      "name": "Wood_Hardwood_Fence",
      "rotation": 1
    },
    {
      "x": -60,
      "y": 4,
      "z": -6,
      "name": "Prototype_Rock_Concrete_Brick_Half"
    },
    {
      "x": -60,
      "y": 2,
      "z": -5,
      "name": "Rock_Shale_Brick"
    },
    {
      "x": -60,
      "y": 3,
      "z": -5,
      "name": "Rock_Shale_Brick"
    },
    {
      "x": -60,
      "y": 4,
      "z": -5,
      "name": "Prototype_Rock_Concrete_Brick"
    },
    {
      "x": -60,
      "y": 5,
      "z": -5,
      "name": "Prototype_Rock_Concrete_Brick_Half"
    },
    {
      "x": -60,
      "y": 4,
      "z": -4,
      "name": "Prototype_Rock_Concrete_Brick_Half"
    },
    {
      "x": -60,
      "y": 4,
      "z": -3,
      "name": "Rock_Shale_Brick_Stairs",
      "rotation": 3
    },
    {
      "x": -60,
      "y": 4,
      "z": -2,
      "name": "Rock_Shale_Cobble_Half"
    },
    {
      "x": -60,
      "y": 4,
      "z": -1,
      "name": "Prototype_Rock_Concrete_Brick_Half"
    },
    {
      "x": -60,
      "y": 4,
      "z": 0,
      "name": "Rock_Shale_Brick_Half"
    },
    {
      "x": -60,
      "y": 4,
      "z": 1,
      "name": "Rock_Shale_Cobble_Half"
    },
    {
      "x": -60,
      "y": 4,
      "z": 2,
      "name": "Rock_Shale_Brick_Half"
    },
    {
      "x": -60,
      "y": 4,
      "z": 3,
      "name": "Prototype_Rock_Concrete_Brick_Half"
    },
    {
      "x": -60,
      "y": 4,
      "z": 4,
      "name": "Rock_Shale_Cobble_Half"
    },
    {
      "x": -60,
      "y": 4,
      "z": 5,
      "name": "Rock_Shale_Brick_Stairs",
      "rotation": 3
    },
    {
      "x": -60,
      "y": 4,
      "z": 6,
      "name": "Prototype_Rock_Concrete_Brick_Half"
    },
    {
      "x": -60,
      "y": 2,
      "z": 7,
      "name": "Rock_Shale_Brick"
    },
    {
      "x": -60,
      "y": 3,
      "z": 7,
      "name": "Rock_Stone_Brick"
    },
    {
      "x": -60,
      "y": 4,
      "z": 7,
      "name": "Prototype_Rock_Concrete_Brick"
    },
    {
      "x": -60,
      "y": 5,
      "z": 7,
      "name": "Prototype_Rock_Concrete_Brick_Half"
    },
    {
      "x": -60,
      "y": 2,
      "z": 8,
      "name": "Wood_Hardwood_Fence",
      "rotation": 1
    },
    {
      "x": -60,
      "y": 3,
      "z": 8,
      "name": "Wood_Hardwood_Fence",
      "rotation": 1
    },
    {
      "x": -60,
      "y": 4,
      "z": 8,
      "name": "Prototype_Rock_Concrete_Brick_Half"
    },
    {
      "x": -59,
      "y": 2,
      "z": -6,
      "name": "*Furniture_Crude_Trapdoor_State_Definitions_OpenDoorOut",
      "rotation": 2
    },
    {
      "x": -59,
      "y": 4,
      "z": -6,
      "name": "Prototype_Rock_Concrete_Brick_Half",
      "rotation": 8
    },
    {
      "x": -59,
      "y": 2,
      "z": -5,
      "name": "Rock_Stone_Cobble"
    },
    {
      "x": -59,
      "y": 3,
      "z": -5,
      "name": "Rock_Stone_Brick"
    },
    {
      "x": -59,
      "y": 4,
      "z": -5,
      "name": "Prototype_Rock_Concrete_Brick"
    },
    {
      "x": -59,
      "y": 5,
      "z": -5,
      "name": "Prototype_Rock_Concrete_Brick_Stairs",
      "rotation": 3
    },
    {
      "x": -59,
      "y": 2,
      "z": -4,
      "name": "Rock_Crystal_Cyan_Block"
    },
    {
      "x": -59,
      "y": 3,
      "z": -4,
      "name": "Rock_Crystal_Cyan_Block"
    },
    {
      "x": -59,
      "y": 4,
      "z": -4,
      "name": "Prototype_Rock_Concrete_Brick_Half",
      "rotation": 8
    },
    {
      "x": -59,
      "y": 4,
      "z": -3,
      "name": "Rock_Crystal_Cyan_Block"
    },
    {
      "x": -59,
      "y": 5,
      "z": -3,
      "name": "Plant_Moss_Rug_Green_Dark"
    },
    {
      "x": -59,
      "y": 4,
      "z": -2,
      "name": "Rock_Shale_Cobble_Half",
      "rotation": 8
    },
    {
      "x": -59,
      "y": 4,
      "z": -1,
      "name": "Prototype_Rock_Concrete_Brick_Half",
      "rotation": 8
    },
    {
      "x": -59,
      "y": 4,
      "z": 0,
      "name": "Rock_Shale_Brick_Half",
      "rotation": 8
    },
    {
      "x": -59,
      "y": 4,
      "z": 1,
      "name": "Rock_Shale_Cobble_Half",
      "rotation": 8
    },
    {
      "x": -59,
      "y": 4,
      "z": 2,
      "name": "Rock_Shale_Brick_Half",
      "rotation": 8
    },
    {
      "x": -59,
      "y": 4,
      "z": 3,
      "name": "Prototype_Rock_Concrete_Brick_Half",
      "rotation": 8
    },
    {
      "x": -59,
      "y": 4,
      "z": 4,
      "name": "Rock_Shale_Cobble_Half",
      "rotation": 8
    },
    {
      "x": -59,
      "y": 4,
      "z": 5,
      "name": "Rock_Crystal_Cyan_Block"
    },
    {
      "x": -59,
      "y": 5,
      "z": 5,
      "name": "Plant_Moss_Rug_Green_Dark"
    },
    {
      "x": -59,
      "y": 2,
      "z": 6,
      "name": "Rock_Crystal_Cyan_Block"
    },
    {
      "x": -59,
      "y": 3,
      "z": 6,
      "name": "Rock_Crystal_Cyan_Block"
    },
    {
      "x": -59,
      "y": 4,
      "z": 6,
      "name": "Prototype_Rock_Concrete_Brick_Half",
      "rotation": 8
    },
    {
      "x": -59,
      "y": 2,
      "z": 7,
      "name": "Rock_Stone_Cobble"
    },
    {
      "x": -59,
      "y": 3,
      "z": 7,
      "name": "Rock_Stone_Brick"
    },
    {
      "x": -59,
      "y": 4,
      "z": 7,
      "name": "Prototype_Rock_Concrete_Brick"
    },
    {
      "x": -59,
      "y": 5,
      "z": 7,
      "name": "Prototype_Rock_Concrete_Brick_Stairs",
      "rotation": 3
    },
    {
      "x": -59,
      "y": 2,
      "z": 8,
      "name": "*Furniture_Crude_Trapdoor_State_Definitions_OpenDoorOut"
    },
    {
      "x": -59,
      "y": 4,
      "z": 8,
      "name": "Prototype_Rock_Concrete_Brick_Half",
      "rotation": 8
    },
    {
      "x": -58,
      "y": 2,
      "z": -6,
      "name": "Wood_Hardwood_Fence",
      "rotation": 1
    },
    {
      "x": -58,
      "y": 3,
      "z": -6,
      "name": "Wood_Hardwood_Fence",
      "rotation": 1
    },
    {
      "x": -58,
      "y": 4,
      "z": -6,
      "name": "Wood_Hardwood_Fence",
      "rotation": 1
    },
    {
      "x": -58,
      "y": 5,
      "z": -6,
      "name": "Prototype_Rock_Concrete_Brick_Half"
    },
    {
      "x": -58,
      "y": 2,
      "z": -5,
      "name": "Rock_Stone_Brick"
    },
    {
      "x": -58,
      "y": 3,
      "z": -5,
      "name": "Rock_Stone_Brick"
    },
    {
      "x": -58,
      "y": 4,
      "z": -5,
      "name": "Rock_Stone_Brick_Mossy"
    },
    {
      "x": -58,
      "y": 5,
      "z": -5,
      "name": "Prototype_Rock_Concrete_Brick"
    },
    {
      "x": -58,
      "y": 6,
      "z": -5,
      "name": "Prototype_Rock_Concrete_Brick_Half"
    },
    {
      "x": -58,
      "y": 5,
      "z": -4,
      "name": "Prototype_Rock_Concrete_Brick_Half"
    },
    {
      "x": -58,
      "y": 5,
      "z": -3,
      "name": "Rock_Shale_Brick_Half"
    },
    {
      "x": -58,
      "y": 5,
      "z": -2,
      "name": "Rock_Shale_Cobble_Half"
    },
    {
      "x": -58,
      "y": 5,
      "z": -1,
      "name": "Prototype_Rock_Concrete_Brick_Half"
    },
    {
      "x": -58,
      "y": 5,
      "z": 0,
      "name": "Rock_Shale_Brick_Half"
    },
    {
      "x": -58,
      "y": 5,
      "z": 1,
      "name": "Rock_Shale_Cobble_Stairs",
      "rotation": 3
    },
    {
      "x": -58,
      "y": 5,
      "z": 2,
      "name": "Rock_Shale_Brick_Half"
    },
    {
      "x": -58,
      "y": 5,
      "z": 3,
      "name": "Prototype_Rock_Concrete_Brick_Half"
    },
    {
      "x": -58,
      "y": 5,
      "z": 4,
      "name": "Rock_Shale_Cobble_Half"
    },
    {
      "x": -58,
      "y": 5,
      "z": 5,
      "name": "Rock_Shale_Brick_Half"
    },
    {
      "x": -58,
      "y": 5,
      "z": 6,
      "name": "Prototype_Rock_Concrete_Brick_Half"
    },
    {
      "x": -58,
      "y": 2,
      "z": 7,
      "name": "Rock_Stone_Brick_Mossy"
    },
    {
      "x": -58,
      "y": 3,
      "z": 7,
      "name": "Rock_Stone_Brick"
    },
    {
      "x": -58,
      "y": 4,
      "z": 7,
      "name": "Rock_Shale_Brick"
    },
    {
      "x": -58,
      "y": 5,
      "z": 7,
      "name": "Prototype_Rock_Concrete_Brick"
    },
    {
      "x": -58,
      "y": 6,
      "z": 7,
      "name": "Prototype_Rock_Concrete_Brick_Half"
    },
    {
      "x": -58,
      "y": 2,
      "z": 8,
      "name": "Wood_Hardwood_Fence",
      "rotation": 1
    },
    {
      "x": -58,
      "y": 3,
      "z": 8,
      "name": "Wood_Hardwood_Fence",
      "rotation": 1
    },
    {
      "x": -58,
      "y": 4,
      "z": 8,
      "name": "Wood_Hardwood_Fence",
      "rotation": 1
    },
    {
      "x": -58,
      "y": 5,
      "z": 8,
      "name": "Prototype_Rock_Concrete_Brick_Half"
    },
    {
      "x": -57,
      "y": 3,
      "z": -6,
      "name": "*Furniture_Crude_Trapdoor_State_Definitions_OpenDoorOut",
      "rotation": 2
    },
    {
      "x": -57,
      "y": 5,
      "z": -6,
      "name": "Prototype_Rock_Concrete_Brick_Half",
      "rotation": 8
    },
    {
      "x": -57,
      "y": 2,
      "z": -5,
      "name": "Rock_Chalk_Brick_Wall"
    },
    {
      "x": -57,
      "y": 3,
      "z": -5,
      "name": "Rock_Stone_Cobble"
    },
    {
      "x": -57,
      "y": 4,
      "z": -5,
      "name": "Rock_Shale_Brick"
    },
    {
      "x": -57,
      "y": 5,
      "z": -5,
      "name": "Prototype_Rock_Concrete_Brick"
    },
    {
      "x": -57,
      "y": 6,
      "z": -5,
      "name": "Prototype_Rock_Concrete_Brick_Stairs",
      "rotation": 3
    },
    {
      "x": -57,
      "y": 2,
      "z": -4,
      "name": "Rock_Crystal_Cyan_Block"
    },
    {
      "x": -57,
      "y": 3,
      "z": -4,
      "name": "Rock_Crystal_Cyan_Block"
    },
    {
      "x": -57,
      "y": 4,
      "z": -4,
      "name": "Rock_Crystal_Cyan_Block"
    },
    {
      "x": -57,
      "y": 5,
      "z": -4,
      "name": "Rock_Shale_Brick_Half",
      "rotation": 8
    },
    {
      "x": -57,
      "y": 5,
      "z": -3,
      "name": "Rock_Shale_Cobble_Half",
      "rotation": 8
    },
    {
      "x": -57,
      "y": 5,
      "z": -2,
      "name": "Prototype_Rock_Concrete_Brick_Half",
      "rotation": 8
    },
    {
      "x": -57,
      "y": 5,
      "z": -1,
      "name": "Rock_Shale_Brick_Half",
      "rotation": 8
    },
    {
      "x": -57,
      "y": 5,
      "z": 0,
      "name": "Rock_Shale_Cobble_Half",
      "rotation": 8
    },
    {
      "x": -57,
      "y": 5,
      "z": 1,
      "name": "Rock_Crystal_Cyan_Block"
    },
    {
      "x": -57,
      "y": 6,
      "z": 1,
      "name": "Plant_Moss_Rug_Green_Dark"
    },
    {
      "x": -57,
      "y": 5,
      "z": 2,
      "name": "Rock_Shale_Cobble_Half",
      "rotation": 8
    },
    {
      "x": -57,
      "y": 5,
      "z": 3,
      "name": "Rock_Shale_Brick_Half",
      "rotation": 8
    },
    {
      "x": -57,
      "y": 5,
      "z": 4,
      "name": "Prototype_Rock_Concrete_Brick_Half",
      "rotation": 8
    },
    {
      "x": -57,
      "y": 5,
      "z": 5,
      "name": "Rock_Shale_Cobble_Half",
      "rotation": 8
    },
    {
      "x": -57,
      "y": 2,
      "z": 6,
      "name": "Rock_Crystal_Cyan_Block"
    },
    {
      "x": -57,
      "y": 3,
      "z": 6,
      "name": "Rock_Crystal_Cyan_Block"
    },
    {
      "x": -57,
      "y": 4,
      "z": 6,
      "name": "Rock_Crystal_Cyan_Block"
    },
    {
      "x": -57,
      "y": 5,
      "z": 6,
      "name": "Rock_Shale_Brick_Half",
      "rotation": 8
    },
    {
      "x": -57,
      "y": 2,
      "z": 7,
      "name": "Rock_Chalk_Brick_Wall"
    },
    {
      "x": -57,
      "y": 3,
      "z": 7,
      "name": "Rock_Stone_Cobble"
    },
    {
      "x": -57,
      "y": 4,
      "z": 7,
      "name": "Rock_Stone_Brick"
    },
    {
      "x": -57,
      "y": 5,
      "z": 7,
      "name": "Prototype_Rock_Concrete_Brick"
    },
    {
      "x": -57,
      "y": 6,
      "z": 7,
      "name": "Prototype_Rock_Concrete_Brick_Stairs",
      "rotation": 3
    },
    {
      "x": -57,
      "y": 3,
      "z": 8,
      "name": "*Furniture_Crude_Trapdoor_State_Definitions_OpenDoorOut"
    },
    {
      "x": -57,
      "y": 5,
      "z": 8,
      "name": "Prototype_Rock_Concrete_Brick_Half",
      "rotation": 8
    },
    {
      "x": -56,
      "y": 2,
      "z": -6,
      "name": "Wood_Hardwood_Fence",
      "rotation": 1
    },
    {
      "x": -56,
      "y": 3,
      "z": -6,
      "name": "Wood_Hardwood_Fence",
      "rotation": 1
    },
    {
      "x": -56,
      "y": 4,
      "z": -6,
      "name": "Wood_Hardwood_Fence",
      "rotation": 1
    },
    {
      "x": -56,
      "y": 5,
      "z": -6,
      "name": "Wood_Hardwood_Fence",
      "rotation": 1
    },
    {
      "x": -56,
      "y": 6,
      "z": -6,
      "name": "Prototype_Rock_Concrete_Brick_Half"
    },
    {
      "x": -56,
      "y": 2,
      "z": -5,
      "name": "Rock_Stone_Brick"
    },
    {
      "x": -56,
      "y": 3,
      "z": -5,
      "name": "Rock_Stone_Brick_Mossy"
    },
    {
      "x": -56,
      "y": 4,
      "z": -5,
      "name": "Rock_Stone_Brick_Mossy"
    },
    {
      "x": -56,
      "y": 5,
      "z": -5,
      "name": "Rock_Shale_Brick"
    },
    {
      "x": -56,
      "y": 6,
      "z": -5,
      "name": "Prototype_Rock_Concrete_Brick"
    },
    {
      "x": -56,
      "y": 7,
      "z": -5,
      "name": "Prototype_Rock_Concrete_Brick_Half"
    },
    {
      "x": -56,
      "y": 6,
      "z": -4,
      "name": "Rock_Shale_Brick_Half"
    },
    {
      "x": -56,
      "y": 6,
      "z": -3,
      "name": "Rock_Shale_Cobble_Half"
    },
    {
      "x": -56,
      "y": 6,
      "z": -2,
      "name": "Prototype_Rock_Concrete_Brick_Half"
    },
    {
      "x": -56,
      "y": 6,
      "z": -1,
      "name": "Rock_Shale_Brick_Half"
    },
    {
      "x": -56,
      "y": 6,
      "z": 0,
      "name": "Rock_Shale_Cobble_Half"
    },
    {
      "x": -56,
      "y": 6,
      "z": 1,
      "name": "Rock_Shale_Brick_Stairs",
      "rotation": 3
    },
    {
      "x": -56,
      "y": 6,
      "z": 2,
      "name": "Rock_Shale_Cobble_Half"
    },
    {
      "x": -56,
      "y": 6,
      "z": 3,
      "name": "Rock_Shale_Brick_Half"
    },
    {
      "x": -56,
      "y": 6,
      "z": 4,
      "name": "Prototype_Rock_Concrete_Brick_Half"
    },
    {
      "x": -56,
      "y": 6,
      "z": 5,
      "name": "Rock_Shale_Cobble_Half"
    },
    {
      "x": -56,
      "y": 6,
      "z": 6,
      "name": "Rock_Shale_Brick_Half"
    },
    {
      "x": -56,
      "y": 2,
      "z": 7,
      "name": "Rock_Stone_Brick_Mossy"
    },
    {
      "x": -56,
      "y": 3,
      "z": 7,
      "name": "Rock_Shale_Brick"
    },
    {
      "x": -56,
      "y": 4,
      "z": 7,
      "name": "Rock_Stone_Brick"
    },
    {
      "x": -56,
      "y": 5,
      "z": 7,
      "name": "Rock_Stone_Brick"
    },
    {
      "x": -56,
      "y": 6,
      "z": 7,
      "name": "Prototype_Rock_Concrete_Brick"
    },
    {
      "x": -56,
      "y": 7,
      "z": 7,
      "name": "Prototype_Rock_Concrete_Brick_Half"
    },
    {
      "x": -56,
      "y": 2,
      "z": 8,
      "name": "Wood_Hardwood_Fence",
      "rotation": 1
    },
    {
      "x": -56,
      "y": 3,
      "z": 8,
      "name": "Wood_Hardwood_Fence",
      "rotation": 1
    },
    {
      "x": -56,
      "y": 4,
      "z": 8,
      "name": "Wood_Hardwood_Fence",
      "rotation": 1
    },
    {
      "x": -56,
      "y": 5,
      "z": 8,
      "name": "Wood_Hardwood_Fence",
      "rotation": 1
    },
    {
      "x": -56,
      "y": 6,
      "z": 8,
      "name": "Prototype_Rock_Concrete_Brick_Half"
    },
    {
      "x": -55,
      "y": 4,
      "z": -6,
      "name": "*Furniture_Crude_Trapdoor_State_Definitions_OpenDoorOut",
      "rotation": 2
    },
    {
      "x": -55,
      "y": 6,
      "z": -6,
      "name": "Prototype_Rock_Concrete_Brick_Half",
      "rotation": 8
    },
    {
      "x": -55,
      "y": 2,
      "z": -5,
      "name": "Rock_Chalk_Brick_Wall"
    },
    {
      "x": -55,
      "y": 3,
      "z": -5,
      "name": "Rock_Chalk_Brick_Wall"
    },
    {
      "x": -55,
      "y": 4,
      "z": -5,
      "name": "Rock_Stone_Cobble"
    },
    {
      "x": -55,
      "y": 5,
      "z": -5,
      "name": "Rock_Stone_Brick_Mossy"
    },
    {
      "x": -55,
      "y": 6,
      "z": -5,
      "name": "Prototype_Rock_Concrete_Brick"
    },
    {
      "x": -55,
      "y": 7,
      "z": -5,
      "name": "Prototype_Rock_Concrete_Brick_Stairs",
      "rotation": 3
    },
    {
      "x": -55,
      "y": 2,
      "z": -4,
      "name": "Rock_Crystal_Cyan_Block"
    },
    {
      "x": -55,
      "y": 3,
      "z": -4,
      "name": "Rock_Crystal_Cyan_Block"
    },
    {
      "x": -55,
      "y": 4,
      "z": -4,
      "name": "Rock_Crystal_Cyan_Block"
    },
    {
      "x": -55,
      "y": 5,
      "z": -4,
      "name": "Rock_Crystal_Cyan_Block"
    },
    {
      "x": -55,
      "y": 6,
      "z": -4,
      "name": "Rock_Shale_Brick_Half",
      "rotation": 8
    },
    {
      "x": -55,
      "y": 6,
      "z": -3,
      "name": "Rock_Shale_Cobble_Half",
      "rotation": 8
    },
    {
      "x": -55,
      "y": 6,
      "z": -2,
      "name": "Prototype_Rock_Concrete_Brick_Half",
      "rotation": 8
    },
    {
      "x": -55,
      "y": 6,
      "z": -1,
      "name": "Rock_Shale_Brick_Half",
      "rotation": 8
    },
    {
      "x": -55,
      "y": 6,
      "z": 0,
      "name": "Rock_Shale_Cobble_Half",
      "rotation": 8
    },
    {
      "x": -55,
      "y": 6,
      "z": 1,
      "name": "Rock_Crystal_Cyan_Block"
    },
    {
      "x": -55,
      "y": 7,
      "z": 1,
      "name": "Plant_Moss_Rug_Green_Dark"
    },
    {
      "x": -55,
      "y": 6,
      "z": 2,
      "name": "Rock_Shale_Cobble_Half",
      "rotation": 8
    },
    {
      "x": -55,
      "y": 6,
      "z": 3,
      "name": "Rock_Shale_Brick_Half",
      "rotation": 8
    },
    {
      "x": -55,
      "y": 6,
      "z": 4,
      "name": "Prototype_Rock_Concrete_Brick_Half",
      "rotation": 8
    },
    {
      "x": -55,
      "y": 6,
      "z": 5,
      "name": "Rock_Shale_Cobble_Half",
      "rotation": 8
    },
    {
      "x": -55,
      "y": 2,
      "z": 6,
      "name": "Rock_Crystal_Cyan_Block"
    },
    {
      "x": -55,
      "y": 3,
      "z": 6,
      "name": "Rock_Crystal_Cyan_Block"
    },
    {
      "x": -55,
      "y": 4,
      "z": 6,
      "name": "Rock_Crystal_Cyan_Block"
    },
    {
      "x": -55,
      "y": 5,
      "z": 6,
      "name": "Rock_Crystal_Cyan_Block"
    },
    {
      "x": -55,
      "y": 6,
      "z": 6,
      "name": "Rock_Shale_Brick_Half",
      "rotation": 8
    },
    {
      "x": -55,
      "y": 2,
      "z": 7,
      "name": "Rock_Chalk_Brick_Wall"
    },
    {
      "x": -55,
      "y": 3,
      "z": 7,
      "name": "Rock_Chalk_Brick_Wall"
    },
    {
      "x": -55,
      "y": 4,
      "z": 7,
      "name": "Rock_Stone_Cobble"
    },
    {
      "x": -55,
      "y": 5,
      "z": 7,
      "name": "Rock_Shale_Brick"
    },
    {
      "x": -55,
      "y": 6,
      "z": 7,
      "name": "Prototype_Rock_Concrete_Brick"
    },
    {
      "x": -55,
      "y": 7,
      "z": 7,
      "name": "Prototype_Rock_Concrete_Brick_Stairs",
      "rotation": 3
    },
    {
      "x": -55,
      "y": 4,
      "z": 8,
      "name": "*Furniture_Crude_Trapdoor_State_Definitions_OpenDoorOut"
    },
    {
      "x": -55,
      "y": 6,
      "z": 8,
      "name": "Prototype_Rock_Concrete_Brick_Half",
      "rotation": 8
    },
    {
      "x": -54,
      "y": 2,
      "z": -6,
      "name": "Wood_Hardwood_Fence",
      "rotation": 1
    },
    {
      "x": -54,
      "y": 3,
      "z": -6,
      "name": "Wood_Hardwood_Fence",
      "rotation": 1
    },
    {
      "x": -54,
      "y": 4,
      "z": -6,
      "name": "Wood_Hardwood_Fence",
      "rotation": 1
    },
    {
      "x": -54,
      "y": 5,
      "z": -6,
      "name": "Wood_Hardwood_Fence",
      "rotation": 1
    },
    {
      "x": -54,
      "y": 6,
      "z": -6,
      "name": "Wood_Hardwood_Fence",
      "rotation": 1
    },
    {
      "x": -54,
      "y": 7,
      "z": -6,
      "name": "Prototype_Rock_Concrete_Brick_Half"
    },
    {
      "x": -54,
      "y": 2,
      "z": -5,
      "name": "Rock_Shale_Brick"
    },
    {
      "x": -54,
      "y": 3,
      "z": -5,
      "name": "Rock_Stone_Brick_Mossy"
    },
    {
      "x": -54,
      "y": 4,
      "z": -5,
      "name": "Rock_Shale_Brick"
    },
    {
      "x": -54,
      "y": 5,
      "z": -5,
      "name": "Rock_Stone_Brick"
    },
    {
      "x": -54,
      "y": 6,
      "z": -5,
      "name": "Rock_Stone_Brick"
    },
    {
      "x": -54,
      "y": 7,
      "z": -5,
      "name": "Prototype_Rock_Concrete_Brick"
    },
    {
      "x": -54,
      "y": 8,
      "z": -5,
      "name": "Prototype_Rock_Concrete_Brick_Half"
    },
    {
      "x": -54,
      "y": 7,
      "z": -4,
      "name": "Rock_Shale_Brick_Half"
    },
    {
      "x": -54,
      "y": 7,
      "z": -3,
      "name": "Rock_Shale_Cobble_Half"
    },
    {
      "x": -54,
      "y": 7,
      "z": -2,
      "name": "Prototype_Rock_Concrete_Brick_Half"
    },
    {
      "x": -54,
      "y": 7,
      "z": -1,
      "name": "Rock_Shale_Brick_Half"
    },
    {
      "x": -54,
      "y": 7,
      "z": 0,
      "name": "Rock_Shale_Cobble_Half"
    },
    {
      "x": -54,
      "y": 7,
      "z": 1,
      "name": "Rock_Shale_Brick_Stairs",
      "rotation": 3
    },
    {
      "x": -54,
      "y": 7,
      "z": 2,
      "name": "Rock_Shale_Cobble_Half"
    },
    {
      "x": -54,
      "y": 7,
      "z": 3,
      "name": "Rock_Shale_Brick_Half"
    },
    {
      "x": -54,
      "y": 7,
      "z": 4,
      "name": "Prototype_Rock_Concrete_Brick_Half"
    },
    {
      "x": -54,
      "y": 7,
      "z": 5,
      "name": "Rock_Shale_Cobble_Half"
    },
    {
      "x": -54,
      "y": 7,
      "z": 6,
      "name": "Rock_Shale_Brick_Half"
    },
    {
      "x": -54,
      "y": 2,
      "z": 7,
      "name": "Rock_Shale_Brick"
    },
    {
      "x": -54,
      "y": 3,
      "z": 7,
      "name": "Rock_Stone_Brick_Mossy"
    },
    {
      "x": -54,
      "y": 4,
      "z": 7,
      "name": "Rock_Shale_Brick"
    },
    {
      "x": -54,
      "y": 5,
      "z": 7,
      "name": "Rock_Stone_Brick_Mossy"
    },
    {
      "x": -54,
      "y": 6,
      "z": 7,
      "name": "Rock_Stone_Brick"
    },
    {
      "x": -54,
      "y": 7,
      "z": 7,
      "name": "Prototype_Rock_Concrete_Brick"
    },
    {
      "x": -54,
      "y": 8,
      "z": 7,
      "name": "Prototype_Rock_Concrete_Brick_Half"
    },
    {
      "x": -54,
      "y": 2,
      "z": 8,
      "name": "Wood_Hardwood_Fence",
      "rotation": 1
    },
    {
      "x": -54,
      "y": 3,
      "z": 8,
      "name": "Wood_Hardwood_Fence",
      "rotation": 1
    },
    {
      "x": -54,
      "y": 4,
      "z": 8,
      "name": "Wood_Hardwood_Fence",
      "rotation": 1
    },
    {
      "x": -54,
      "y": 5,
      "z": 8,
      "name": "Wood_Hardwood_Fence",
      "rotation": 1
    },
    {
      "x": -54,
      "y": 6,
      "z": 8,
      "name": "Wood_Hardwood_Fence",
      "rotation": 1
    },
    {
      "x": -54,
      "y": 7,
      "z": 8,
      "name": "Prototype_Rock_Concrete_Brick_Half"
    },
    {
      "x": -53,
      "y": 5,
      "z": -6,
      "name": "*Furniture_Crude_Trapdoor_State_Definitions_OpenDoorOut",
      "rotation": 2
    },
    {
      "x": -53,
      "y": 7,
      "z": -6,
      "name": "Prototype_Rock_Concrete_Brick_Half",
      "rotation": 8
    },
    {
      "x": -53,
      "y": 2,
      "z": -5,
      "name": "Rock_Chalk_Brick_Wall"
    },
    {
      "x": -53,
      "y": 3,
      "z": -5,
      "name": "Rock_Chalk_Brick_Wall"
    },
    {
      "x": -53,
      "y": 4,
      "z": -5,
      "name": "Rock_Chalk_Brick_Wall"
    },
    {
      "x": -53,
      "y": 5,
      "z": -5,
      "name": "Rock_Stone_Cobble"
    },
    {
      "x": -53,
      "y": 6,
      "z": -5,
      "name": "Rock_Shale_Brick"
    },
    {
      "x": -53,
      "y": 7,
      "z": -5,
      "name": "Prototype_Rock_Concrete_Brick"
    },
    {
      "x": -53,
      "y": 8,
      "z": -5,
      "name": "Prototype_Rock_Concrete_Brick_Stairs",
      "rotation": 3
    },
    {
      "x": -53,
      "y": 2,
      "z": -4,
      "name": "Rock_Crystal_Cyan_Block"
    },
    {
      "x": -53,
      "y": 3,
      "z": -4,
      "name": "Rock_Crystal_Cyan_Block"
    },
    {
      "x": -53,
      "y": 4,
      "z": -4,
      "name": "Rock_Crystal_Cyan_Block"
    },
    {
      "x": -53,
      "y": 5,
      "z": -4,
      "name": "Rock_Crystal_Cyan_Block"
    },
    {
      "x": -53,
      "y": 6,
      "z": -4,
      "name": "Rock_Crystal_Cyan_Block"
    },
    {
      "x": -53,
      "y": 7,
      "z": -4,
      "name": "Prototype_Rock_Concrete_Brick_Half",
      "rotation": 8
    },
    {
      "x": -53,
      "y": 7,
      "z": -3,
      "name": "Rock_Shale_Brick_Half",
      "rotation": 8
    },
    {
      "x": -53,
      "y": 7,
      "z": -2,
      "name": "Rock_Shale_Cobble_Half",
      "rotation": 8
    },
    {
      "x": -53,
      "y": 7,
      "z": -1,
      "name": "Prototype_Rock_Concrete_Brick_Half",
      "rotation": 8
    },
    {
      "x": -53,
      "y": 7,
      "z": 0,
      "name": "Rock_Shale_Brick_Half",
      "rotation": 8
    },
    {
      "x": -53,
      "y": 7,
      "z": 1,
      "name": "Rock_Crystal_Cyan_Block"
    },
    {
      "x": -53,
      "y": 8,
      "z": 1,
      "name": "Plant_Moss_Rug_Green_Dark"
    },
    {
      "x": -53,
      "y": 7,
      "z": 2,
      "name": "Rock_Shale_Brick_Half",
      "rotation": 8
    },
    {
      "x": -53,
      "y": 7,
      "z": 3,
      "name": "Prototype_Rock_Concrete_Brick_Half",
      "rotation": 8
    },
    {
      "x": -53,
      "y": 7,
      "z": 4,
      "name": "Rock_Shale_Cobble_Half",
      "rotation": 8
    },
    {
      "x": -53,
      "y": 7,
      "z": 5,
      "name": "Rock_Shale_Brick_Half",
      "rotation": 8
    },
    {
      "x": -53,
      "y": 2,
      "z": 6,
      "name": "Rock_Crystal_Cyan_Block"
    },
    {
      "x": -53,
      "y": 3,
      "z": 6,
      "name": "Rock_Crystal_Cyan_Block"
    },
    {
      "x": -53,
      "y": 4,
      "z": 6,
      "name": "Rock_Crystal_Cyan_Block"
    },
    {
      "x": -53,
      "y": 5,
      "z": 6,
      "name": "Rock_Crystal_Cyan_Block"
    },
    {
      "x": -53,
      "y": 6,
      "z": 6,
      "name": "Rock_Crystal_Cyan_Block"
    },
    {
      "x": -53,
      "y": 7,
      "z": 6,
      "name": "Prototype_Rock_Concrete_Brick_Half",
      "rotation": 8
    },
    {
      "x": -53,
      "y": 2,
      "z": 7,
      "name": "Rock_Chalk_Brick_Wall"
    },
    {
      "x": -53,
      "y": 3,
      "z": 7,
      "name": "Rock_Chalk_Brick_Wall"
    },
    {
      "x": -53,
      "y": 4,
      "z": 7,
      "name": "Rock_Chalk_Brick_Wall"
    },
    {
      "x": -53,
      "y": 5,
      "z": 7,
      "name": "Rock_Stone_Cobble"
    },
    {
      "x": -53,
      "y": 6,
      "z": 7,
      "name": "Rock_Shale_Brick"
    },
    {
      "x": -53,
      "y": 7,
      "z": 7,
      "name": "Prototype_Rock_Concrete_Brick"
    },
    {
      "x": -53,
      "y": 8,
      "z": 7,
      "name": "Prototype_Rock_Concrete_Brick_Stairs",
      "rotation": 3
    },
    {
      "x": -53,
      "y": 5,
      "z": 8,
      "name": "*Furniture_Crude_Trapdoor_State_Definitions_OpenDoorOut"
    },
    {
      "x": -53,
      "y": 7,
      "z": 8,
      "name": "Prototype_Rock_Concrete_Brick_Half",
      "rotation": 8
    },
    {
      "x": -52,
      "y": 2,
      "z": -6,
      "name": "Wood_Hardwood_Fence",
      "rotation": 1
    },
    {
      "x": -52,
      "y": 3,
      "z": -6,
      "name": "Wood_Hardwood_Fence",
      "rotation": 1
    },
    {
      "x": -52,
      "y": 4,
      "z": -6,
      "name": "Wood_Hardwood_Fence",
      "rotation": 1
    },
    {
      "x": -52,
      "y": 5,
      "z": -6,
      "name": "Wood_Hardwood_Fence",
      "rotation": 1
    },
    {
      "x": -52,
      "y": 6,
      "z": -6,
      "name": "Wood_Hardwood_Fence",
      "rotation": 1
    },
    {
      "x": -52,
      "y": 7,
      "z": -6,
      "name": "Wood_Hardwood_Fence",
      "rotation": 1
    },
    {
      "x": -52,
      "y": 8,
      "z": -6,
      "name": "Prototype_Rock_Concrete_Brick_Half"
    },
    {
      "x": -52,
      "y": 2,
      "z": -5,
      "name": "Rock_Stone_Brick_Mossy"
    },
    {
      "x": -52,
      "y": 3,
      "z": -5,
      "name": "Rock_Stone_Brick"
    },
    {
      "x": -52,
      "y": 4,
      "z": -5,
      "name": "Rock_Stone_Brick"
    },
    {
      "x": -52,
      "y": 5,
      "z": -5,
      "name": "Rock_Shale_Brick"
    },
    {
      "x": -52,
      "y": 6,
      "z": -5,
      "name": "Rock_Stone_Brick"
    },
    {
      "x": -52,
      "y": 7,
      "z": -5,
      "name": "Rock_Stone_Brick"
    },
    {
      "x": -52,
      "y": 8,
      "z": -5,
      "name": "Prototype_Rock_Concrete_Brick"
    },
    {
      "x": -52,
      "y": 9,
      "z": -5,
      "name": "Prototype_Rock_Concrete_Brick_Half"
    },
    {
      "x": -52,
      "y": 8,
      "z": -4,
      "name": "Prototype_Rock_Concrete_Brick_Stairs",
      "rotation": 3
    },
    {
      "x": -52,
      "y": 8,
      "z": -3,
      "name": "Rock_Shale_Brick_Half"
    },
    {
      "x": -52,
      "y": 8,
      "z": -2,
      "name": "Rock_Shale_Cobble_Half"
    },
    {
      "x": -52,
      "y": 8,
      "z": -1,
      "name": "Prototype_Rock_Concrete_Brick_Half"
    },
    {
      "x": -52,
      "y": 8,
      "z": 0,
      "name": "Rock_Shale_Brick_Half"
    },
    {
      "x": -52,
      "y": 8,
      "z": 1,
      "name": "Rock_Shale_Cobble_Half"
    },
    {
      "x": -52,
      "y": 8,
      "z": 2,
      "name": "Rock_Shale_Brick_Half"
    },
    {
      "x": -52,
      "y": 8,
      "z": 3,
      "name": "Prototype_Rock_Concrete_Brick_Half"
    },
    {
      "x": -52,
      "y": 8,
      "z": 4,
      "name": "Rock_Shale_Cobble_Half"
    },
    {
      "x": -52,
      "y": 8,
      "z": 5,
      "name": "Rock_Shale_Brick_Half"
    },
    {
      "x": -52,
      "y": 8,
      "z": 6,
      "name": "Prototype_Rock_Concrete_Brick_Stairs",
      "rotation": 3
    },
    {
      "x": -52,
      "y": 2,
      "z": 7,
      "name": "Rock_Stone_Brick"
    },
    {
      "x": -52,
      "y": 3,
      "z": 7,
      "name": "Rock_Stone_Brick"
    },
    {
      "x": -52,
      "y": 4,
      "z": 7,
      "name": "Rock_Stone_Brick"
    },
    {
      "x": -52,
      "y": 5,
      "z": 7,
      "name": "Rock_Stone_Brick_Mossy"
    },
    {
      "x": -52,
      "y": 6,
      "z": 7,
      "name": "Rock_Stone_Brick_Mossy"
    },
    {
      "x": -52,
      "y": 7,
      "z": 7,
      "name": "Rock_Stone_Brick_Mossy"
    },
    {
      "x": -52,
      "y": 8,
      "z": 7,
      "name": "Prototype_Rock_Concrete_Brick"
    },
    {
      "x": -52,
      "y": 9,
      "z": 7,
      "name": "Prototype_Rock_Concrete_Brick_Half"
    },
    {
      "x": -52,
      "y": 2,
      "z": 8,
      "name": "Wood_Hardwood_Fence",
      "rotation": 1
    },
    {
      "x": -52,
      "y": 3,
      "z": 8,
      "name": "Wood_Hardwood_Fence",
      "rotation": 1
    },
    {
      "x": -52,
      "y": 4,
      "z": 8,
      "name": "Wood_Hardwood_Fence",
      "rotation": 1
    },
    {
      "x": -52,
      "y": 5,
      "z": 8,
      "name": "Wood_Hardwood_Fence",
      "rotation": 1
    },
    {
      "x": -52,
      "y": 6,
      "z": 8,
      "name": "Wood_Hardwood_Fence",
      "rotation": 1
    },
    {
      "x": -52,
      "y": 7,
      "z": 8,
      "name": "Wood_Hardwood_Fence",
      "rotation": 1
    },
    {
      "x": -52,
      "y": 8,
      "z": 8,
      "name": "Prototype_Rock_Concrete_Brick_Half"
    },
    {
      "x": -51,
      "y": 6,
      "z": -6,
      "name": "*Furniture_Crude_Trapdoor_State_Definitions_OpenDoorOut",
      "rotation": 2
    },
    {
      "x": -51,
      "y": 8,
      "z": -6,
      "name": "Prototype_Rock_Concrete_Brick_Half",
      "rotation": 8
    },
    {
      "x": -51,
      "y": 2,
      "z": -5,
      "name": "Rock_Chalk_Brick_Wall"
    },
    {
      "x": -51,
      "y": 3,
      "z": -5,
      "name": "Rock_Chalk_Brick_Wall"
    },
    {
      "x": -51,
      "y": 4,
      "z": -5,
      "name": "Rock_Chalk_Brick_Wall"
    },
    {
      "x": -51,
      "y": 5,
      "z": -5,
      "name": "Rock_Chalk_Brick_Wall"
    },
    {
      "x": -51,
      "y": 6,
      "z": -5,
      "name": "Rock_Stone_Cobble"
    },
    {
      "x": -51,
      "y": 7,
      "z": -5,
      "name": "Rock_Stone_Brick"
    },
    {
      "x": -51,
      "y": 8,
      "z": -5,
      "name": "Prototype_Rock_Concrete_Brick"
    },
    {
      "x": -51,
      "y": 9,
      "z": -5,
      "name": "Prototype_Rock_Concrete_Brick_Stairs",
      "rotation": 3
    },
    {
      "x": -51,
      "y": 2,
      "z": -4,
      "name": "Rock_Crystal_Cyan_Block"
    },
    {
      "x": -51,
      "y": 3,
      "z": -4,
      "name": "Rock_Crystal_Cyan_Block"
    },
    {
      "x": -51,
      "y": 4,
      "z": -4,
      "name": "Rock_Crystal_Cyan_Block"
    },
    {
      "x": -51,
      "y": 5,
      "z": -4,
      "name": "Rock_Crystal_Cyan_Block"
    },
    {
      "x": -51,
      "y": 6,
      "z": -4,
      "name": "Rock_Crystal_Cyan_Block"
    },
    {
      "x": -51,
      "y": 7,
      "z": -4,
      "name": "Rock_Crystal_Cyan_Block"
    },
    {
      "x": -51,
      "y": 8,
      "z": -4,
      "name": "Rock_Crystal_Cyan_Block"
    },
    {
      "x": -51,
      "y": 9,
      "z": -4,
      "name": "Plant_Moss_Rug_Green_Dark"
    },
    {
      "x": -51,
      "y": 8,
      "z": -3,
      "name": "Rock_Shale_Brick_Half",
      "rotation": 8
    },
    {
      "x": -51,
      "y": 8,
      "z": -2,
      "name": "Rock_Shale_Cobble_Half",
      "rotation": 8
    },
    {
      "x": -51,
      "y": 8,
      "z": -1,
      "name": "Prototype_Rock_Concrete_Brick_Half",
      "rotation": 8
    },
    {
      "x": -51,
      "y": 8,
      "z": 0,
      "name": "Rock_Shale_Brick_Half",
      "rotation": 8
    },
    {
      "x": -51,
      "y": 8,
      "z": 1,
      "name": "Rock_Shale_Cobble_Half",
      "rotation": 8
    },
    {
      "x": -51,
      "y": 8,
      "z": 2,
      "name": "Rock_Shale_Brick_Half",
      "rotation": 8
    },
    {
      "x": -51,
      "y": 8,
      "z": 3,
      "name": "Prototype_Rock_Concrete_Brick_Half",
      "rotation": 8
    },
    {
      "x": -51,
      "y": 8,
      "z": 4,
      "name": "Rock_Shale_Cobble_Half",
      "rotation": 8
    },
    {
      "x": -51,
      "y": 8,
      "z": 5,
      "name": "Rock_Shale_Brick_Half",
      "rotation": 8
    },
    {
      "x": -51,
      "y": 2,
      "z": 6,
      "name": "Rock_Crystal_Cyan_Block"
    },
    {
      "x": -51,
      "y": 3,
      "z": 6,
      "name": "Rock_Crystal_Cyan_Block"
    },
    {
      "x": -51,
      "y": 4,
      "z": 6,
      "name": "Rock_Crystal_Cyan_Block"
    },
    {
      "x": -51,
      "y": 5,
      "z": 6,
      "name": "Rock_Crystal_Cyan_Block"
    },
    {
      "x": -51,
      "y": 6,
      "z": 6,
      "name": "Rock_Crystal_Cyan_Block"
    },
    {
      "x": -51,
      "y": 7,
      "z": 6,
      "name": "Rock_Crystal_Cyan_Block"
    },
    {
      "x": -51,
      "y": 8,
      "z": 6,
      "name": "Rock_Crystal_Cyan_Block"
    },
    {
      "x": -51,
      "y": 9,
      "z": 6,
      "name": "Plant_Moss_Rug_Green_Dark"
    },
    {
      "x": -51,
      "y": 2,
      "z": 7,
      "name": "Rock_Chalk_Brick_Wall"
    },
    {
      "x": -51,
      "y": 3,
      "z": 7,
      "name": "Rock_Chalk_Brick_Wall"
    },
    {
      "x": -51,
      "y": 4,
      "z": 7,
      "name": "Rock_Chalk_Brick_Wall"
    },
    {
      "x": -51,
      "y": 5,
      "z": 7,
      "name": "Rock_Chalk_Brick_Wall"
    },
    {
      "x": -51,
      "y": 6,
      "z": 7,
      "name": "Rock_Stone_Cobble"
    },
    {
      "x": -51,
      "y": 7,
      "z": 7,
      "name": "Rock_Stone_Brick"
    },
    {
      "x": -51,
      "y": 8,
      "z": 7,
      "name": "Prototype_Rock_Concrete_Brick"
    },
    {
      "x": -51,
      "y": 9,
      "z": 7,
      "name": "Prototype_Rock_Concrete_Brick_Stairs",
      "rotation": 3
    },
    {
      "x": -51,
      "y": 6,
      "z": 8,
      "name": "*Furniture_Crude_Trapdoor_State_Definitions_OpenDoorOut"
    },
    {
      "x": -51,
      "y": 8,
      "z": 8,
      "name": "Prototype_Rock_Concrete_Brick_Half",
      "rotation": 8
    },
    {
      "x": -50,
      "y": 2,
      "z": -6,
      "name": "Wood_Hardwood_Fence",
      "rotation": 1
    },
    {
      "x": -50,
      "y": 3,
      "z": -6,
      "name": "Wood_Hardwood_Fence",
      "rotation": 1
    },
    {
      "x": -50,
      "y": 4,
      "z": -6,
      "name": "Wood_Hardwood_Fence",
      "rotation": 1
    },
    {
      "x": -50,
      "y": 5,
      "z": -6,
      "name": "Wood_Hardwood_Fence",
      "rotation": 1
    },
    {
      "x": -50,
      "y": 6,
      "z": -6,
      "name": "Wood_Hardwood_Fence",
      "rotation": 1
    },
    {
      "x": -50,
      "y": 7,
      "z": -6,
      "name": "Wood_Hardwood_Fence",
      "rotation": 1
    },
    {
      "x": -50,
      "y": 8,
      "z": -6,
      "name": "Wood_Hardwood_Fence",
      "rotation": 1
    },
    {
      "x": -50,
      "y": 9,
      "z": -6,
      "name": "Prototype_Rock_Concrete_Brick_Half"
    },
    {
      "x": -50,
      "y": 2,
      "z": -5,
      "name": "Rock_Stone_Brick_Mossy"
    },
    {
      "x": -50,
      "y": 3,
      "z": -5,
      "name": "Rock_Stone_Brick"
    },
    {
      "x": -50,
      "y": 4,
      "z": -5,
      "name": "Rock_Shale_Brick"
    },
    {
      "x": -50,
      "y": 5,
      "z": -5,
      "name": "Rock_Stone_Brick"
    },
    {
      "x": -50,
      "y": 6,
      "z": -5,
      "name": "Rock_Stone_Brick"
    },
    {
      "x": -50,
      "y": 7,
      "z": -5,
      "name": "Rock_Stone_Brick_Mossy"
    },
    {
      "x": -50,
      "y": 8,
      "z": -5,
      "name": "Rock_Stone_Brick_Mossy"
    },
    {
      "x": -50,
      "y": 9,
      "z": -5,
      "name": "Prototype_Rock_Concrete_Brick"
    },
    {
      "x": -50,
      "y": 10,
      "z": -5,
      "name": "Prototype_Rock_Concrete_Brick_Half"
    },
    {
      "x": -50,
      "y": 9,
      "z": -4,
      "name": "Prototype_Rock_Concrete_Brick_Half"
    },
    {
      "x": -50,
      "y": 9,
      "z": -3,
      "name": "Rock_Shale_Brick_Half"
    },
    {
      "x": -50,
      "y": 9,
      "z": -2,
      "name": "Rock_Shale_Cobble_Half"
    },
    {
      "x": -50,
      "y": 9,
      "z": -1,
      "name": "Prototype_Rock_Concrete_Brick_Half"
    },
    {
      "x": -50,
      "y": 9,
      "z": 0,
      "name": "Rock_Shale_Brick_Half"
    },
    {
      "x": -50,
      "y": 9,
      "z": 1,
      "name": "Rock_Shale_Cobble_Stairs",
      "rotation": 3
    },
    {
      "x": -50,
      "y": 9,
      "z": 2,
      "name": "Rock_Shale_Brick_Half"
    },
    {
      "x": -50,
      "y": 9,
      "z": 3,
      "name": "Prototype_Rock_Concrete_Brick_Half"
    },
    {
      "x": -50,
      "y": 9,
      "z": 4,
      "name": "Rock_Shale_Cobble_Half"
    },
    {
      "x": -50,
      "y": 9,
      "z": 5,
      "name": "Rock_Shale_Brick_Half"
    },
    {
      "x": -50,
      "y": 9,
      "z": 6,
      "name": "Prototype_Rock_Concrete_Brick_Half"
    },
    {
      "x": -50,
      "y": 2,
      "z": 7,
      "name": "Rock_Shale_Brick"
    },
    {
      "x": -50,
      "y": 3,
      "z": 7,
      "name": "Rock_Shale_Brick"
    },
    {
      "x": -50,
      "y": 4,
      "z": 7,
      "name": "Rock_Stone_Brick"
    },
    {
      "x": -50,
      "y": 5,
      "z": 7,
      "name": "Rock_Stone_Brick"
    },
    {
      "x": -50,
      "y": 6,
      "z": 7,
      "name": "Rock_Stone_Brick_Mossy"
    },
    {
      "x": -50,
      "y": 7,
      "z": 7,
      "name": "Rock_Stone_Brick_Mossy"
    },
    {
      "x": -50,
      "y": 8,
      "z": 7,
      "name": "Rock_Stone_Brick"
    },
    {
      "x": -50,
      "y": 9,
      "z": 7,
      "name": "Prototype_Rock_Concrete_Brick"
    },
    {
      "x": -50,
      "y": 10,
      "z": 7,
      "name": "Prototype_Rock_Concrete_Brick_Half"
    },
    {
      "x": -50,
      "y": 2,
      "z": 8,
      "name": "Wood_Hardwood_Fence",
      "rotation": 1
    },
    {
      "x": -50,
      "y": 3,
      "z": 8,
      "name": "Wood_Hardwood_Fence",
      "rotation": 1
    },
    {
      "x": -50,
      "y": 4,
      "z": 8,
      "name": "Wood_Hardwood_Fence",
      "rotation": 1
    },
    {
      "x": -50,
      "y": 5,
      "z": 8,
      "name": "Wood_Hardwood_Fence",
      "rotation": 1
    },
    {
      "x": -50,
      "y": 6,
      "z": 8,
      "name": "Wood_Hardwood_Fence",
      "rotation": 1
    },
    {
      "x": -50,
      "y": 7,
      "z": 8,
      "name": "Wood_Hardwood_Fence",
      "rotation": 1
    },
    {
      "x": -50,
      "y": 8,
      "z": 8,
      "name": "Wood_Hardwood_Fence",
      "rotation": 1
    },
    {
      "x": -50,
      "y": 9,
      "z": 8,
      "name": "Prototype_Rock_Concrete_Brick_Half"
    },
    {
      "x": -49,
      "y": 7,
      "z": -6,
      "name": "*Furniture_Crude_Trapdoor_State_Definitions_OpenDoorOut",
      "rotation": 2
    },
    {
      "x": -49,
      "y": 9,
      "z": -6,
      "name": "Prototype_Rock_Concrete_Brick_Half",
      "rotation": 8
    },
    {
      "x": -49,
      "y": 2,
      "z": -5,
      "name": "Rock_Chalk_Brick_Wall"
    },
    {
      "x": -49,
      "y": 3,
      "z": -5,
      "name": "Rock_Chalk_Brick_Wall"
    },
    {
      "x": -49,
      "y": 4,
      "z": -5,
      "name": "Rock_Chalk_Brick_Wall"
    },
    {
      "x": -49,
      "y": 5,
      "z": -5,
      "name": "Rock_Chalk_Brick_Wall"
    },
    {
      "x": -49,
      "y": 6,
      "z": -5,
      "name": "Rock_Chalk_Brick_Wall"
    },
    {
      "x": -49,
      "y": 7,
      "z": -5,
      "name": "Rock_Stone_Cobble"
    },
    {
      "x": -49,
      "y": 8,
      "z": -5,
      "name": "Rock_Stone_Brick"
    },
    {
      "x": -49,
      "y": 9,
      "z": -5,
      "name": "Prototype_Rock_Concrete_Brick"
    },
    {
      "x": -49,
      "y": 10,
      "z": -5,
      "name": "Prototype_Rock_Concrete_Brick_Stairs",
      "rotation": 3
    },
    {
      "x": -49,
      "y": 2,
      "z": -4,
      "name": "Rock_Crystal_Cyan_Block"
    },
    {
      "x": -49,
      "y": 3,
      "z": -4,
      "name": "Rock_Crystal_Cyan_Block"
    },
    {
      "x": -49,
      "y": 4,
      "z": -4,
      "name": "Rock_Crystal_Cyan_Block"
    },
    {
      "x": -49,
      "y": 5,
      "z": -4,
      "name": "Rock_Crystal_Cyan_Block"
    },
    {
      "x": -49,
      "y": 6,
      "z": -4,
      "name": "Rock_Crystal_Cyan_Block"
    },
    {
      "x": -49,
      "y": 7,
      "z": -4,
      "name": "Rock_Crystal_Cyan_Block"
    },
    {
      "x": -49,
      "y": 8,
      "z": -4,
      "name": "Rock_Crystal_Cyan_Block"
    },
    {
      "x": -49,
      "y": 9,
      "z": -4,
      "name": "Prototype_Rock_Concrete_Brick_Half",
      "rotation": 8
    },
    {
      "x": -49,
      "y": 9,
      "z": -3,
      "name": "Rock_Shale_Brick_Half",
      "rotation": 8
    },
    {
      "x": -49,
      "y": 9,
      "z": -2,
      "name": "Rock_Shale_Cobble_Half",
      "rotation": 8
    },
    {
      "x": -49,
      "y": 9,
      "z": -1,
      "name": "Prototype_Rock_Concrete_Brick_Half",
      "rotation": 8
    },
    {
      "x": -49,
      "y": 9,
      "z": 0,
      "name": "Rock_Shale_Brick_Half",
      "rotation": 8
    },
    {
      "x": -49,
      "y": 9,
      "z": 1,
      "name": "Rock_Crystal_Cyan_Block"
    },
    {
      "x": -49,
      "y": 10,
      "z": 1,
      "name": "Plant_Moss_Rug_Green_Dark"
    },
    {
      "x": -49,
      "y": 9,
      "z": 2,
      "name": "Rock_Shale_Brick_Half",
      "rotation": 8
    },
    {
      "x": -49,
      "y": 9,
      "z": 3,
      "name": "Prototype_Rock_Concrete_Brick_Half",
      "rotation": 8
    },
    {
      "x": -49,
      "y": 9,
      "z": 4,
      "name": "Rock_Shale_Cobble_Half",
      "rotation": 8
    },
    {
      "x": -49,
      "y": 9,
      "z": 5,
      "name": "Rock_Shale_Brick_Half",
      "rotation": 8
    },
    {
      "x": -49,
      "y": 2,
      "z": 6,
      "name": "Rock_Crystal_Cyan_Block"
    },
    {
      "x": -49,
      "y": 3,
      "z": 6,
      "name": "Rock_Crystal_Cyan_Block"
    },
    {
      "x": -49,
      "y": 4,
      "z": 6,
      "name": "Rock_Crystal_Cyan_Block"
    },
    {
      "x": -49,
      "y": 5,
      "z": 6,
      "name": "Rock_Crystal_Cyan_Block"
    },
    {
      "x": -49,
      "y": 6,
      "z": 6,
      "name": "Rock_Crystal_Cyan_Block"
    },
    {
      "x": -49,
      "y": 7,
      "z": 6,
      "name": "Rock_Crystal_Cyan_Block"
    },
    {
      "x": -49,
      "y": 8,
      "z": 6,
      "name": "Rock_Crystal_Cyan_Block"
    },
    {
      "x": -49,
      "y": 9,
      "z": 6,
      "name": "Prototype_Rock_Concrete_Brick_Half",
      "rotation": 8
    },
    {
      "x": -49,
      "y": 2,
      "z": 7,
      "name": "Rock_Chalk_Brick_Wall"
    },
    {
      "x": -49,
      "y": 3,
      "z": 7,
      "name": "Rock_Chalk_Brick_Wall"
    },
    {
      "x": -49,
      "y": 4,
      "z": 7,
      "name": "Rock_Chalk_Brick_Wall"
    },
    {
      "x": -49,
      "y": 5,
      "z": 7,
      "name": "Rock_Chalk_Brick_Wall"
    },
    {
      "x": -49,
      "y": 6,
      "z": 7,
      "name": "Rock_Chalk_Brick_Wall"
    },
    {
      "x": -49,
      "y": 7,
      "z": 7,
      "name": "Rock_Stone_Cobble"
    },
    {
      "x": -49,
      "y": 8,
      "z": 7,
      "name": "Rock_Stone_Brick"
    },
    {
      "x": -49,
      "y": 9,
      "z": 7,
      "name": "Prototype_Rock_Concrete_Brick"
    },
    {
      "x": -49,
      "y": 10,
      "z": 7,
      "name": "Prototype_Rock_Concrete_Brick_Stairs",
      "rotation": 3
    },
    {
      "x": -49,
      "y": 7,
      "z": 8,
      "name": "*Furniture_Crude_Trapdoor_State_Definitions_OpenDoorOut"
    },
    {
      "x": -49,
      "y": 9,
      "z": 8,
      "name": "Prototype_Rock_Concrete_Brick_Half",
      "rotation": 8
    },
    {
      "x": -48,
      "y": 2,
      "z": -6,
      "name": "Wood_Hardwood_Fence",
      "rotation": 1
    },
    {
      "x": -48,
      "y": 3,
      "z": -6,
      "name": "Wood_Hardwood_Fence",
      "rotation": 1
    },
    {
      "x": -48,
      "y": 4,
      "z": -6,
      "name": "Wood_Hardwood_Fence",
      "rotation": 1
    },
    {
      "x": -48,
      "y": 5,
      "z": -6,
      "name": "Wood_Hardwood_Fence",
      "rotation": 1
    },
    {
      "x": -48,
      "y": 6,
      "z": -6,
      "name": "Wood_Hardwood_Fence",
      "rotation": 1
    },
    {
      "x": -48,
      "y": 7,
      "z": -6,
      "name": "Wood_Hardwood_Fence",
      "rotation": 1
    },
    {
      "x": -48,
      "y": 8,
      "z": -6,
      "name": "Wood_Hardwood_Fence",
      "rotation": 1
    },
    {
      "x": -48,
      "y": 9,
      "z": -6,
      "name": "Wood_Hardwood_Fence",
      "rotation": 1
    },
    {
      "x": -48,
      "y": 10,
      "z": -6,
      "name": "Prototype_Rock_Concrete_Brick_Half"
    },
    {
      "x": -48,
      "y": 2,
      "z": -5,
      "name": "Rock_Stone_Brick"
    },
    {
      "x": -48,
      "y": 3,
      "z": -5,
      "name": "Rock_Stone_Brick"
    },
    {
      "x": -48,
      "y": 4,
      "z": -5,
      "name": "Rock_Stone_Brick"
    },
    {
      "x": -48,
      "y": 5,
      "z": -5,
      "name": "Rock_Stone_Brick"
    },
    {
      "x": -48,
      "y": 6,
      "z": -5,
      "name": "Rock_Stone_Brick"
    },
    {
      "x": -48,
      "y": 7,
      "z": -5,
      "name": "Rock_Stone_Brick"
    },
    {
      "x": -48,
      "y": 8,
      "z": -5,
      "name": "Rock_Shale_Brick"
    },
    {
      "x": -48,
      "y": 9,
      "z": -5,
      "name": "Rock_Stone_Brick"
    },
    {
      "x": -48,
      "y": 10,
      "z": -5,
      "name": "Prototype_Rock_Concrete_Brick"
    },
    {
      "x": -48,
      "y": 11,
      "z": -5,
      "name": "Prototype_Rock_Concrete_Brick_Half"
    },
    {
      "x": -48,
      "y": 10,
      "z": -4,
      "name": "Prototype_Rock_Concrete_Brick_Half"
    },
    {
      "x": -48,
      "y": 10,
      "z": -3,
      "name": "Prototype_Rock_Concrete_Brick_Stairs",
      "rotation": 3
    },
    {
      "x": -48,
      "y": 10,
      "z": -2,
      "name": "Rock_Shale_Brick_Half"
    },
    {
      "x": -48,
      "y": 10,
      "z": -1,
      "name": "Rock_Shale_Cobble_Half"
    },
    {
      "x": -48,
      "y": 10,
      "z": 0,
      "name": "Prototype_Rock_Concrete_Brick_Half"
    },
    {
      "x": -48,
      "y": 10,
      "z": 1,
      "name": "Rock_Shale_Brick_Half"
    },
    {
      "x": -48,
      "y": 10,
      "z": 2,
      "name": "Prototype_Rock_Concrete_Brick_Half"
    },
    {
      "x": -48,
      "y": 10,
      "z": 3,
      "name": "Rock_Shale_Cobble_Half"
    },
    {
      "x": -48,
      "y": 10,
      "z": 4,
      "name": "Rock_Shale_Brick_Half"
    },
    {
      "x": -48,
      "y": 10,
      "z": 5,
      "name": "Prototype_Rock_Concrete_Brick_Stairs",
      "rotation": 3
    },
    {
      "x": -48,
      "y": 10,
      "z": 6,
      "name": "Prototype_Rock_Concrete_Brick_Half"
    },
    {
      "x": -48,
      "y": 2,
      "z": 7,
      "name": "Rock_Stone_Brick"
    },
    {
      "x": -48,
      "y": 3,
      "z": 7,
      "name": "Rock_Stone_Brick"
    },
    {
      "x": -48,
      "y": 4,
      "z": 7,
      "name": "Rock_Stone_Brick"
    },
    {
      "x": -48,
      "y": 5,
      "z": 7,
      "name": "Rock_Stone_Brick"
    },
    {
      "x": -48,
      "y": 6,
      "z": 7,
      "name": "Rock_Stone_Brick"
    },
    {
      "x": -48,
      "y": 7,
      "z": 7,
      "name": "Rock_Shale_Brick"
    },
    {
      "x": -48,
      "y": 8,
      "z": 7,
      "name": "Rock_Shale_Brick"
    },
    {
      "x": -48,
      "y": 9,
      "z": 7,
      "name": "Rock_Stone_Brick"
    },
    {
      "x": -48,
      "y": 10,
      "z": 7,
      "name": "Prototype_Rock_Concrete_Brick"
    },
    {
      "x": -48,
      "y": 11,
      "z": 7,
      "name": "Prototype_Rock_Concrete_Brick_Half"
    },
    {
      "x": -48,
      "y": 2,
      "z": 8,
      "name": "Wood_Hardwood_Fence",
      "rotation": 1
    },
    {
      "x": -48,
      "y": 3,
      "z": 8,
      "name": "Wood_Hardwood_Fence",
      "rotation": 1
    },
    {
      "x": -48,
      "y": 4,
      "z": 8,
      "name": "Wood_Hardwood_Fence",
      "rotation": 1
    },
    {
      "x": -48,
      "y": 5,
      "z": 8,
      "name": "Wood_Hardwood_Fence",
      "rotation": 1
    },
    {
      "x": -48,
      "y": 6,
      "z": 8,
      "name": "Wood_Hardwood_Fence",
      "rotation": 1
    },
    {
      "x": -48,
      "y": 7,
      "z": 8,
      "name": "Wood_Hardwood_Fence",
      "rotation": 1
    },
    {
      "x": -48,
      "y": 8,
      "z": 8,
      "name": "Wood_Hardwood_Fence",
      "rotation": 1
    },
    {
      "x": -48,
      "y": 9,
      "z": 8,
      "name": "Wood_Hardwood_Fence",
      "rotation": 1
    },
    {
      "x": -48,
      "y": 10,
      "z": 8,
      "name": "Prototype_Rock_Concrete_Brick_Half"
    },
    {
      "x": -48,
      "y": 2,
      "z": 14,
      "name": "Rock_Stone_Brick_Mossy"
    },
    {
      "x": -48,
      "y": 2,
      "z": 16,
      "name": "Rock_Stone_Brick"
    },
    {
      "x": -47,
      "y": 2,
      "z": -13,
      "name": "Rock_Stone_Brick"
    },
    {
      "x": -47,
      "y": 2,
      "z": -12,
      "name": "Plant_Moss_Rug_Green_Dark"
    },
    {
      "x": -47,
      "y": 2,
      "z": -9,
      "name": "Rock_Shale_Brick"
    },
    {
      "x": -47,
      "y": 4,
      "z": -8,
      "name": "Rock_Shale_Brick"
    },
    {
      "x": -47,
      "y": 2,
      "z": -7,
      "name": "Rock_Stone_Brick"
    },
    {
      "x": -47,
      "y": 8,
      "z": -6,
      "name": "*Furniture_Crude_Trapdoor_State_Definitions_OpenDoorOut",
      "rotation": 2
    },
    {
      "x": -47,
      "y": 10,
      "z": -6,
      "name": "Prototype_Rock_Concrete_Brick_Half",
      "rotation": 8
    },
    {
      "x": -47,
      "y": 2,
      "z": -5,
      "name": "Rock_Chalk_Brick_Wall"
    },
    {
      "x": -47,
      "y": 3,
      "z": -5,
      "name": "Rock_Chalk_Brick_Wall"
    },
    {
      "x": -47,
      "y": 4,
      "z": -5,
      "name": "Rock_Chalk_Brick_Wall"
    },
    {
      "x": -47,
      "y": 5,
      "z": -5,
      "name": "Rock_Chalk_Brick_Wall"
    },
    {
      "x": -47,
      "y": 6,
      "z": -5,
      "name": "Rock_Chalk_Brick_Wall"
    },
    {
      "x": -47,
      "y": 7,
      "z": -5,
      "name": "Rock_Chalk_Brick_Wall"
    },
    {
      "x": -47,
      "y": 8,
      "z": -5,
      "name": "Rock_Stone_Cobble"
    },
    {
      "x": -47,
      "y": 9,
      "z": -5,
      "name": "Rock_Shale_Brick"
    },
    {
      "x": -47,
      "y": 10,
      "z": -5,
      "name": "Prototype_Rock_Concrete_Brick"
    },
    {
      "x": -47,
      "y": 11,
      "z": -5,
      "name": "Prototype_Rock_Concrete_Brick_Stairs",
      "rotation": 3
    },
    {
      "x": -47,
      "y": 2,
      "z": -4,
      "name": "Rock_Crystal_Cyan_Block"
    },
    {
      "x": -47,
      "y": 3,
      "z": -4,
      "name": "Rock_Crystal_Cyan_Block"
    },
    {
      "x": -47,
      "y": 4,
      "z": -4,
      "name": "Rock_Crystal_Cyan_Block"
    },
    {
      "x": -47,
      "y": 5,
      "z": -4,
      "name": "Rock_Crystal_Cyan_Block"
    },
    {
      "x": -47,
      "y": 6,
      "z": -4,
      "name": "Rock_Crystal_Cyan_Block"
    },
    {
      "x": -47,
      "y": 7,
      "z": -4,
      "name": "Rock_Crystal_Cyan_Block"
    },
    {
      "x": -47,
      "y": 8,
      "z": -4,
      "name": "Rock_Crystal_Cyan_Block"
    },
    {
      "x": -47,
      "y": 9,
      "z": -4,
      "name": "Rock_Crystal_Cyan_Block"
    },
    {
      "x": -47,
      "y": 10,
      "z": -4,
      "name": "Prototype_Rock_Concrete_Brick_Half",
      "rotation": 8
    },
    {
      "x": -47,
      "y": 10,
      "z": -3,
      "name": "Rock_Crystal_Cyan_Block"
    },
    {
      "x": -47,
      "y": 11,
      "z": -3,
      "name": "Plant_Moss_Rug_Green_Dark"
    },
    {
      "x": -47,
      "y": 10,
      "z": -2,
      "name": "Rock_Shale_Brick_Half",
      "rotation": 8
    },
    {
      "x": -47,
      "y": 10,
      "z": -1,
      "name": "Rock_Shale_Cobble_Half",
      "rotation": 8
    },
    {
      "x": -47,
      "y": 10,
      "z": 0,
      "name": "Prototype_Rock_Concrete_Brick_Half",
      "rotation": 8
    },
    {
      "x": -47,
      "y": 10,
      "z": 1,
      "name": "Rock_Shale_Brick_Half",
      "rotation": 8
    },
    {
      "x": -47,
      "y": 10,
      "z": 2,
      "name": "Prototype_Rock_Concrete_Brick_Half",
      "rotation": 8
    },
    {
      "x": -47,
      "y": 10,
      "z": 3,
      "name": "Rock_Shale_Cobble_Half",
      "rotation": 8
    },
    {
      "x": -47,
      "y": 10,
      "z": 4,
      "name": "Rock_Shale_Brick_Half",
      "rotation": 8
    },
    {
      "x": -47,
      "y": 10,
      "z": 5,
      "name": "Rock_Crystal_Cyan_Block"
    },
    {
      "x": -47,
      "y": 11,
      "z": 5,
      "name": "Plant_Moss_Rug_Green_Dark"
    },
    {
      "x": -47,
      "y": 2,
      "z": 6,
      "name": "Rock_Crystal_Cyan_Block"
    },
    {
      "x": -47,
      "y": 3,
      "z": 6,
      "name": "Rock_Crystal_Cyan_Block"
    },
    {
      "x": -47,
      "y": 4,
      "z": 6,
      "name": "Rock_Crystal_Cyan_Block"
    },
    {
      "x": -47,
      "y": 5,
      "z": 6,
      "name": "Rock_Crystal_Cyan_Block"
    },
    {
      "x": -47,
      "y": 6,
      "z": 6,
      "name": "Rock_Crystal_Cyan_Block"
    },
    {
      "x": -47,
      "y": 7,
      "z": 6,
      "name": "Rock_Crystal_Cyan_Block"
    },
    {
      "x": -47,
      "y": 8,
      "z": 6,
      "name": "Rock_Crystal_Cyan_Block"
    },
    {
      "x": -47,
      "y": 9,
      "z": 6,
      "name": "Rock_Crystal_Cyan_Block"
    },
    {
      "x": -47,
      "y": 10,
      "z": 6,
      "name": "Prototype_Rock_Concrete_Brick_Half",
      "rotation": 8
    },
    {
      "x": -47,
      "y": 2,
      "z": 7,
      "name": "Rock_Chalk_Brick_Wall"
    },
    {
      "x": -47,
      "y": 3,
      "z": 7,
      "name": "Rock_Chalk_Brick_Wall"
    },
    {
      "x": -47,
      "y": 4,
      "z": 7,
      "name": "Rock_Chalk_Brick_Wall"
    },
    {
      "x": -47,
      "y": 5,
      "z": 7,
      "name": "Rock_Chalk_Brick_Wall"
    },
    {
      "x": -47,
      "y": 6,
      "z": 7,
      "name": "Rock_Chalk_Brick_Wall"
    },
    {
      "x": -47,
      "y": 7,
      "z": 7,
      "name": "Rock_Chalk_Brick_Wall"
    },
    {
      "x": -47,
      "y": 8,
      "z": 7,
      "name": "Rock_Stone_Cobble"
    },
    {
      "x": -47,
      "y": 9,
      "z": 7,
      "name": "Rock_Shale_Brick"
    },
    {
      "x": -47,
      "y": 10,
      "z": 7,
      "name": "Prototype_Rock_Concrete_Brick"
    },
    {
      "x": -47,
      "y": 11,
      "z": 7,
      "name": "Prototype_Rock_Concrete_Brick_Stairs",
      "rotation": 3
    },
    {
      "x": -47,
      "y": 8,
      "z": 8,
      "name": "*Furniture_Crude_Trapdoor_State_Definitions_OpenDoorOut"
    },
    {
      "x": -47,
      "y": 10,
      "z": 8,
      "name": "Prototype_Rock_Concrete_Brick_Half",
      "rotation": 8
    },
    {
      "x": -47,
      "y": 2,
      "z": 11,
      "name": "Rock_Stone_Brick"
    },
    {
      "x": -47,
      "y": 2,
      "z": 13,
      "name": "Rock_Shale_Brick"
    },
    {
      "x": -47,
      "y": 2,
      "z": 15,
      "name": "Rock_Shale_Brick"
    },
    {
      "x": -47,
      "y": 2,
      "z": 16,
      "name": "Plant_Moss_Rug_Green_Dark"
    },
    {
      "x": -46,
      "y": 2,
      "z": -14,
      "name": "Rock_Stone_Brick"
    },
    {
      "x": -46,
      "y": 2,
      "z": -13,
      "name": "Rock_Shale_Brick"
    },
    {
      "x": -46,
      "y": 3,
      "z": -13,
      "name": "Rock_Stone_Brick_Mossy"
    },
    {
      "x": -46,
      "y": 2,
      "z": -12,
      "name": "Rock_Stone_Brick_Mossy"
    },
    {
      "x": -46,
      "y": 3,
      "z": -12,
      "name": "Rock_Shale_Brick"
    },
    {
      "x": -46,
      "y": 2,
      "z": -11,
      "name": "Rock_Stone_Brick"
    },
    {
      "x": -46,
      "y": 3,
      "z": -11,
      "name": "Rock_Stone_Brick"
    },
    {
      "x": -46,
      "y": 2,
      "z": -10,
      "name": "Rock_Stone_Brick"
    },
    {
      "x": -46,
      "y": 2,
      "z": -9,
      "name": "Rock_Shale_Brick"
    },
    {
      "x": -46,
      "y": 3,
      "z": -9,
      "name": "Rock_Stone_Brick"
    },
    {
      "x": -46,
      "y": 2,
      "z": -8,
      "name": "Rock_Shale_Brick"
    },
    {
      "x": -46,
      "y": 3,
      "z": -8,
      "name": "Rock_Stone_Brick"
    },
    {
      "x": -46,
      "y": 4,
      "z": -8,
      "name": "Rock_Stone_Brick"
    },
    {
      "x": -46,
      "y": 2,
      "z": -7,
      "name": "Rock_Stone_Brick"
    },
    {
      "x": -46,
      "y": 3,
      "z": -7,
      "name": "Rock_Shale_Brick"
    },
    {
      "x": -46,
      "y": 4,
      "z": -7,
      "name": "Rock_Stone_Brick"
    },
    {
      "x": -46,
      "y": 2,
      "z": -6,
      "name": "Wood_Hardwood_Fence"
    },
    {
      "x": -46,
      "y": 3,
      "z": -6,
      "name": "Wood_Hardwood_Fence"
    },
    {
      "x": -46,
      "y": 4,
      "z": -6,
      "name": "Wood_Hardwood_Fence"
    },
    {
      "x": -46,
      "y": 5,
      "z": -6,
      "name": "*Wood_Hardwood_Fence_State_Definitions_Corner",
      "rotation": 1
    },
    {
      "x": -46,
      "y": 6,
      "z": -6,
      "name": "*Wood_Hardwood_Fence_State_Definitions_Corner",
      "rotation": 1
    },
    {
      "x": -46,
      "y": 7,
      "z": -6,
      "name": "*Wood_Hardwood_Fence_State_Definitions_Corner",
      "rotation": 1
    },
    {
      "x": -46,
      "y": 8,
      "z": -6,
      "name": "*Wood_Hardwood_Fence_State_Definitions_Corner",
      "rotation": 1
    },
    {
      "x": -46,
      "y": 9,
      "z": -6,
      "name": "*Wood_Hardwood_Fence_State_Definitions_Corner",
      "rotation": 1
    },
    {
      "x": -46,
      "y": 10,
      "z": -6,
      "name": "*Wood_Hardwood_Fence_State_Definitions_Corner",
      "rotation": 1
    },
    {
      "x": -46,
      "y": 11,
      "z": -6,
      "name": "Prototype_Rock_Concrete_Brick_Half"
    },
    {
      "x": -46,
      "y": 2,
      "z": -5,
      "name": "Rock_Stone_Brick"
    },
    {
      "x": -46,
      "y": 3,
      "z": -5,
      "name": "Rock_Stone_Brick"
    },
    {
      "x": -46,
      "y": 4,
      "z": -5,
      "name": "Rock_Shale_Brick"
    },
    {
      "x": -46,
      "y": 5,
      "z": -5,
      "name": "Rock_Stone_Brick"
    },
    {
      "x": -46,
      "y": 6,
      "z": -5,
      "name": "Rock_Stone_Brick_Mossy"
    },
    {
      "x": -46,
      "y": 7,
      "z": -5,
      "name": "Rock_Stone_Brick"
    },
    {
      "x": -46,
      "y": 8,
      "z": -5,
      "name": "Rock_Stone_Brick"
    },
    {
      "x": -46,
      "y": 9,
      "z": -5,
      "name": "Rock_Shale_Brick"
    },
    {
      "x": -46,
      "y": 10,
      "z": -5,
      "name": "Rock_Stone_Brick"
    },
    {
      "x": -46,
      "y": 11,
      "z": -5,
      "name": "Prototype_Rock_Concrete_Brick"
    },
    {
      "x": -46,
      "y": 11,
      "z": -4,
      "name": "Prototype_Rock_Concrete_Brick_Half"
    },
    {
      "x": -46,
      "y": 11,
      "z": -3,
      "name": "Prototype_Rock_Concrete_Brick_Half"
    },
    {
      "x": -46,
      "y": 11,
      "z": -2,
      "name": "Prototype_Rock_Concrete_Brick_Half"
    },
    {
      "x": -46,
      "y": 11,
      "z": -1,
      "name": "Rock_Shale_Brick_Half"
    },
    {
      "x": -46,
      "y": 11,
      "z": 0,
      "name": "Rock_Shale_Cobble_Half"
    },
    {
      "x": -46,
      "y": 11,
      "z": 1,
      "name": "Prototype_Rock_Concrete_Brick_Half"
    },
    {
      "x": -46,
      "y": 11,
      "z": 2,
      "name": "Rock_Shale_Cobble_Half"
    },
    {
      "x": -46,
      "y": 11,
      "z": 3,
      "name": "Rock_Shale_Brick_Half"
    },
    {
      "x": -46,
      "y": 11,
      "z": 4,
      "name": "Prototype_Rock_Concrete_Brick_Half"
    },
    {
      "x": -46,
      "y": 11,
      "z": 5,
      "name": "Prototype_Rock_Concrete_Brick_Half"
    },
    {
      "x": -46,
      "y": 11,
      "z": 6,
      "name": "Prototype_Rock_Concrete_Brick_Half"
    },
    {
      "x": -46,
      "y": 2,
      "z": 7,
      "name": "Rock_Stone_Brick_Mossy"
    },
    {
      "x": -46,
      "y": 3,
      "z": 7,
      "name": "Rock_Stone_Brick"
    },
    {
      "x": -46,
      "y": 4,
      "z": 7,
      "name": "Rock_Stone_Brick_Mossy"
    },
    {
      "x": -46,
      "y": 5,
      "z": 7,
      "name": "Rock_Stone_Brick_Mossy"
    },
    {
      "x": -46,
      "y": 6,
      "z": 7,
      "name": "Rock_Shale_Brick"
    },
    {
      "x": -46,
      "y": 7,
      "z": 7,
      "name": "Rock_Stone_Brick"
    },
    {
      "x": -46,
      "y": 8,
      "z": 7,
      "name": "Rock_Stone_Brick"
    },
    {
      "x": -46,
      "y": 9,
      "z": 7,
      "name": "Rock_Stone_Brick"
    },
    {
      "x": -46,
      "y": 10,
      "z": 7,
      "name": "Rock_Stone_Brick"
    },
    {
      "x": -46,
      "y": 11,
      "z": 7,
      "name": "Prototype_Rock_Concrete_Brick"
    },
    {
      "x": -46,
      "y": 2,
      "z": 8,
      "name": "Wood_Hardwood_Fence"
    },
    {
      "x": -46,
      "y": 3,
      "z": 8,
      "name": "*Wood_Hardwood_Fence_State_Definitions_Corner",
      "rotation": 2
    },
    {
      "x": -46,
      "y": 4,
      "z": 8,
      "name": "*Wood_Hardwood_Fence_State_Definitions_Corner",
      "rotation": 2
    },
    {
      "x": -46,
      "y": 5,
      "z": 8,
      "name": "*Wood_Hardwood_Fence_State_Definitions_Corner",
      "rotation": 2
    },
    {
      "x": -46,
      "y": 6,
      "z": 8,
      "name": "*Wood_Hardwood_Fence_State_Definitions_Corner",
      "rotation": 2
    },
    {
      "x": -46,
      "y": 7,
      "z": 8,
      "name": "*Wood_Hardwood_Fence_State_Definitions_Corner",
      "rotation": 2
    },
    {
      "x": -46,
      "y": 8,
      "z": 8,
      "name": "*Wood_Hardwood_Fence_State_Definitions_Corner",
      "rotation": 2
    },
    {
      "x": -46,
      "y": 9,
      "z": 8,
      "name": "*Wood_Hardwood_Fence_State_Definitions_Corner",
      "rotation": 2
    },
    {
      "x": -46,
      "y": 10,
      "z": 8,
      "name": "*Wood_Hardwood_Fence_State_Definitions_Corner",
      "rotation": 2
    },
    {
      "x": -46,
      "y": 11,
      "z": 8,
      "name": "Prototype_Rock_Concrete_Brick_Half"
    },
    {
      "x": -46,
      "y": 2,
      "z": 9,
      "name": "Rock_Shale_Brick"
    },
    {
      "x": -46,
      "y": 2,
      "z": 10,
      "name": "Rock_Stone_Brick"
    },
    {
      "x": -46,
      "y": 4,
      "z": 10,
      "name": "Rock_Stone_Brick"
    },
    {
      "x": -46,
      "y": 2,
      "z": 11,
      "name": "Rock_Stone_Brick"
    },
    {
      "x": -46,
      "y": 3,
      "z": 11,
      "name": "Rock_Stone_Brick"
    },
    {
      "x": -46,
      "y": 2,
      "z": 12,
      "name": "Rock_Stone_Brick"
    },
    {
      "x": -46,
      "y": 3,
      "z": 12,
      "name": "Rock_Stone_Brick"
    },
    {
      "x": -46,
      "y": 2,
      "z": 13,
      "name": "Rock_Stone_Brick"
    },
    {
      "x": -46,
      "y": 2,
      "z": 14,
      "name": "Rock_Stone_Brick_Mossy"
    },
    {
      "x": -46,
      "y": 3,
      "z": 15,
      "name": "Rock_Shale_Brick"
    },
    {
      "x": -46,
      "y": 57,
      "z": 15,
      "name": "Rock_Crystal_White_Block"
    },
    {
      "x": -46,
      "y": 58,
      "z": 15,
      "name": "Plant_Coral_Block_White"
    },
    {
      "x": -46,
      "y": 2,
      "z": 16,
      "name": "Rock_Stone_Brick"
    },
    {
      "x": -46,
      "y": 3,
      "z": 16,
      "name": "Rock_Stone_Brick"
    },
    {
      "x": -46,
      "y": 2,
      "z": 17,
      "name": "Rock_Stone_Brick"
    },
    {
      "x": -46,
      "y": 2,
      "z": 18,
      "name": "Rock_Stone_Brick"
    },
    {
      "x": -46,
      "y": 3,
      "z": 18,
      "name": "Rock_Stone_Brick_Mossy"
    },
    {
      "x": -46,
      "y": 2,
      "z": 20,
      "name": "Rock_Stone_Brick"
    },
    {
      "x": -45,
      "y": 2,
      "z": -14,
      "name": "Rock_Stone_Brick_Mossy"
    },
    {
      "x": -45,
      "y": 3,
      "z": -14,
      "name": "Rock_Shale_Brick"
    },
    {
      "x": -45,
      "y": 2,
      "z": -13,
      "name": "Rock_Stone_Brick"
    },
    {
      "x": -45,
      "y": 3,
      "z": -13,
      "name": "Rock_Stone_Brick"
    },
    {
      "x": -45,
      "y": 4,
      "z": -13,
      "name": "Rock_Stone_Brick_Mossy"
    },
    {
      "x": -45,
      "y": 5,
      "z": -13,
      "name": "Rock_Stone_Brick"
    },
    {
      "x": -45,
      "y": 2,
      "z": -12,
      "name": "Rock_Stone_Brick"
    },
    {
      "x": -45,
      "y": 3,
      "z": -12,
      "name": "Rock_Stone_Brick"
    },
    {
      "x": -45,
      "y": 4,
      "z": -12,
      "name": "Rock_Shale_Brick"
    },
    {
      "x": -45,
      "y": 2,
      "z": -11,
      "name": "Rock_Stone_Brick_Mossy"
    },
    {
      "x": -45,
      "y": 3,
      "z": -11,
      "name": "Rock_Stone_Brick_Mossy"
    },
    {
      "x": -45,
      "y": 4,
      "z": -11,
      "name": "Rock_Stone_Brick"
    },
    {
      "x": -45,
      "y": 6,
      "z": -11,
      "name": "Rock_Stone_Brick_Mossy"
    },
    {
      "x": -45,
      "y": 11,
      "z": -11,
      "name": "Prototype_Rock_Concrete_Brick_Half"
    },
    {
      "x": -45,
      "y": 2,
      "z": -10,
      "name": "Rock_Stone_Brick_Mossy"
    },
    {
      "x": -45,
      "y": 3,
      "z": -10,
      "name": "Rock_Stone_Brick"
    },
    {
      "x": -45,
      "y": 4,
      "z": -10,
      "name": "Rock_Shale_Brick"
    },
    {
      "x": -45,
      "y": 11,
      "z": -10,
      "name": "Prototype_Rock_Concrete_Brick_Half"
    },
    {
      "x": -45,
      "y": 2,
      "z": -9,
      "name": "Rock_Stone_Brick"
    },
    {
      "x": -45,
      "y": 3,
      "z": -9,
      "name": "Rock_Stone_Brick"
    },
    {
      "x": -45,
      "y": 4,
      "z": -9,
      "name": "Rock_Stone_Brick"
    },
    {
      "x": -45,
      "y": 5,
      "z": -9,
      "name": "Rock_Stone_Brick"
    },
    {
      "x": -45,
      "y": 11,
      "z": -9,
      "name": "Prototype_Rock_Concrete_Brick_Half"
    },
    {
      "x": -45,
      "y": 2,
      "z": -8,
      "name": "Rock_Stone_Brick_Mossy"
    },
    {
      "x": -45,
      "y": 4,
      "z": -8,
      "name": "Rock_Crystal_Cyan_Block"
    },
    {
      "x": -45,
      "y": 5,
      "z": -8,
      "name": "Plant_Moss_Rug_Green_Dark"
    },
    {
      "x": -45,
      "y": 11,
      "z": -8,
      "name": "Prototype_Rock_Concrete_Brick_Half"
    },
    {
      "x": -45,
      "y": 3,
      "z": -7,
      "name": "Rock_Stone_Brick"
    },
    {
      "x": -45,
      "y": 5,
      "z": -7,
      "name": "Rock_Stone_Brick"
    },
    {
      "x": -45,
      "y": 6,
      "z": -7,
      "name": "Rock_Shale_Brick"
    },
    {
      "x": -45,
      "y": 11,
      "z": -7,
      "name": "Prototype_Rock_Concrete_Brick_Half"
    },
    {
      "x": -45,
      "y": 2,
      "z": -6,
      "name": "Rock_Stone_Brick_Mossy"
    },
    {
      "x": -45,
      "y": 3,
      "z": -6,
      "name": "Rock_Stone_Brick_Mossy"
    },
    {
      "x": -45,
      "y": 4,
      "z": -6,
      "name": "Rock_Stone_Brick"
    },
    {
      "x": -45,
      "y": 5,
      "z": -6,
      "name": "Rock_Stone_Brick_Mossy"
    },
    {
      "x": -45,
      "y": 6,
      "z": -6,
      "name": "Rock_Stone_Brick_Mossy"
    },
    {
      "x": -45,
      "y": 7,
      "z": -6,
      "name": "Rock_Shale_Brick"
    },
    {
      "x": -45,
      "y": 8,
      "z": -6,
      "name": "Rock_Stone_Brick_Mossy"
    },
    {
      "x": -45,
      "y": 9,
      "z": -6,
      "name": "Rock_Stone_Brick"
    },
    {
      "x": -45,
      "y": 10,
      "z": -6,
      "name": "Rock_Stone_Brick"
    },
    {
      "x": -45,
      "y": 11,
      "z": -6,
      "name": "Prototype_Rock_Concrete_Brick"
    },
    {
      "x": -45,
      "y": 2,
      "z": -5,
      "name": "Rock_Stone_Brick_Mossy"
    },
    {
      "x": -45,
      "y": 3,
      "z": -5,
      "name": "Rock_Stone_Brick_Mossy"
    },
    {
      "x": -45,
      "y": 4,
      "z": -5,
      "name": "Rock_Shale_Brick"
    },
    {
      "x": -45,
      "y": 5,
      "z": -5,
      "name": "Rock_Stone_Brick"
    },
    {
      "x": -45,
      "y": 6,
      "z": -5,
      "name": "Rock_Stone_Brick_Mossy"
    },
    {
      "x": -45,
      "y": 7,
      "z": -5,
      "name": "Rock_Stone_Brick"
    },
    {
      "x": -45,
      "y": 8,
      "z": -5,
      "name": "Rock_Stone_Brick_Mossy"
    },
    {
      "x": -45,
      "y": 9,
      "z": -5,
      "name": "Rock_Stone_Brick"
    },
    {
      "x": -45,
      "y": 10,
      "z": -5,
      "name": "Rock_Stone_Brick_Mossy"
    },
    {
      "x": -45,
      "y": 11,
      "z": -5,
      "name": "Prototype_Rock_Concrete_Brick"
    },
    {
      "x": -45,
      "y": 2,
      "z": -4,
      "name": "Rock_Stone_Brick_Mossy"
    },
    {
      "x": -45,
      "y": 3,
      "z": -4,
      "name": "Rock_Shale_Brick"
    },
    {
      "x": -45,
      "y": 4,
      "z": -4,
      "name": "Rock_Stone_Brick_Mossy"
    },
    {
      "x": -45,
      "y": 5,
      "z": -4,
      "name": "Rock_Stone_Brick"
    },
    {
      "x": -45,
      "y": 6,
      "z": -4,
      "name": "Rock_Shale_Brick"
    },
    {
      "x": -45,
      "y": 7,
      "z": -4,
      "name": "Rock_Shale_Brick"
    },
    {
      "x": -45,
      "y": 8,
      "z": -4,
      "name": "Rock_Stone_Brick_Mossy"
    },
    {
      "x": -45,
      "y": 9,
      "z": -4,
      "name": "Rock_Stone_Brick"
    },
    {
      "x": -45,
      "y": 10,
      "z": -4,
      "name": "Rock_Stone_Brick"
    },
    {
      "x": -45,
      "y": 11,
      "z": -4,
      "name": "Prototype_Rock_Concrete_Brick"
    },
    {
      "x": -45,
      "y": 2,
      "z": -3,
      "name": "Rock_Stone_Brick"
    },
    {
      "x": -45,
      "y": 3,
      "z": -3,
      "name": "Rock_Stone_Brick_Mossy"
    },
    {
      "x": -45,
      "y": 4,
      "z": -3,
      "name": "Rock_Stone_Brick"
    },
    {
      "x": -45,
      "y": 5,
      "z": -3,
      "name": "Rock_Stone_Brick"
    },
    {
      "x": -45,
      "y": 6,
      "z": -3,
      "name": "Rock_Shale_Brick"
    },
    {
      "x": -45,
      "y": 7,
      "z": -3,
      "name": "Rock_Stone_Brick"
    },
    {
      "x": -45,
      "y": 8,
      "z": -3,
      "name": "Rock_Stone_Brick"
    },
    {
      "x": -45,
      "y": 9,
      "z": -3,
      "name": "Rock_Shale_Brick"
    },
    {
      "x": -45,
      "y": 10,
      "z": -3,
      "name": "Rock_Stone_Brick"
    },
    {
      "x": -45,
      "y": 11,
      "z": -3,
      "name": "Rock_Shale_Brick_Half"
    },
    {
      "x": -45,
      "y": 2,
      "z": -2,
      "name": "Rock_Stone_Brick_Mossy"
    },
    {
      "x": -45,
      "y": 3,
      "z": -2,
      "name": "Rock_Stone_Brick_Mossy"
    },
    {
      "x": -45,
      "y": 4,
      "z": -2,
      "name": "Rock_Stone_Brick"
    },
    {
      "x": -45,
      "y": 5,
      "z": -2,
      "name": "Rock_Shale_Brick"
    },
    {
      "x": -45,
      "y": 6,
      "z": -2,
      "name": "Rock_Shale_Brick"
    },
    {
      "x": -45,
      "y": 7,
      "z": -2,
      "name": "Rock_Stone_Brick"
    },
    {
      "x": -45,
      "y": 8,
      "z": -2,
      "name": "Rock_Stone_Brick_Mossy"
    },
    {
      "x": -45,
      "y": 9,
      "z": -2,
      "name": "Rock_Stone_Brick"
    },
    {
      "x": -45,
      "y": 10,
      "z": -2,
      "name": "Rock_Shale_Brick"
    },
    {
      "x": -45,
      "y": 11,
      "z": -2,
      "name": "Rock_Shale_Brick_Half"
    },
    {
      "x": -45,
      "y": 2,
      "z": -1,
      "name": "Rock_Stone_Brick_Mossy"
    },
    {
      "x": -45,
      "y": 3,
      "z": -1,
      "name": "Rock_Shale_Brick"
    },
    {
      "x": -45,
      "y": 4,
      "z": -1,
      "name": "Rock_Stone_Brick_Mossy"
    },
    {
      "x": -45,
      "y": 5,
      "z": -1,
      "name": "Rock_Stone_Brick"
    },
    {
      "x": -45,
      "y": 6,
      "z": -1,
      "name": "Rock_Stone_Brick_Mossy"
    },
    {
      "x": -45,
      "y": 7,
      "z": -1,
      "name": "Rock_Stone_Brick"
    },
    {
      "x": -45,
      "y": 8,
      "z": -1,
      "name": "Rock_Stone_Brick"
    },
    {
      "x": -45,
      "y": 9,
      "z": -1,
      "name": "Rock_Stone_Brick"
    },
    {
      "x": -45,
      "y": 10,
      "z": -1,
      "name": "Rock_Shale_Brick"
    },
    {
      "x": -45,
      "y": 11,
      "z": -1,
      "name": "Rock_Shale_Brick_Half"
    },
    {
      "x": -45,
      "y": 2,
      "z": 0,
      "name": "Rock_Stone_Brick"
    },
    {
      "x": -45,
      "y": 3,
      "z": 0,
      "name": "Rock_Shale_Brick"
    },
    {
      "x": -45,
      "y": 4,
      "z": 0,
      "name": "Rock_Stone_Brick"
    },
    {
      "x": -45,
      "y": 5,
      "z": 0,
      "name": "Rock_Stone_Brick"
    },
    {
      "x": -45,
      "y": 6,
      "z": 0,
      "name": "Rock_Shale_Brick"
    },
    {
      "x": -45,
      "y": 7,
      "z": 0,
      "name": "Rock_Stone_Brick"
    },
    {
      "x": -45,
      "y": 8,
      "z": 0,
      "name": "Rock_Stone_Brick_Mossy"
    },
    {
      "x": -45,
      "y": 9,
      "z": 0,
      "name": "Rock_Shale_Brick"
    },
    {
      "x": -45,
      "y": 10,
      "z": 0,
      "name": "Rock_Shale_Brick"
    },
    {
      "x": -45,
      "y": 11,
      "z": 0,
      "name": "Rock_Shale_Cobble"
    },
    {
      "x": -45,
      "y": 2,
      "z": 1,
      "name": "Rock_Stone_Brick"
    },
    {
      "x": -45,
      "y": 3,
      "z": 1,
      "name": "Rock_Stone_Brick"
    },
    {
      "x": -45,
      "y": 4,
      "z": 1,
      "name": "Rock_Stone_Brick_Mossy"
    },
    {
      "x": -45,
      "y": 5,
      "z": 1,
      "name": "Rock_Stone_Brick"
    },
    {
      "x": -45,
      "y": 6,
      "z": 1,
      "name": "Rock_Shale_Brick"
    },
    {
      "x": -45,
      "y": 7,
      "z": 1,
      "name": "Rock_Stone_Brick"
    },
    {
      "x": -45,
      "y": 8,
      "z": 1,
      "name": "Rock_Stone_Brick_Mossy"
    },
    {
      "x": -45,
      "y": 9,
      "z": 1,
      "name": "Rock_Stone_Brick"
    },
    {
      "x": -45,
      "y": 10,
      "z": 1,
      "name": "Rock_Stone_Brick_Mossy"
    },
    {
      "x": -45,
      "y": 11,
      "z": 1,
      "name": "Rock_Shale_Brick"
    },
    {
      "x": -45,
      "y": 2,
      "z": 2,
      "name": "Rock_Shale_Brick"
    },
    {
      "x": -45,
      "y": 3,
      "z": 2,
      "name": "Rock_Stone_Brick_Mossy"
    },
    {
      "x": -45,
      "y": 4,
      "z": 2,
      "name": "Rock_Shale_Brick"
    },
    {
      "x": -45,
      "y": 5,
      "z": 2,
      "name": "Rock_Stone_Brick_Mossy"
    },
    {
      "x": -45,
      "y": 6,
      "z": 2,
      "name": "Rock_Stone_Brick"
    },
    {
      "x": -45,
      "y": 7,
      "z": 2,
      "name": "Rock_Stone_Brick"
    },
    {
      "x": -45,
      "y": 8,
      "z": 2,
      "name": "Rock_Stone_Brick"
    },
    {
      "x": -45,
      "y": 9,
      "z": 2,
      "name": "Rock_Stone_Brick"
    },
    {
      "x": -45,
      "y": 10,
      "z": 2,
      "name": "Rock_Stone_Brick"
    },
    {
      "x": -45,
      "y": 11,
      "z": 2,
      "name": "Rock_Shale_Cobble"
    },
    {
      "x": -45,
      "y": 2,
      "z": 3,
      "name": "Rock_Shale_Brick"
    },
    {
      "x": -45,
      "y": 3,
      "z": 3,
      "name": "Rock_Stone_Brick"
    },
    {
      "x": -45,
      "y": 4,
      "z": 3,
      "name": "Rock_Stone_Brick"
    },
    {
      "x": -45,
      "y": 5,
      "z": 3,
      "name": "Rock_Stone_Brick"
    },
    {
      "x": -45,
      "y": 6,
      "z": 3,
      "name": "Rock_Stone_Brick"
    },
    {
      "x": -45,
      "y": 7,
      "z": 3,
      "name": "Rock_Stone_Brick"
    },
    {
      "x": -45,
      "y": 8,
      "z": 3,
      "name": "Rock_Stone_Brick"
    },
    {
      "x": -45,
      "y": 9,
      "z": 3,
      "name": "Rock_Shale_Brick"
    },
    {
      "x": -45,
      "y": 10,
      "z": 3,
      "name": "Rock_Stone_Brick"
    },
    {
      "x": -45,
      "y": 11,
      "z": 3,
      "name": "Rock_Shale_Brick_Half"
    },
    {
      "x": -45,
      "y": 2,
      "z": 4,
      "name": "Rock_Stone_Brick_Mossy"
    },
    {
      "x": -45,
      "y": 3,
      "z": 4,
      "name": "Rock_Stone_Brick"
    },
    {
      "x": -45,
      "y": 4,
      "z": 4,
      "name": "Rock_Stone_Brick_Mossy"
    },
    {
      "x": -45,
      "y": 5,
      "z": 4,
      "name": "Rock_Stone_Brick"
    },
    {
      "x": -45,
      "y": 6,
      "z": 4,
      "name": "Rock_Shale_Brick"
    },
    {
      "x": -45,
      "y": 7,
      "z": 4,
      "name": "Rock_Stone_Brick"
    },
    {
      "x": -45,
      "y": 8,
      "z": 4,
      "name": "Rock_Stone_Brick_Mossy"
    },
    {
      "x": -45,
      "y": 9,
      "z": 4,
      "name": "Rock_Stone_Brick"
    },
    {
      "x": -45,
      "y": 10,
      "z": 4,
      "name": "Rock_Stone_Brick"
    },
    {
      "x": -45,
      "y": 11,
      "z": 4,
      "name": "Rock_Shale_Brick_Half"
    },
    {
      "x": -45,
      "y": 2,
      "z": 5,
      "name": "Rock_Stone_Brick"
    },
    {
      "x": -45,
      "y": 3,
      "z": 5,
      "name": "Rock_Stone_Brick"
    },
    {
      "x": -45,
      "y": 4,
      "z": 5,
      "name": "Rock_Shale_Brick"
    },
    {
      "x": -45,
      "y": 5,
      "z": 5,
      "name": "Rock_Shale_Brick"
    },
    {
      "x": -45,
      "y": 6,
      "z": 5,
      "name": "Rock_Stone_Brick_Mossy"
    },
    {
      "x": -45,
      "y": 7,
      "z": 5,
      "name": "Rock_Stone_Brick"
    },
    {
      "x": -45,
      "y": 8,
      "z": 5,
      "name": "Rock_Stone_Brick"
    },
    {
      "x": -45,
      "y": 9,
      "z": 5,
      "name": "Rock_Stone_Brick"
    },
    {
      "x": -45,
      "y": 10,
      "z": 5,
      "name": "Rock_Stone_Brick"
    },
    {
      "x": -45,
      "y": 11,
      "z": 5,
      "name": "Rock_Shale_Brick_Half"
    },
    {
      "x": -45,
      "y": 2,
      "z": 6,
      "name": "Rock_Stone_Brick"
    },
    {
      "x": -45,
      "y": 3,
      "z": 6,
      "name": "Rock_Stone_Brick_Mossy"
    },
    {
      "x": -45,
      "y": 4,
      "z": 6,
      "name": "Rock_Stone_Brick"
    },
    {
      "x": -45,
      "y": 5,
      "z": 6,
      "name": "Rock_Stone_Brick"
    },
    {
      "x": -45,
      "y": 6,
      "z": 6,
      "name": "Rock_Stone_Brick"
    },
    {
      "x": -45,
      "y": 7,
      "z": 6,
      "name": "Rock_Shale_Brick"
    },
    {
      "x": -45,
      "y": 8,
      "z": 6,
      "name": "Rock_Stone_Brick_Mossy"
    },
    {
      "x": -45,
      "y": 9,
      "z": 6,
      "name": "Rock_Shale_Brick"
    },
    {
      "x": -45,
      "y": 10,
      "z": 6,
      "name": "Rock_Stone_Brick"
    },
    {
      "x": -45,
      "y": 11,
      "z": 6,
      "name": "Prototype_Rock_Concrete_Brick"
    },
    {
      "x": -45,
      "y": 2,
      "z": 7,
      "name": "Rock_Stone_Brick_Mossy"
    },
    {
      "x": -45,
      "y": 3,
      "z": 7,
      "name": "Rock_Stone_Brick"
    },
    {
      "x": -45,
      "y": 4,
      "z": 7,
      "name": "Rock_Stone_Brick"
    },
    {
      "x": -45,
      "y": 5,
      "z": 7,
      "name": "Rock_Shale_Brick"
    },
    {
      "x": -45,
      "y": 6,
      "z": 7,
      "name": "Rock_Stone_Brick"
    },
    {
      "x": -45,
      "y": 7,
      "z": 7,
      "name": "Rock_Stone_Brick_Mossy"
    },
    {
      "x": -45,
      "y": 8,
      "z": 7,
      "name": "Rock_Shale_Brick"
    },
    {
      "x": -45,
      "y": 9,
      "z": 7,
      "name": "Rock_Stone_Brick"
    },
    {
      "x": -45,
      "y": 10,
      "z": 7,
      "name": "Rock_Shale_Brick"
    },
    {
      "x": -45,
      "y": 11,
      "z": 7,
      "name": "Prototype_Rock_Concrete_Brick"
    },
    {
      "x": -45,
      "y": 2,
      "z": 8,
      "name": "Rock_Stone_Brick"
    },
    {
      "x": -45,
      "y": 3,
      "z": 8,
      "name": "Rock_Stone_Brick"
    },
    {
      "x": -45,
      "y": 4,
      "z": 8,
      "name": "Rock_Stone_Brick"
    },
    {
      "x": -45,
      "y": 5,
      "z": 8,
      "name": "Rock_Shale_Brick"
    },
    {
      "x": -45,
      "y": 6,
      "z": 8,
      "name": "Rock_Stone_Brick"
    },
    {
      "x": -45,
      "y": 7,
      "z": 8,
      "name": "Rock_Shale_Brick"
    },
    {
      "x": -45,
      "y": 8,
      "z": 8,
      "name": "Rock_Stone_Brick"
    },
    {
      "x": -45,
      "y": 9,
      "z": 8,
      "name": "Rock_Stone_Brick"
    },
    {
      "x": -45,
      "y": 10,
      "z": 8,
      "name": "Rock_Shale_Brick"
    },
    {
      "x": -45,
      "y": 11,
      "z": 8,
      "name": "Prototype_Rock_Concrete_Brick"
    },
    {
      "x": -45,
      "y": 2,
      "z": 9,
      "name": "Rock_Stone_Brick"
    },
    {
      "x": -45,
      "y": 3,
      "z": 9,
      "name": "Rock_Stone_Brick"
    },
    {
      "x": -45,
      "y": 4,
      "z": 9,
      "name": "Rock_Stone_Brick_Mossy"
    },
    {
      "x": -45,
      "y": 11,
      "z": 9,
      "name": "Prototype_Rock_Concrete_Brick_Half"
    },
    {
      "x": -45,
      "y": 2,
      "z": 10,
      "name": "Rock_Stone_Brick_Mossy"
    },
    {
      "x": -45,
      "y": 3,
      "z": 10,
      "name": "Rock_Stone_Brick"
    },
    {
      "x": -45,
      "y": 4,
      "z": 10,
      "name": "Rock_Stone_Brick_Mossy"
    },
    {
      "x": -45,
      "y": 5,
      "z": 10,
      "name": "Rock_Stone_Brick"
    },
    {
      "x": -45,
      "y": 11,
      "z": 10,
      "name": "Prototype_Rock_Concrete_Brick_Half"
    },
    {
      "x": -45,
      "y": 2,
      "z": 11,
      "name": "Rock_Stone_Brick_Mossy"
    },
    {
      "x": -45,
      "y": 3,
      "z": 11,
      "name": "Rock_Shale_Brick"
    },
    {
      "x": -45,
      "y": 4,
      "z": 11,
      "name": "Rock_Shale_Brick"
    },
    {
      "x": -45,
      "y": 5,
      "z": 11,
      "name": "Rock_Stone_Brick_Mossy"
    },
    {
      "x": -45,
      "y": 11,
      "z": 11,
      "name": "Prototype_Rock_Concrete_Brick_Half"
    },
    {
      "x": -45,
      "y": 2,
      "z": 12,
      "name": "Rock_Crystal_Cyan_Block"
    },
    {
      "x": -45,
      "y": 3,
      "z": 12,
      "name": "Plant_Moss_Rug_Green_Dark"
    },
    {
      "x": -45,
      "y": 11,
      "z": 12,
      "name": "Prototype_Rock_Concrete_Brick_Half"
    },
    {
      "x": -45,
      "y": 57,
      "z": 12,
      "name": "Build_Lightsource_White"
    },
    {
      "x": -45,
      "y": 58,
      "z": 12,
      "name": "Build_Lightsource_White"
    },
    {
      "x": -45,
      "y": 59,
      "z": 12,
      "name": "Build_Lightsource_White"
    },
    {
      "x": -45,
      "y": 60,
      "z": 12,
      "name": "Plant_Coral_Block_White"
    },
    {
      "x": -45,
      "y": 2,
      "z": 13,
      "name": "Rock_Shale_Brick"
    },
    {
      "x": -45,
      "y": 11,
      "z": 13,
      "name": "Prototype_Rock_Concrete_Brick_Half"
    },
    {
      "x": -45,
      "y": 55,
      "z": 13,
      "name": "Build_Lightsource_White"
    },
    {
      "x": -45,
      "y": 56,
      "z": 13,
      "name": "Plant_Coral_Block_White"
    },
    {
      "x": -45,
      "y": 57,
      "z": 13,
      "name": "Plant_Coral_Block_White"
    },
    {
      "x": -45,
      "y": 2,
      "z": 14,
      "name": "Rock_Stone_Brick"
    },
    {
      "x": -45,
      "y": 3,
      "z": 14,
      "name": "Rock_Stone_Brick"
    },
    {
      "x": -45,
      "y": 57,
      "z": 14,
      "name": "Plant_Coral_Block_White"
    },
    {
      "x": -45,
      "y": 58,
      "z": 14,
      "name": "Rock_Crystal_White_Block"
    },
    {
      "x": -45,
      "y": 59,
      "z": 14,
      "name": "Plant_Coral_Block_White"
    },
    {
      "x": -45,
      "y": 2,
      "z": 15,
      "name": "Rock_Stone_Brick"
    },
    {
      "x": -45,
      "y": 56,
      "z": 15,
      "name": "Plant_Coral_Block_White"
    },
    {
      "x": -45,
      "y": 57,
      "z": 15,
      "name": "Rock_Crystal_White_Block"
    },
    {
      "x": -45,
      "y": 59,
      "z": 15,
      "name": "Plant_Coral_Block_White"
    },
    {
      "x": -45,
      "y": 60,
      "z": 15,
      "name": "Rock_Crystal_White_Block"
    },
    {
      "x": -45,
      "y": 61,
      "z": 15,
      "name": "Plant_Coral_Block_White"
    },
    {
      "x": -45,
      "y": 62,
      "z": 15,
      "name": "Build_Lightsource_White"
    },
    {
      "x": -45,
      "y": 3,
      "z": 16,
      "name": "Rock_Stone_Brick_Mossy"
    },
    {
      "x": -45,
      "y": 56,
      "z": 16,
      "name": "Rock_Crystal_White_Block"
    },
    {
      "x": -45,
      "y": 57,
      "z": 16,
      "name": "Plant_Coral_Block_White"
    },
    {
      "x": -45,
      "y": 58,
      "z": 16,
      "name": "Build_Lightsource_White"
    },
    {
      "x": -45,
      "y": 2,
      "z": 17,
      "name": "Rock_Stone_Brick"
    },
    {
      "x": -45,
      "y": 3,
      "z": 17,
      "name": "Rock_Shale_Brick"
    },
    {
      "x": -45,
      "y": 57,
      "z": 17,
      "name": "Rock_Crystal_White_Block"
    },
    {
      "x": -45,
      "y": 58,
      "z": 17,
      "name": "Plant_Coral_Block_White"
    },
    {
      "x": -45,
      "y": 59,
      "z": 17,
      "name": "Rock_Crystal_White_Block"
    },
    {
      "x": -45,
      "y": 60,
      "z": 17,
      "name": "Plant_Coral_Block_White"
    },
    {
      "x": -45,
      "y": 2,
      "z": 18,
      "name": "Rock_Stone_Brick"
    },
    {
      "x": -45,
      "y": 2,
      "z": 19,
      "name": "Rock_Shale_Brick"
    },
    {
      "x": -45,
      "y": 2,
      "z": 20,
      "name": "Rock_Stone_Brick"
    },
    {
      "x": -45,
      "y": 3,
      "z": 20,
      "name": "Rock_Stone_Brick"
    },
    {
      "x": -45,
      "y": 2,
      "z": 21,
      "name": "Rock_Shale_Brick"
    },
    {
      "x": -44,
      "y": 2,
      "z": -20,
      "name": "Rock_Stone_Brick_Mossy"
    },
    {
      "x": -44,
      "y": 2,
      "z": -19,
      "name": "Rock_Stone_Brick_Mossy"
    },
    {
      "x": -44,
      "y": 3,
      "z": -19,
      "name": "Rock_Stone_Brick"
    },
    {
      "x": -44,
      "y": 2,
      "z": -17,
      "name": "Rock_Stone_Brick_Mossy"
    },
    {
      "x": -44,
      "y": 3,
      "z": -17,
      "name": "Rock_Shale_Brick"
    },
    {
      "x": -44,
      "y": 4,
      "z": -17,
      "name": "Rock_Shale_Brick"
    },
    {
      "x": -44,
      "y": 2,
      "z": -16,
      "name": "Rock_Stone_Brick"
    },
    {
      "x": -44,
      "y": 31,
      "z": -16,
      "name": "Build_Lightsource_White"
    },
    {
      "x": -44,
      "y": 32,
      "z": -16,
      "name": "Plant_Coral_Block_White"
    },
    {
      "x": -44,
      "y": 42,
      "z": -16,
      "name": "Rock_Crystal_White_Block"
    },
    {
      "x": -44,
      "y": 33,
      "z": -15,
      "name": "Build_Lightsource_White"
    },
    {
      "x": -44,
      "y": 43,
      "z": -15,
      "name": "Plant_Coral_Block_White"
    },
    {
      "x": -44,
      "y": 49,
      "z": -15,
      "name": "Rock_Crystal_White_Block"
    },
    {
      "x": -44,
      "y": 2,
      "z": -14,
      "name": "Rock_Stone_Brick_Mossy"
    },
    {
      "x": -44,
      "y": 3,
      "z": -14,
      "name": "Rock_Stone_Brick"
    },
    {
      "x": -44,
      "y": 4,
      "z": -14,
      "name": "Rock_Stone_Brick"
    },
    {
      "x": -44,
      "y": 5,
      "z": -14,
